Workbook

Sheet START_HERE
A1: Activity / Media Dictionary Builder
A2: Formula-driven, no VBA -- builds a complete activity_dictionary row and its activity_id
A4: What this builder is for
A5: Use this workbook to define one row per activity (a channel/platform/campaign-type combination such as Paid Search - Google - Brand) that you have spend, clicks, or impressions for.
A6: It builds a stable activity_id for you from the fields that genuinely distinguish one activity from another, and produces a clean row ready to paste into the activity_dictionary sheet of the standard Activity and Media upload workbook.
A8: What you need to fill in
A9: Go to the BUILDER sheet. Fill in channel, market, activity_ownership, intended_model_role, model_input_measure, economic_treatment, planning_eligibility, and source for every activity row.
A10: For Paid Search activities you want split by Google/Bing and Brand/Non-Brand, also fill in platform and campaign_type -- the same two ordinary dictionary fields any other channel would use, not special Search-only inputs.
A11: Only fill in the grey (optional/advanced) columns if you have the information handy -- they are reporting metadata, not fit or planning inputs.
A13: What is generated automatically
A14: Generated ID -- built from channel plus whichever of platform and campaign_type you filled in.
A15: Final ID -- the Generated ID, unless you type something in Manual override.
... A36: This builder never asks for your weekly spend, clicks, or impressions. Those go in the activity_data sheet of the same upload workbook, one row per period_start x market x activity_id.

Sheet BUILDER
A7: channel | B7: market | C7: activity_ownership | D7: intended_model_role | E7: model_input_column | F7: model_input_measure | G7: economic_treatment | H7: planning_eligibility | I7: source | J7: activity_id (existing) | K7: Manual override | L7: Generated ID | M7: Final ID | N7: Row status | O7: platform | P7: campaign_type | Q7: pooling_group_id | R7: funnel_stage | S7: marketing_objective | T7: product_advertised | U7: message_type | V7: currency | W7: effective_from | X7: effective_to | AA7: _A_clean | AB7: _A_collapsed | AC7: _A_token | AD7: _O_clean | AE7: _O_collapsed | AF7: _O_token | AG7: _P_clean | AH7: _P_collapsed | AI7: _P_token
A8: Paid Search | B8: UK | C8: paid | D8: intervention | F8: spend | G8: paid_media_cost | H8: optimisable | I8: Google Ads export | L8: =IF(AC8<>"",AC8,"")&IF(AF8<>"",IF(AC8<>"","_"&AF8,AF8),"")&IF(AI8<>"",IF(AC8<>"","_"&AI8,AI8),"") | M8: =IF(TRIM(K8)<>"",TRIM(K8),L8) | N8: =IF(OR(A8="",B8="",C8="",D8="",F8="",G8="",H8="",I8=""),"Missing required field — fill in channel, market, activity_ownership, intended_model_role, model_input_measure, economic_treatment, planning_eligibility, and source.",IF(L8="","Missing required field — channel must be filled in to build an ID.",IF(COUNTIF($M$8:$M$31,M8)>1,"Duplicate activity ID — two rows currently build the same activity_id; add the next meaningful field, not a random number.",IF(AND(J8<>"",J8<>M8),"Existing activity_id differs from the built ID — review before using.","Ready")))) | O8: Google | P8: Brand | AA8: =IF(OR(LOWER(TRIM(A8))="",LOWER(TRIM(A8))="nan",LOWER(TRIM(A8))="none",LOWER(TRIM(A8))="n/a"),"",SUBSTITUTE(SUBSTITUTE(SUBSTITUTE(SUBSTITUTE(SUBSTITUTE(SUBSTITUTE(SUBSTITUTE(SUBSTITUTE(SUBSTITUTE(SUBSTITUTE(SUBSTITUTE(SUBSTITUTE(SUBSTITUTE(SUBSTITUTE(SUBSTITUTE(SUBSTITUTE(SUBSTITUTE(SUBSTITUTE(SUBSTITUTE(SUBSTITUTE(SUBSTITUTE(SUBSTITUTE(SUBSTITUTE(SUBSTITUTE(SUBSTITUTE(SUBSTITUTE(SUBSTITUTE(SUBSTITUTE(SUBSTITUTE(SUBSTITUTE(SUBSTITUTE(SUBSTITUTE(SUBSTITUTE(SUBSTITUTE(SUBSTITUTE(SUBSTITUTE(SUBSTITUTE(SUBSTITUTE(LOWER(TRIM(A8))," ","_"),"!","_"),"#","_"),"$","_"),"%","_"),"&","_"),"'","_"),"(","_"),")","_"),"*","_"),"+","_"),",","_"),"-","_"),".","_"),"/","_"),":","_"),";","_"),"<","_"),"=","_"),">","_"),"?","_"),"@","_"),"[","_"),"\","_"),"]","_"),"^","_"),"`","_"),"{","_"),"|","_"),"}","_"),"~","_"),"–","_"),"—","_"),"’","_"),"“","_"),"”","_"),CHAR(9),"_"),CHAR(160),"_")) | AB8: =IF(AA8="","",SUBSTITUTE(SUBSTITUTE(SUBSTITUTE(SUBSTITUTE(SUBSTITUTE(SUBSTITUTE(SUBSTITUTE(SUBSTITUTE(AA8,"__","_"),"__","_"),"__","_"),"__","_"),"__","_"),"__","_"),"__","_"),"__","_")) | AC8: =IF(OR(AB8="",AB8="_"),"",IF(LEFT(AB8,1)="_",IF(RIGHT(AB8,1)="_",MID(AB8,2,LEN(AB8)-2),RIGHT(AB8,LEN(AB8)-1)),IF(RIGHT(AB8,1)="_",LEFT(AB8,LEN(AB8)-1),AB8))) | AD8: =IF(OR(LOWER(TRIM(O8))="",LOWER(TRIM(O8))="nan",LOWER(TRIM(O8))="none",LOWER(TRIM(O8))="n/a"),"",SUBSTITUTE(SUBSTITUTE(SUBSTITUTE(SUBSTITUTE(SUBSTITUTE(SUBSTITUTE(SUBSTITUTE(SUBSTITUTE(SUBSTITUTE(SUBSTITUTE(SUBSTITUTE(SUBSTITUTE(SUBSTITUTE(SUBSTITUTE(SUBSTITUTE(SUBSTITUTE(SUBSTITUTE(SUBSTITUTE(SUBSTITUTE(SUBSTITUTE(SUBSTITUTE(SUBSTITUTE(SUBSTITUTE(SUBSTITUTE(SUBSTITUTE(SUBSTITUTE(SUBSTITUTE(SUBSTITUTE(SUBSTITUTE(SUBSTITUTE(SUBSTITUTE(SUBSTITUTE(SUBSTITUTE(SUBSTITUTE(SUBSTITUTE(SUBSTITUTE(SUBSTITUTE(SUBSTITUTE(LOWER(TRIM(O8))," ","_"),"!","_"),"#","_"),"$","_"),"%","_"),"&","_"),"'","_"),"(","_"),")","_"),"*","_"),"+","_"),",","_"),"-","_"),".","_"),"/","_"),":","_"),";","_"),"<","_"),"=","_"),">","_"),"?","_"),"@","_"),"[","_"),"\","_"),"]","_"),"^","_"),"`","_"),"{","_"),"|","_"),"}","_"),"~","_"),"–","_"),"—","_"),"’","_"),"“","_"),"”","_"),CHAR(9),"_"),CHAR(160),"_")) | AE8: =IF(AD8="","",SUBSTITUTE(SUBSTITUTE(SUBSTITUTE(SUBSTITUTE(SUBSTITUTE(SUBSTITUTE(SUBSTITUTE(SUBSTITUTE(AD8,"__","_"),"__","_"),"__","_"),"__","_"),"__","_"),"__","_"),"__","_"),"__","_")) | AF8: =IF(OR(AE8="",AE8="_"),"",IF(LEFT(AE8,1)="_",IF(RIGHT(AE8,1)="_",MID(AE8,2,LEN(AE8)-2),RIGHT(AE8,LEN(AE8)-1)),IF(RIGHT(AE8,1)="_",LEFT(AE8,LEN(AE8)-1),AE8))) | AG8: =IF(OR(LOWER(TRIM(P8))="",LOWER(TRIM(P8))="nan",LOWER(TRIM(P8))="none",LOWER(TRIM(P8))="n/a"),"",SUBSTITUTE(SUBSTITUTE(SUBSTITUTE(SUBSTITUTE(SUBSTITUTE(SUBSTITUTE(SUBSTITUTE(SUBSTITUTE(SUBSTITUTE(SUBSTITUTE(SUBSTITUTE(SUBSTITUTE(SUBSTITUTE(SUBSTITUTE(SUBSTITUTE(SUBSTITUTE(SUBSTITUTE(SUBSTITUTE(SUBSTITUTE(SUBSTITUTE(SUBSTITUTE(SUBSTITUTE(SUBSTITUTE(SUBSTITUTE(SUBSTITUTE(SUBSTITUTE(SUBSTITUTE(SUBSTITUTE(SUBSTITUTE(SUBSTITUTE(SUBSTITUTE(SUBSTITUTE(SUBSTITUTE(SUBSTITUTE(SUBSTITUTE(SUBSTITUTE(SUBSTITUTE(SUBSTITUTE(LOWER(TRIM(P8))," ","_"),"!","_"),"#","_"),"$","_"),"%","_"),"&","_"),"'","_"),"(","_"),")","_"),"*","_"),"+","_"),",","_"),"-","_"),".","_"),"/","_"),":","_"),";","_"),"<","_"),"=","_"),">","_"),"?","_"),"@","_"),"[","_"),"\","_"),"]","_"),"^","_"),"`","_"),"{","_"),"|","_"),"}","_"),"~","_"),"–","_"),"—","_"),"’","_"),"“","_"),"”","_"),CHAR(9),"_"),CHAR(160),"_")) | AH8: =IF(AG8="","",SUBSTITUTE(SUBSTITUTE(SUBSTITUTE(SUBSTITUTE(SUBSTITUTE(SUBSTITUTE(SUBSTITUTE(SUBSTITUTE(AG8,"__","_"),"__","_"),"__","_"),"__","_"),"__","_"),"__","_"),"__","_"),"__","_")) | AI8: =IF(OR(AH8="",AH8="_"),"",IF(LEFT(AH8,1)="_",IF(RIGHT(AH8,1)="_",MID(AH8,2,LEN(AH8)-2),RIGHT(AH8,LEN(AH8)-1)),IF(RIGHT(AH8,1)="_",LEFT(AH8,LEN(AH8)-1),AH8)))
A9: Paid Search | B9: UK | C9: paid | D9: intervention | F9: spend | G9: paid_media_cost | H9: optimisable | I9: Bing Ads export | L9: =IF(AC9<>"",AC9,"")&IF(AF9<>"",IF(AC9<>"","_"&AF9,AF9),"")&IF(AI9<>"",IF(AC9<>"","_"&AI9,AI9),"") | M9: =IF(TRIM(K9)<>"",TRIM(K9),L9) | N9: =IF(OR(A9="",B9="",C9="",D9="",F9="",G9="",H9="",I9=""),"Missing required field — fill in channel, market, activity_ownership, intended_model_role, model_input_measure, economic_treatment, planning_eligibility, and source.",IF(L9="","Missing required field — channel must be filled in to build an ID.",IF(COUNTIF($M$8:$M$31,M9)>1,"Duplicate activity ID — two rows currently build the same activity_id; add the next meaningful field, not a random number.",IF(AND(J9<>"",J9<>M9),"Existing activity_id differs from the built ID — review before using.","Ready")))) | O9: Bing | P9: Brand | AA9: =IF(OR(LOWER(TRIM(A9))="",LOWER(TRIM(A9))="nan",LOWER(TRIM(A9))="none",LOWER(TRIM(A9))="n/a"),"",SUBSTITUTE(SUBSTITUTE(SUBSTITUTE(SUBSTITUTE(SUBSTITUTE(SUBSTITUTE(SUBSTITUTE(SUBSTITUTE(SUBSTITUTE(SUBSTITUTE(SUBSTITUTE(SUBSTITUTE(SUBSTITUTE(SUBSTITUTE(SUBSTITUTE(SUBSTITUTE(SUBSTITUTE(SUBSTITUTE(SUBSTITUTE(SUBSTITUTE(SUBSTITUTE(SUBSTITUTE(SUBSTITUTE(SUBSTITUTE(SUBSTITUTE(SUBSTITUTE(SUBSTITUTE(SUBSTITUTE(SUBSTITUTE(SUBSTITUTE(SUBSTITUTE(SUBSTITUTE(SUBSTITUTE(SUBSTITUTE(SUBSTITUTE(SUBSTITUTE(SUBSTITUTE(SUBSTITUTE(LOWER(TRIM(A9))," ","_"),"!","_"),"#","_"),"$","_"),"%","_"),"&","_"),"'","_"),"(","_"),")","_"),"*","_"),"+","_"),",","_"),"-","_"),".","_"),"/","_"),":","_"),";","_"),"<","_"),"=","_"),">","_"),"?","_"),"@","_"),"[","_"),"\","_"),"]","_"),"^","_"),"`","_"),"{","_"),"|","_"),"}","_"),"~","_"),"–","_"),"—","_"),"’","_"),"“","_"),"”","_"),CHAR(9),"_"),CHAR(160),"_")) | AB9: =IF(AA9="","",SUBSTITUTE(SUBSTITUTE(SUBSTITUTE(SUBSTITUTE(SUBSTITUTE(SUBSTITUTE(SUBSTITUTE(SUBSTITUTE(AA9,"__","_"),"__","_"),"__","_"),"__","_"),"__","_"),"__","_"),"__","_"),"__","_")) | AC9: =IF(OR(AB9="",AB9="_"),"",IF(LEFT(AB9,1)="_",IF(RIGHT(AB9,1)="_",MID(AB9,2,LEN(AB9)-2),RIGHT(AB9,LEN(AB9)-1)),IF(RIGHT(AB9,1)="_",LEFT(AB9,LEN(AB9)-1),AB9))) | AD9: =IF(OR(LOWER(TRIM(O9))="",LOWER(TRIM(O9))="nan",LOWER(TRIM(O9))="none",LOWER(TRIM(O9))="n/a"),"",SUBSTITUTE(SUBSTITUTE(SUBSTITUTE(SUBSTITUTE(SUBSTITUTE(SUBSTITUTE(SUBSTITUTE(SUBSTITUTE(SUBSTITUTE(SUBSTITUTE(SUBSTITUTE(SUBSTITUTE(SUBSTITUTE(SUBSTITUTE(SUBSTITUTE(SUBSTITUTE(SUBSTITUTE(SUBSTITUTE(SUBSTITUTE(SUBSTITUTE(SUBSTITUTE(SUBSTITUTE(SUBSTITUTE(SUBSTITUTE(SUBSTITUTE(SUBSTITUTE(SUBSTITUTE(SUBSTITUTE(SUBSTITUTE(SUBSTITUTE(SUBSTITUTE(SUBSTITUTE(SUBSTITUTE(SUBSTITUTE(SUBSTITUTE(SUBSTITUTE(SUBSTITUTE(SUBSTITUTE(LOWER(TRIM(O9))," ","_"),"!","_"),"#","_"),"$","_"),"%","_"),"&","_"),"'","_"),"(","_"),")","_"),"*","_"),"+","_"),",","_"),"-","_"),".","_"),"/","_"),":","_"),";","_"),"<","_"),"=","_"),">","_"),"?","_"),"@","_"),"[","_"),"\","_"),"]","_"),"^","_"),"`","_"),"{","_"),"|","_"),"}","_"),"~","_"),"–","_"),"—","_"),"’","_"),"“","_"),"”","_"),CHAR(9),"_"),CHAR(160),"_")) | AE9: =IF(AD9="","",SUBSTITUTE(SUBSTITUTE(SUBSTITUTE(SUBSTITUTE(SUBSTITUTE(SUBSTITUTE(SUBSTITUTE(SUBSTITUTE(AD9,"__","_"),"__","_"),"__","_"),"__","_"),"__","_"),"__","_"),"__","_"),"__","_")) | AF9: =IF(OR(AE9="",AE9="_"),"",IF(LEFT(AE9,1)="_",IF(RIGHT(AE9,1)="_",MID(AE9,2,LEN(AE9)-2),RIGHT(AE9,LEN(AE9)-1)),IF(RIGHT(AE9,1)="_",LEFT(AE9,LEN(AE9)-1),AE9))) | AG9: =IF(OR(LOWER(TRIM(P9))="",LOWER(TRIM(P9))="nan",LOWER(TRIM(P9))="none",LOWER(TRIM(P9))="n/a"),"",SUBSTITUTE(SUBSTITUTE(SUBSTITUTE(SUBSTITUTE(SUBSTITUTE(SUBSTITUTE(SUBSTITUTE(SUBSTITUTE(SUBSTITUTE(SUBSTITUTE(SUBSTITUTE(SUBSTITUTE(SUBSTITUTE(SUBSTITUTE(SUBSTITUTE(SUBSTITUTE(SUBSTITUTE(SUBSTITUTE(SUBSTITUTE(SUBSTITUTE(SUBSTITUTE(SUBSTITUTE(SUBSTITUTE(SUBSTITUTE(SUBSTITUTE(SUBSTITUTE(SUBSTITUTE(SUBSTITUTE(SUBSTITUTE(SUBSTITUTE(SUBSTITUTE(SUBSTITUTE(SUBSTITUTE(SUBSTITUTE(SUBSTITUTE(SUBSTITUTE(SUBSTITUTE(SUBSTITUTE(LOWER(TRIM(P9))," ","_"),"!","_"),"#","_"),"$","_"),"%","_"),"&","_"),"'","_"),"(","_"),")","_"),"*","_"),"+","_"),",","_"),"-","_"),".","_"),"/","_"),":","_"),";","_"),"<","_"),"=","_"),">","_"),"?","_"),"@","_"),"[","_"),"\","_"),"]","_"),"^","_"),"`","_"),"{","_"),"|","_"),"}","_"),"~","_"),"–","_"),"—","_"),"’","_"),"“","_"),"”","_"),CHAR(9),"_"),CHAR(160),"_")) | AH9: =IF(AG9="","",SUBSTITUTE(SUBSTITUTE(SUBSTITUTE(SUBSTITUTE(SUBSTITUTE(SUBSTITUTE(SUBSTITUTE(SUBSTITUTE(AG9,"__","_"),"__","_"),"__","_"),"__","_"),"__","_"),"__","_"),"__","_"),"__","_")) | AI9: =IF(OR(AH9="",AH9="_"),"",IF(LEFT(AH9,1)="_",IF(RIGHT(AH9,1)="_",MID(AH9,2,LEN(AH9)-2),RIGHT(AH9,LEN(AH9)-1)),IF(RIGHT(AH9,1)="_",LEFT(AH9,LEN(AH9)-1),AH9)))
A10: TV | B10: UK | C10: paid | D10: intervention | F10: spend | G10: paid_media_cost | H10: optimisable | I10: Broadcaster invoice | L10: =IF(AC10<>"",AC10,"")&IF(AF10<>"",IF(AC10<>"","_"&AF10,AF10),"")&IF(AI10<>"",IF(AC10<>"","_"&AI10,AI10),"") | M10: =IF(TRIM(K10)<>"",TRIM(K10),L10) | N10: =IF(OR(A10="",B10="",C10="",D10="",F10="",G10="",H10="",I10=""),"Missing required field — fill in channel, market, activity_ownership, intended_model_role, model_input_measure, economic_treatment, planning_eligibility, and source.",IF(L10="","Missing required field — channel must be filled in to build an ID.",IF(COUNTIF($M$8:$M$31,M10)>1,"Duplicate activity ID — two rows currently build the same activity_id; add the next meaningful field, not a random number.",IF(AND(J10<>"",J10<>M10),"Existing activity_id differs from the built ID — review before using.","Ready")))) | AA10: =IF(OR(LOWER(TRIM(A10))="",LOWER(TRIM(A10))="nan",LOWER(TRIM(A10))="none",LOWER(TRIM(A10))="n/a"),"",SUBSTITUTE(SUBSTITUTE(SUBSTITUTE(SUBSTITUTE(SUBSTITUTE(SUBSTITUTE(SUBSTITUTE(SUBSTITUTE(SUBSTITUTE(SUBSTITUTE(SUBSTITUTE(SUBSTITUTE(SUBSTITUTE(SUBSTITUTE(SUBSTITUTE(SUBSTITUTE(SUBSTITUTE(SUBSTITUTE(SUBSTITUTE(SUBSTITUTE(SUBSTITUTE(SUBSTITUTE(SUBSTITUTE(SUBSTITUTE(SUBSTITUTE(SUBSTITUTE(SUBSTITUTE(SUBSTITUTE(SUBSTITUTE(SUBSTITUTE(SUBSTITUTE(SUBSTITUTE(SUBSTITUTE(SUBSTITUTE(SUBSTITUTE(SUBSTITUTE(SUBSTITUTE(SUBSTITUTE(LOWER(TRIM(A10))," ","_"),"!","_"),"#","_"),"$","_"),"%","_"),"&","_"),"'","_"),"(","_"),")","_"),"*","_"),"+","_"),",","_"),"-","_"),".","_"),"/","_"),":","_"),";","_"),"<","_"),"=","_"),">","_"),"?","_"),"@","_"),"[","_"),"\","_"),"]","_"),"^","_"),"`","_"),"{","_"),"|","_"),"}","_"),"~","_"),"–","_"),"—","_"),"’","_"),"“","_"),"”","_"),CHAR(9),"_"),CHAR(160),"_")) | AB10: =IF(AA10="","",SUBSTITUTE(SUBSTITUTE(SUBSTITUTE(SUBSTITUTE(SUBSTITUTE(SUBSTITUTE(SUBSTITUTE(SUBSTITUTE(AA10,"__","_"),"__","_"),"__","_"),"__","_"),"__","_"),"__","_"),"__","_"),"__","_")) | AC10: =IF(OR(AB10="",AB10="_"),"",IF(LEFT(AB10,1)="_",IF(RIGHT(AB10,1)="_",MID(AB10,2,LEN(AB10)-2),RIGHT(AB10,LEN(AB10)-1)),IF(RIGHT(AB10,1)="_",LEFT(AB10,LEN(AB10)-1),AB10))) | AD10: =IF(OR(LOWER(TRIM(O10))="",LOWER(TRIM(O10))="nan",LOWER(TRIM(O10))="none",LOWER(TRIM(O10))="n/a"),"",SUBSTITUTE(SUBSTITUTE(SUBSTITUTE(SUBSTITUTE(SUBSTITUTE(SUBSTITUTE(SUBSTITUTE(SUBSTITUTE(SUBSTITUTE(SUBSTITUTE(SUBSTITUTE(SUBSTITUTE(SUBSTITUTE(SUBSTITUTE(SUBSTITUTE(SUBSTITUTE(SUBSTITUTE(SUBSTITUTE(SUBSTITUTE(SUBSTITUTE(SUBSTITUTE(SUBSTITUTE(SUBSTITUTE(SUBSTITUTE(SUBSTITUTE(SUBSTITUTE(SUBSTITUTE(SUBSTITUTE(SUBSTITUTE(SUBSTITUTE(SUBSTITUTE(SUBSTITUTE(SUBSTITUTE(SUBSTITUTE(SUBSTITUTE(SUBSTITUTE(SUBSTITUTE(SUBSTITUTE(LOWER(TRIM(O10))," ","_"),"!","_"),"#","_"),"$","_"),"%","_"),"&","_"),"'","_"),"(","_"),")","_"),"*","_"),"+","_"),",","_"),"-","_"),".","_"),"/","_"),":","_"),";","_"),"<","_"),"=","_"),">","_"),"?","_"),"@","_"),"[","_"),"\","_"),"]","_"),"^","_"),"`","_"),"{","_"),"|","_"),"}","_"),"~","_"),"–","_"),"—","_"),"’","_"),"“","_"),"”","_"),CHAR(9),"_"),CHAR(160),"_")) | AE10: =IF(AD10="","",SUBSTITUTE(SUBSTITUTE(SUBSTITUTE(SUBSTITUTE(SUBSTITUTE(SUBSTITUTE(SUBSTITUTE(SUBSTITUTE(AD10,"__","_"),"__","_"),"__","_"),"__","_"),"__","_"),"__","_"),"__","_"),"__","_")) | AF10: =IF(OR(AE10="",AE10="_"),"",IF(LEFT(AE10,1)="_",IF(RIGHT(AE10,1)="_",MID(AE10,2,LEN(AE10)-2),RIGHT(AE10,LEN(AE10)-1)),IF(RIGHT(AE10,1)="_",LEFT(AE10,LEN(AE10)-1),AE10))) | AG10: =IF(OR(LOWER(TRIM(P10))="",LOWER(TRIM(P10))="nan",LOWER(TRIM(P10))="none",LOWER(TRIM(P10))="n/a"),"",SUBSTITUTE(SUBSTITUTE(SUBSTITUTE(SUBSTITUTE(SUBSTITUTE(SUBSTITUTE(SUBSTITUTE(SUBSTITUTE(SUBSTITUTE(SUBSTITUTE(SUBSTITUTE(SUBSTITUTE(SUBSTITUTE(SUBSTITUTE(SUBSTITUTE(SUBSTITUTE(SUBSTITUTE(SUBSTITUTE(SUBSTITUTE(SUBSTITUTE(SUBSTITUTE(SUBSTITUTE(SUBSTITUTE(SUBSTITUTE(SUBSTITUTE(SUBSTITUTE(SUBSTITUTE(SUBSTITUTE(SUBSTITUTE(SUBSTITUTE(SUBSTITUTE(SUBSTITUTE(SUBSTITUTE(SUBSTITUTE(SUBSTITUTE(SUBSTITUTE(SUBSTITUTE(SUBSTITUTE(LOWER(TRIM(P10))," ","_"),"!","_"),"#","_"),"$","_"),"%","_"),"&","_"),"'","_"),"(","_"),")","_"),"*","_"),"+","_"),",","_"),"-","_"),".","_"),"/","_"),":","_"),";","_"),"<","_"),"=","_"),">","_"),"?","_"),"@","_"),"[","_"),"\","_"),"]","_"),"^","_"),"`","_"),"{","_"),"|","_"),"}","_"),"~","_"),"–","_"),"—","_"),"’","_"),"“","_"),"”","_"),CHAR(9),"_"),CHAR(160),"_")) | AH10: =IF(AG10="","",SUBSTITUTE(SUBSTITUTE(SUBSTITUTE(SUBSTITUTE(SUBSTITUTE(SUBSTITUTE(SUBSTITUTE(SUBSTITUTE(AG10,"__","_"),"__","_"),"__","_"),"__","_"),"__","_"),"__","_"),"__","_"),"__","_")) | AI10: =IF(OR(AH10="",AH10="_"),"",IF(LEFT(AH10,1)="_",IF(RIGHT(AH10,1)="_",MID(AH10,2,LEN(AH10)-2),RIGHT(AH10,LEN(AH10)-1)),IF(RIGHT(AH10,1)="_",LEFT(AH10,LEN(AH10)-1),AH10)))
A11: SEO | B11: UK | C11: owned | D11: demand_capture | F11: clicks | G11: response_only | H11: scenario_only | I11: Google Search Console | L11: =IF(AC11<>"",AC11,"")&IF(AF11<>"",IF(AC11<>"","_"&AF11,AF11),"")&IF(AI11<>"",IF(AC11<>"","_"&AI11,AI11),"") | M11: =IF(TRIM(K11)<>"",TRIM(K11),L11) | N11: =IF(OR(A11="",B11="",C11="",D11="",F11="",G11="",H11="",I11=""),"Missing required field — fill in channel, market, activity_ownership, intended_model_role, model_input_measure, economic_treatment, planning_eligibility, and source.",IF(L11="","Missing required field — channel must be filled in to build an ID.",IF(COUNTIF($M$8:$M$31,M11)>1,"Duplicate activity ID — two rows currently build the same activity_id; add the next meaningful field, not a random number.",IF(AND(J11<>"",J11<>M11),"Existing activity_id differs from the built ID — review before using.","Ready")))) | AA11: =IF(OR(LOWER(TRIM(A11))="",LOWER(TRIM(A11))="nan",LOWER(TRIM(A11))="none",LOWER(TRIM(A11))="n/a"),"",SUBSTITUTE(SUBSTITUTE(SUBSTITUTE(SUBSTITUTE(SUBSTITUTE(SUBSTITUTE(SUBSTITUTE(SUBSTITUTE(SUBSTITUTE(SUBSTITUTE(SUBSTITUTE(SUBSTITUTE(SUBSTITUTE(SUBSTITUTE(SUBSTITUTE(SUBSTITUTE(SUBSTITUTE(SUBSTITUTE(SUBSTITUTE(SUBSTITUTE(SUBSTITUTE(SUBSTITUTE(SUBSTITUTE(SUBSTITUTE(SUBSTITUTE(SUBSTITUTE(SUBSTITUTE(SUBSTITUTE(SUBSTITUTE(SUBSTITUTE(SUBSTITUTE(SUBSTITUTE(SUBSTITUTE(SUBSTITUTE(SUBSTITUTE(SUBSTITUTE(SUBSTITUTE(SUBSTITUTE(LOWER(TRIM(A11))," ","_"),"!","_"),"#","_"),"$","_"),"%","_"),"&","_"),"'","_"),"(","_"),")","_"),"*","_"),"+","_"),",","_"),"-","_"),".","_"),"/","_"),":","_"),";","_"),"<","_"),"=","_"),">","_"),"?","_"),"@","_"),"[","_"),"\","_"),"]","_"),"^","_"),"`","_"),"{","_"),"|","_"),"}","_"),"~","_"),"–","_"),"—","_"),"’","_"),"“","_"),"”","_"),CHAR(9),"_"),CHAR(160),"_")) | AB11: =IF(AA11="","",SUBSTITUTE(SUBSTITUTE(SUBSTITUTE(SUBSTITUTE(SUBSTITUTE(SUBSTITUTE(SUBSTITUTE(SUBSTITUTE(AA11,"__","_"),"__","_"),"__","_"),"__","_"),"__","_"),"__","_"),"__","_"),"__","_")) | AC11: =IF(OR(AB11="",AB11="_"),"",IF(LEFT(AB11,1)="_",IF(RIGHT(AB11,1)="_",MID(AB11,2,LEN(AB11)-2),RIGHT(AB11,LEN(AB11)-1)),IF(RIGHT(AB11,1)="_",LEFT(AB11,LEN(AB11)-1),AB11))) | AD11: =IF(OR(LOWER(TRIM(O11))="",LOWER(TRIM(O11))="nan",LOWER(TRIM(O11))="none",LOWER(TRIM(O11))="n/a"),"",SUBSTITUTE(SUBSTITUTE(SUBSTITUTE(SUBSTITUTE(SUBSTITUTE(SUBSTITUTE(SUBSTITUTE(SUBSTITUTE(SUBSTITUTE(SUBSTITUTE(SUBSTITUTE(SUBSTITUTE(SUBSTITUTE(SUBSTITUTE(SUBSTITUTE(SUBSTITUTE(SUBSTITUTE(SUBSTITUTE(SUBSTITUTE(SUBSTITUTE(SUBSTITUTE(SUBSTITUTE(SUBSTITUTE(SUBSTITUTE(SUBSTITUTE(SUBSTITUTE(SUBSTITUTE(SUBSTITUTE(SUBSTITUTE(SUBSTITUTE(SUBSTITUTE(SUBSTITUTE(SUBSTITUTE(SUBSTITUTE(SUBSTITUTE(SUBSTITUTE(SUBSTITUTE(SUBSTITUTE(LOWER(TRIM(O11))," ","_"),"!","_"),"#","_"),"$","_"),"%","_"),"&","_"),"'","_"),"(","_"),")","_"),"*","_"),"+","_"),",","_"),"-","_"),".","_"),"/","_"),":","_"),";","_"),"<","_"),"=","_"),">","_"),"?","_"),"@","_"),"[","_"),"\","_"),"]","_"),"^","_"),"`","_"),"{","_"),"|","_"),"}","_"),"~","_"),"–","_"),"—","_"),"’","_"),"“","_"),"”","_"),CHAR(9),"_"),CHAR(160),"_")) | AE11: =IF(AD11="","",SUBSTITUTE(SUBSTITUTE(SUBSTITUTE(SUBSTITUTE(SUBSTITUTE(SUBSTITUTE(SUBSTITUTE(SUBSTITUTE(AD11,"__","_"),"__","_"),"__","_"),"__","_"),"__","_"),"__","_"),"__","_"),"__","_")) | AF11: =IF(OR(AE11="",AE11="_"),"",IF(LEFT(AE11,1)="_",IF(RIGHT(AE11,1)="_",MID(AE11,2,LEN(AE11)-2),RIGHT(AE11,LEN(AE11)-1)),IF(RIGHT(AE11,1)="_",LEFT(AE11,LEN(AE11)-1),AE11))) | AG11: =IF(OR(LOWER(TRIM(P11))="",LOWER(TRIM(P11))="nan",LOWER(TRIM(P11))="none",LOWER(TRIM(P11))="n/a"),"",SUBSTITUTE(SUBSTITUTE(SUBSTITUTE(SUBSTITUTE(SUBSTITUTE(SUBSTITUTE(SUBSTITUTE(SUBSTITUTE(SUBSTITUTE(SUBSTITUTE(SUBSTITUTE(SUBSTITUTE(SUBSTITUTE(SUBSTITUTE(SUBSTITUTE(SUBSTITUTE(SUBSTITUTE(SUBSTITUTE(SUBSTITUTE(SUBSTITUTE(SUBSTITUTE(SUBSTITUTE(SUBSTITUTE(SUBSTITUTE(SUBSTITUTE(SUBSTITUTE(SUBSTITUTE(SUBSTITUTE(SUBSTITUTE(SUBSTITUTE(SUBSTITUTE(SUBSTITUTE(SUBSTITUTE(SUBSTITUTE(SUBSTITUTE(SUBSTITUTE(SUBSTITUTE(SUBSTITUTE(LOWER(TRIM(P11))," ","_"),"!","_"),"#","_"),"$","_"),"%","_"),"&","_"),"'","_"),"(","_"),")","_"),"*","_"),"+","_"),",","_"),"-","_"),".","_"),"/","_"),":","_"),";","_"),"<","_"),"=","_"),">","_"),"?","_"),"@","_"),"[","_"),"\","_"),"]","_"),"^","_"),"`","_"),"{","_"),"|","_"),"}","_"),"~","_"),"–","_"),"—","_"),"’","_"),"“","_"),"”","_"),CHAR(9),"_"),CHAR(160),"_")) | AH11: =IF(AG11="","",SUBSTITUTE(SUBSTITUTE(SUBSTITUTE(SUBSTITUTE(SUBSTITUTE(SUBSTITUTE(SUBSTITUTE(SUBSTITUTE(AG11,"__","_"),"__","_"),"__","_"),"__","_"),"__","_"),"__","_"),"__","_"),"__","_")) | AI11: =IF(OR(AH11="",AH11="_"),"",IF(LEFT(AH11,1)="_",IF(RIGHT(AH11,1)="_",MID(AH11,2,LEN(AH11)-2),RIGHT(AH11,LEN(AH11)-1)),IF(RIGHT(AH11,1)="_",LEFT(AH11,LEN(AH11)-1),AH11)))
L12: =IF(AC12<>"",AC12,"")&IF(AF12<>"",IF(AC12<>"","_"&AF12,AF12),"")&IF(AI12<>"",IF(AC12<>"","_"&AI12,AI12),"") | M12: =IF(TRIM(K12)<>"",TRIM(K12),L12) | N12: =IF(OR(A12="",B12="",C12="",D12="",F12="",G12="",H12="",I12=""),"Missing required field — fill in channel, market, activity_ownership, intended_model_role, model_input_measure, economic_treatment, planning_eligibility, and source.",IF(L12="","Missing required field — channel must be filled in to build an ID.",IF(COUNTIF($M$8:$M$31,M12)>1,"Duplicate activity ID — two rows currently build the same activity_id; add the next meaningful field, not a random number.",IF(AND(J12<>"",J12<>M12),"Existing activity_id differs from the built ID — review before using.","Ready")))) | AA12: =IF(OR(LOWER(TRIM(A12))="",LOWER(TRIM(A12))="nan",LOWER(TRIM(A12))="none",LOWER(TRIM(A12))="n/a"),"",SUBSTITUTE(SUBSTITUTE(SUBSTITUTE(SUBSTITUTE(SUBSTITUTE(SUBSTITUTE(SUBSTITUTE(SUBSTITUTE(SUBSTITUTE(SUBSTITUTE(SUBSTITUTE(SUBSTITUTE(SUBSTITUTE(SUBSTITUTE(SUBSTITUTE(SUBSTITUTE(SUBSTITUTE(SUBSTITUTE(SUBSTITUTE(SUBSTITUTE(SUBSTITUTE(SUBSTITUTE(SUBSTITUTE(SUBSTITUTE(SUBSTITUTE(SUBSTITUTE(SUBSTITUTE(SUBSTITUTE(SUBSTITUTE(SUBSTITUTE(SUBSTITUTE(SUBSTITUTE(SUBSTITUTE(SUBSTITUTE(SUBSTITUTE(SUBSTITUTE(SUBSTITUTE(SUBSTITUTE(LOWER(TRIM(A12))," ","_"),"!","_"),"#","_"),"$","_"),"%","_"),"&","_"),"'","_"),"(","_"),")","_"),"*","_"),"+","_"),",","_"),"-","_"),".","_"),"/","_"),":","_"),";","_"),"<","_"),"=","_"),">","_"),"?","_"),"@","_"),"[","_"),"\","_"),"]","_"),"^","_"),"`","_"),"{","_"),"|","_"),"}","_"),"~","_"),"–","_"),"—","_"),"’","_"),"“","_"),"”","_"),CHAR(9),"_"),CHAR(160),"_")) | AB12: =IF(AA12="","",SUBSTITUTE(SUBSTITUTE(SUBSTITUTE(SUBSTITUTE(SUBSTITUTE(SUBSTITUTE(SUBSTITUTE(SUBSTITUTE(AA12,"__","_"),"__","_"),"__","_"),"__","_"),"__","_"),"__","_"),"__","_"),"__","_")) | AC12: =IF(OR(AB12="",AB12="_"),"",IF(LEFT(AB12,1)="_",IF(RIGHT(AB12,1)="_",MID(AB12,2,LEN(AB12)-2),RIGHT(AB12,LEN(AB12)-1)),IF(RIGHT(AB12,1)="_",LEFT(AB12,LEN(AB12)-1),AB12))) | AD12: =IF(OR(LOWER(TRIM(O12))="",LOWER(TRIM(O12))="nan",LOWER(TRIM(O12))="none",LOWER(TRIM(O12))="n/a"),"",SUBSTITUTE(SUBSTITUTE(SUBSTITUTE(SUBSTITUTE(SUBSTITUTE(SUBSTITUTE(SUBSTITUTE(SUBSTITUTE(SUBSTITUTE(SUBSTITUTE(SUBSTITUTE(SUBSTITUTE(SUBSTITUTE(SUBSTITUTE(SUBSTITUTE(SUBSTITUTE(SUBSTITUTE(SUBSTITUTE(SUBSTITUTE(SUBSTITUTE(SUBSTITUTE(SUBSTITUTE(SUBSTITUTE(SUBSTITUTE(SUBSTITUTE(SUBSTITUTE(SUBSTITUTE(SUBSTITUTE(SUBSTITUTE(SUBSTITUTE(SUBSTITUTE(SUBSTITUTE(SUBSTITUTE(SUBSTITUTE(SUBSTITUTE(SUBSTITUTE(SUBSTITUTE(SUBSTITUTE(LOWER(TRIM(O12))," ","_"),"!","_"),"#","_"),"$","_"),"%","_"),"&","_"),"'","_"),"(","_"),")","_"),"*","_"),"+","_"),",","_"),"-","_"),".","_"),"/","_"),":","_"),";","_"),"<","_"),"=","_"),">","_"),"?","_"),"@","_"),"[","_"),"\","_"),"]","_"),"^","_"),"`","_"),"{","_"),"|","_"),"}","_"),"~","_"),"–","_"),"—","_"),"’","_"),"“","_"),"”","_"),CHAR(9),"_"),CHAR(160),"_")) | AE12: =IF(AD12="","",SUBSTITUTE(SUBSTITUTE(SUBSTITUTE(SUBSTITUTE(SUBSTITUTE(SUBSTITUTE(SUBSTITUTE(SUBSTITUTE(AD12,"__","_"),"__","_"),"__","_"),"__","_"),"__","_"),"__","_"),"__","_"),"__","_")) | AF12: =IF(OR(AE12="",AE12="_"),"",IF(LEFT(AE12,1)="_",IF(RIGHT(AE12,1)="_",MID(AE12,2,LEN(AE12)-2),RIGHT(AE12,LEN(AE12)-1)),IF(RIGHT(AE12,1)="_",LEFT(AE12,LEN(AE12)-1),AE12))) | AG12: =IF(OR(LOWER(TRIM(P12))="",LOWER(TRIM(P12))="nan",LOWER(TRIM(P12))="none",LOWER(TRIM(P12))="n/a"),"",SUBSTITUTE(SUBSTITUTE(SUBSTITUTE(SUBSTITUTE(SUBSTITUTE(SUBSTITUTE(SUBSTITUTE(SUBSTITUTE(SUBSTITUTE(SUBSTITUTE(SUBSTITUTE(SUBSTITUTE(SUBSTITUTE(SUBSTITUTE(SUBSTITUTE(SUBSTITUTE(SUBSTITUTE(SUBSTITUTE(SUBSTITUTE(SUBSTITUTE(SUBSTITUTE(SUBSTITUTE(SUBSTITUTE(SUBSTITUTE(SUBSTITUTE(SUBSTITUTE(SUBSTITUTE(SUBSTITUTE(SUBSTITUTE(SUBSTITUTE(SUBSTITUTE(SUBSTITUTE(SUBSTITUTE(SUBSTITUTE(SUBSTITUTE(SUBSTITUTE(SUBSTITUTE(SUBSTITUTE(LOWER(TRIM(P12))," ","_"),"!","_"),"#","_"),"$","_"),"%","_"),"&","_"),"'","_"),"(","_"),")","_"),"*","_"),"+","_"),",","_"),"-","_"),".","_"),"/","_"),":","_"),";","_"),"<","_"),"=","_"),">","_"),"?","_"),"@","_"),"[","_"),"\","_"),"]","_"),"^","_"),"`","_"),"{","_"),"|","_"),"}","_"),"~","_"),"–","_"),"—","_"),"’","_"),"“","_"),"”","_"),CHAR(9),"_"),CHAR(160),"_")) | AH12: =IF(AG12="","",SUBSTITUTE(SUBSTITUTE(SUBSTITUTE(SUBSTITUTE(SUBSTITUTE(SUBSTITUTE(SUBSTITUTE(SUBSTITUTE(AG12,"__","_"),"__","_"),"__","_"),"__","_"),"__","_"),"__","_"),"__","_"),"__","_")) | AI12: =IF(OR(AH12="",AH12="_"),"",IF(LEFT(AH12,1)="_",IF(RIGHT(AH12,1)="_",MID(AH12,2,LEN(AH12)-2),RIGHT(AH12,LEN(AH12)-1)),IF(RIGHT(AH12,1)="_",LEFT(AH12,LEN(AH12)-1),AH12)))
L13: =IF(AC13<>"",AC13,"")&IF(AF13<>"",IF(AC13<>"","_"&AF13,AF13),"")&IF(AI13<>"",IF(AC13<>"","_"&AI13,AI13),"") | M13: =IF(TRIM(K13)<>"",TRIM(K13),L13) | N13: =IF(OR(A13="",B13="",C13="",D13="",F13="",G13="",H13="",I13=""),"Missing required field — fill in channel, market, activity_ownership, intended_model_role, model_input_measure, economic_treatment, planning_eligibility, and source.",IF(L13="","Missing required field — channel must be filled in to build an ID.",IF(COUNTIF($M$8:$M$31,M13)>1,"Duplicate activity ID — two rows currently build the same activity_id; add the next meaningful field, not a random number.",IF(AND(J13<>"",J13<>M13),"Existing activity_id differs from the built ID — review before using.","Ready")))) | AA13: =IF(OR(LOWER(TRIM(A13))="",LOWER(TRIM(A13))="nan",LOWER(TRIM(A13))="none",LOWER(TRIM(A13))="n/a"),"",SUBSTITUTE(SUBSTITUTE(SUBSTITUTE(SUBSTITUTE(SUBSTITUTE(SUBSTITUTE(SUBSTITUTE(SUBSTITUTE(SUBSTITUTE(SUBSTITUTE(SUBSTITUTE(SUBSTITUTE(SUBSTITUTE(SUBSTITUTE(SUBSTITUTE(SUBSTITUTE(SUBSTITUTE(SUBSTITUTE(SUBSTITUTE(SUBSTITUTE(SUBSTITUTE(SUBSTITUTE(SUBSTITUTE(SUBSTITUTE(SUBSTITUTE(SUBSTITUTE(SUBSTITUTE(SUBSTITUTE(SUBSTITUTE(SUBSTITUTE(SUBSTITUTE(SUBSTITUTE(SUBSTITUTE(SUBSTITUTE(SUBSTITUTE(SUBSTITUTE(SUBSTITUTE(SUBSTITUTE(LOWER(TRIM(A13))," ","_"),"!","_"),"#","_"),"$","_"),"%","_"),"&","_"),"'","_"),"(","_"),")","_"),"*","_"),"+","_"),",","_"),"-","_"),".","_"),"/","_"),":","_"),";","_"),"<","_"),"=","_"),">","_"),"?","_"),"@","_"),"[","_"),"\","_"),"]","_"),"^","_"),"`","_"),"{","_"),"|","_"),"}","_"),"~","_"),"–","_"),"—","_"),"’","_"),"“","_"),"”","_"),CHAR(9),"_"),CHAR(160),"_")) | AB13: =IF(AA13="","",SUBSTITUTE(SUBSTITUTE(SUBSTITUTE(SUBSTITUTE(SUBSTITUTE(SUBSTITUTE(SUBSTITUTE(SUBSTITUTE(AA13,"__","_"),"__","_"),"__","_"),"__","_"),"__","_"),"__","_"),"__","_"),"__","_")) | AC13: =IF(OR(AB13="",AB13="_"),"",IF(LEFT(AB13,1)="_",IF(RIGHT(AB13,1)="_",MID(AB13,2,LEN(AB13)-2),RIGHT(AB13,LEN(AB13)-1)),IF(RIGHT(AB13,1)="_",LEFT(AB13,LEN(AB13)-1),AB13))) | AD13: =IF(OR(LOWER(TRIM(O13))="",LOWER(TRIM(O13))="nan",LOWER(TRIM(O13))="none",LOWER(TRIM(O13))="n/a"),"",SUBSTITUTE(SUBSTITUTE(SUBSTITUTE(SUBSTITUTE(SUBSTITUTE(SUBSTITUTE(SUBSTITUTE(SUBSTITUTE(SUBSTITUTE(SUBSTITUTE(SUBSTITUTE(SUBSTITUTE(SUBSTITUTE(SUBSTITUTE(SUBSTITUTE(SUBSTITUTE(SUBSTITUTE(SUBSTITUTE(SUBSTITUTE(SUBSTITUTE(SUBSTITUTE(SUBSTITUTE(SUBSTITUTE(SUBSTITUTE(SUBSTITUTE(SUBSTITUTE(SUBSTITUTE(SUBSTITUTE(SUBSTITUTE(SUBSTITUTE(SUBSTITUTE(SUBSTITUTE(SUBSTITUTE(SUBSTITUTE(SUBSTITUTE(SUBSTITUTE(SUBSTITUTE(SUBSTITUTE(LOWER(TRIM(O13))," ","_"),"!","_"),"#","_"),"$","_"),"%","_"),"&","_"),"'","_"),"(","_"),")","_"),"*","_"),"+","_"),",","_"),"-","_"),".","_"),"/","_"),":","_"),";","_"),"<","_"),"=","_"),">","_"),"?","_"),"@","_"),"[","_"),"\","_"),"]","_"),"^","_"),"`","_"),"{","_"),"|","_"),"}","_"),"~","_"),"–","_"),"—","_"),"’","_"),"“","_"),"”","_"),CHAR(9),"_"),CHAR(160),"_")) | AE13: =IF(AD13="","",SUBSTITUTE(SUBSTITUTE(SUBSTITUTE(SUBSTITUTE(SUBSTITUTE(SUBSTITUTE(SUBSTITUTE(SUBSTITUTE(AD13,"__","_"),"__","_"),"__","_"),"__","_"),"__","_"),"__","_"),"__","_"),"__","_")) | AF13: =IF(OR(AE13="",AE13="_"),"",IF(LEFT(AE13,1)="_",IF(RIGHT(AE13,1)="_",MID(AE13,2,LEN(AE13)-2),RIGHT(AE13,LEN(AE13)-1)),IF(RIGHT(AE13,1)="_",LEFT(AE13,LEN(AE13)-1),AE13))) | AG13: =IF(OR(LOWER(TRIM(P13))="",LOWER(TRIM(P13))="nan",LOWER(TRIM(P13))="none",LOWER(TRIM(P13))="n/a"),"",SUBSTITUTE(SUBSTITUTE(SUBSTITUTE(SUBSTITUTE(SUBSTITUTE(SUBSTITUTE(SUBSTITUTE(SUBSTITUTE(SUBSTITUTE(SUBSTITUTE(SUBSTITUTE(SUBSTITUTE(SUBSTITUTE(SUBSTITUTE(SUBSTITUTE(SUBSTITUTE(SUBSTITUTE(SUBSTITUTE(SUBSTITUTE(SUBSTITUTE(SUBSTITUTE(SUBSTITUTE(SUBSTITUTE(SUBSTITUTE(SUBSTITUTE(SUBSTITUTE(SUBSTITUTE(SUBSTITUTE(SUBSTITUTE(SUBSTITUTE(SUBSTITUTE(SUBSTITUTE(SUBSTITUTE(SUBSTITUTE(SUBSTITUTE(SUBSTITUTE(SUBSTITUTE(SUBSTITUTE(LOWER(TRIM(P13))," ","_"),"!","_"),"#","_"),"$","_"),"%","_"),"&","_"),"'","_"),"(","_"),")","_"),"*","_"),"+","_"),",","_"),"-","_"),".","_"),"/","_"),":","_"),";","_"),"<","_"),"=","_"),">","_"),"?","_"),"@","_"),"[","_"),"\","_"),"]","_"),"^","_"),"`","_"),"{","_"),"|","_"),"}","_"),"~","_"),"–","_"),"—","_"),"’","_"),"“","_"),"”","_"),CHAR(9),"_"),CHAR(160),"_")) | AH13: =IF(AG13="","",SUBSTITUTE(SUBSTITUTE(SUBSTITUTE(SUBSTITUTE(SUBSTITUTE(SUBSTITUTE(SUBSTITUTE(SUBSTITUTE(AG13,"__","_"),"__","_"),"__","_"),"__","_"),"__","_"),"__","_"),"__","_"),"__","_")) | AI13: =IF(OR(AH13="",AH13="_"),"",IF(LEFT(AH13,1)="_",IF(RIGHT(AH13,1)="_",MID(AH13,2,LEN(AH13)-2),RIGHT(AH13,LEN(AH13)-1)),IF(RIGHT(AH13,1)="_",LEFT(AH13,LEN(AH13)-1),AH13)))
L14: =IF(AC14<>"",AC14,"")&IF(AF14<>"",IF(AC14<>"","_"&AF14,AF14),"")&IF(AI14<>"",IF(AC14<>"","_"&AI14,AI14),"") | M14: =IF(TRIM(K14)<>"",TRIM(K14),L14) | N14: =IF(OR(A14="",B14="",C14="",D14="",F14="",G14="",H14="",I14=""),"Missing required field — fill in channel, market, activity_ownership, intended_model_role, model_input_measure, economic_treatment, planning_eligibility, and source.",IF(L14="","Missing required field — channel must be filled in to build an ID.",IF(COUNTIF($M$8:$M$31,M14)>1,"Duplicate activity ID — two rows currently build the same activity_id; add the next meaningful field, not a random number.",IF(AND(J14<>"",J14<>M14),"Existing activity_id differs from the built ID — review before using.","Ready")))) | AA14: =IF(OR(LOWER(TRIM(A14))="",LOWER(TRIM(A14))="nan",LOWER(TRIM(A14))="none",LOWER(TRIM(A14))="n/a"),"",SUBSTITUTE(SUBSTITUTE(SUBSTITUTE(SUBSTITUTE(SUBSTITUTE(SUBSTITUTE(SUBSTITUTE(SUBSTITUTE(SUBSTITUTE(SUBSTITUTE(SUBSTITUTE(SUBSTITUTE(SUBSTITUTE(SUBSTITUTE(SUBSTITUTE(SUBSTITUTE(SUBSTITUTE(SUBSTITUTE(SUBSTITUTE(SUBSTITUTE(SUBSTITUTE(SUBSTITUTE(SUBSTITUTE(SUBSTITUTE(SUBSTITUTE(SUBSTITUTE(SUBSTITUTE(SUBSTITUTE(SUBSTITUTE(SUBSTITUTE(SUBSTITUTE(SUBSTITUTE(SUBSTITUTE(SUBSTITUTE(SUBSTITUTE(SUBSTITUTE(SUBSTITUTE(SUBSTITUTE(LOWER(TRIM(A14))," ","_"),"!","_"),"#","_"),"$","_"),"%","_"),"&","_"),"'","_"),"(","_"),")","_"),"*","_"),"+","_"),",","_"),"-","_"),".","_"),"/","_"),":","_"),";","_"),"<","_"),"=","_"),">","_"),"?","_"),"@","_"),"[","_"),"\","_"),"]","_"),"^","_"),"`","_"),"{","_"),"|","_"),"}","_"),"~","_"),"–","_"),"—","_"),"’","_"),"“","_"),"”","_"),CHAR(9),"_"),CHAR(160),"_")) | AB14: =IF(AA14="","",SUBSTITUTE(SUBSTITUTE(SUBSTITUTE(SUBSTITUTE(SUBSTITUTE(SUBSTITUTE(SUBSTITUTE(SUBSTITUTE(AA14,"__","_"),"__","_"),"__","_"),"__","_"),"__","_"),"__","_"),"__","_"),"__","_")) | AC14: =IF(OR(AB14="",AB14="_"),"",IF(LEFT(AB14,1)="_",IF(RIGHT(AB14,1)="_",MID(AB14,2,LEN(AB14)-2),RIGHT(AB14,LEN(AB14)-1)),IF(RIGHT(AB14,1)="_",LEFT(AB14,LEN(AB14)-1),AB14))) | AD14: =IF(OR(LOWER(TRIM(O14))="",LOWER(TRIM(O14))="nan",LOWER(TRIM(O14))="none",LOWER(TRIM(O14))="n/a"),"",SUBSTITUTE(SUBSTITUTE(SUBSTITUTE(SUBSTITUTE(SUBSTITUTE(SUBSTITUTE(SUBSTITUTE(SUBSTITUTE(SUBSTITUTE(SUBSTITUTE(SUBSTITUTE(SUBSTITUTE(SUBSTITUTE(SUBSTITUTE(SUBSTITUTE(SUBSTITUTE(SUBSTITUTE(SUBSTITUTE(SUBSTITUTE(SUBSTITUTE(SUBSTITUTE(SUBSTITUTE(SUBSTITUTE(SUBSTITUTE(SUBSTITUTE(SUBSTITUTE(SUBSTITUTE(SUBSTITUTE(SUBSTITUTE(SUBSTITUTE(SUBSTITUTE(SUBSTITUTE(SUBSTITUTE(SUBSTITUTE(SUBSTITUTE(SUBSTITUTE(SUBSTITUTE(SUBSTITUTE(LOWER(TRIM(O14))," ","_"),"!","_"),"#","_"),"$","_"),"%","_"),"&","_"),"'","_"),"(","_"),")","_"),"*","_"),"+","_"),",","_"),"-","_"),".","_"),"/","_"),":","_"),";","_"),"<","_"),"=","_"),">","_"),"?","_"),"@","_"),"[","_"),"\","_"),"]","_"),"^","_"),"`","_"),"{","_"),"|","_"),"}","_"),"~","_"),"–","_"),"—","_"),"’","_"),"“","_"),"”","_"),CHAR(9),"_"),CHAR(160),"_")) | AE14: =IF(AD14="","",SUBSTITUTE(SUBSTITUTE(SUBSTITUTE(SUBSTITUTE(SUBSTITUTE(SUBSTITUTE(SUBSTITUTE(SUBSTITUTE(AD14,"__","_"),"__","_"),"__","_"),"__","_"),"__","_"),"__","_"),"__","_"),"__","_")) | AF14: =IF(OR(AE14="",AE14="_"),"",IF(LEFT(AE14,1)="_",IF(RIGHT(AE14,1)="_",MID(AE14,2,LEN(AE14)-2),RIGHT(AE14,LEN(AE14)-1)),IF(RIGHT(AE14,1)="_",LEFT(AE14,LEN(AE14)-1),AE14))) | AG14: =IF(OR(LOWER(TRIM(P14))="",LOWER(TRIM(P14))="nan",LOWER(TRIM(P14))="none",LOWER(TRIM(P14))="n/a"),"",SUBSTITUTE(SUBSTITUTE(SUBSTITUTE(SUBSTITUTE(SUBSTITUTE(SUBSTITUTE(SUBSTITUTE(SUBSTITUTE(SUBSTITUTE(SUBSTITUTE(SUBSTITUTE(SUBSTITUTE(SUBSTITUTE(SUBSTITUTE(SUBSTITUTE(SUBSTITUTE(SUBSTITUTE(SUBSTITUTE(SUBSTITUTE(SUBSTITUTE(SUBSTITUTE(SUBSTITUTE(SUBSTITUTE(SUBSTITUTE(SUBSTITUTE(SUBSTITUTE(SUBSTITUTE(SUBSTITUTE(SUBSTITUTE(SUBSTITUTE(SUBSTITUTE(SUBSTITUTE(SUBSTITUTE(SUBSTITUTE(SUBSTITUTE(SUBSTITUTE(SUBSTITUTE(SUBSTITUTE(LOWER(TRIM(P14))," ","_"),"!","_"),"#","_"),"$","_"),"%","_"),"&","_"),"'","_"),"(","_"),")","_"),"*","_"),"+","_"),",","_"),"-","_"),".","_"),"/","_"),":","_"),";","_"),"<","_"),"=","_"),">","_"),"?","_"),"@","_"),"[","_"),"\","_"),"]","_"),"^","_"),"`","_"),"{","_"),"|","_"),"}","_"),"~","_"),"–","_"),"—","_"),"’","_"),"“","_"),"”","_"),CHAR(9),"_"),CHAR(160),"_")) | AH14: =IF(AG14="","",SUBSTITUTE(SUBSTITUTE(SUBSTITUTE(SUBSTITUTE(SUBSTITUTE(SUBSTITUTE(SUBSTITUTE(SUBSTITUTE(AG14,"__","_"),"__","_"),"__","_"),"__","_"),"__","_"),"__","_"),"__","_"),"__","_")) | AI14: =IF(OR(AH14="",AH14="_"),"",IF(LEFT(AH14,1)="_",IF(RIGHT(AH14,1)="_",MID(AH14,2,LEN(AH14)-2),RIGHT(AH14,LEN(AH14)-1)),IF(RIGHT(AH14,1)="_",LEFT(AH14,LEN(AH14)-1),AH14)))
L15: =IF(AC15<>"",AC15,"")&IF(AF15<>"",IF(AC15<>"","_"&AF15,AF15),"")&IF(AI15<>"",IF(AC15<>"","_"&AI15,AI15),"") | M15: =IF(TRIM(K15)<>"",TRIM(K15),L15) | N15: =IF(OR(A15="",B15="",C15="",D15="",F15="",G15="",H15="",I15=""),"Missing required field — fill in channel, market, activity_ownership, intended_model_role, model_input_measure, economic_treatment, planning_eligibility, and source.",IF(L15="","Missing required field — channel must be filled in to build an ID.",IF(COUNTIF($M$8:$M$31,M15)>1,"Duplicate activity ID — two rows currently build the same activity_id; add the next meaningful field, not a random number.",IF(AND(J15<>"",J15<>M15),"Existing activity_id differs from the built ID — review before using.","Ready")))) | AA15: =IF(OR(LOWER(TRIM(A15))="",LOWER(TRIM(A15))="nan",LOWER(TRIM(A15))="none",LOWER(TRIM(A15))="n/a"),"",SUBSTITUTE(SUBSTITUTE(SUBSTITUTE(SUBSTITUTE(SUBSTITUTE(SUBSTITUTE(SUBSTITUTE(SUBSTITUTE(SUBSTITUTE(SUBSTITUTE(SUBSTITUTE(SUBSTITUTE(SUBSTITUTE(SUBSTITUTE(SUBSTITUTE(SUBSTITUTE(SUBSTITUTE(SUBSTITUTE(SUBSTITUTE(SUBSTITUTE(SUBSTITUTE(SUBSTITUTE(SUBSTITUTE(SUBSTITUTE(SUBSTITUTE(SUBSTITUTE(SUBSTITUTE(SUBSTITUTE(SUBSTITUTE(SUBSTITUTE(SUBSTITUTE(SUBSTITUTE(SUBSTITUTE(SUBSTITUTE(SUBSTITUTE(SUBSTITUTE(SUBSTITUTE(SUBSTITUTE(LOWER(TRIM(A15))," ","_"),"!","_"),"#","_"),"$","_"),"%","_"),"&","_"),"'","_"),"(","_"),")","_"),"*","_"),"+","_"),",","_"),"-","_"),".","_"),"/","_"),":","_"),";","_"),"<","_"),"=","_"),">","_"),"?","_"),"@","_"),"[","_"),"\","_"),"]","_"),"^","_"),"`","_"),"{","_"),"|","_"),"}","_"),"~","_"),"–","_"),"—","_"),"’","_"),"“","_"),"”","_"),CHAR(9),"_"),CHAR(160),"_")) | AB15: =IF(AA15="","",SUBSTITUTE(SUBSTITUTE(SUBSTITUTE(SUBSTITUTE(SUBSTITUTE(SUBSTITUTE(SUBSTITUTE(SUBSTITUTE(AA15,"__","_"),"__","_"),"__","_"),"__","_"),"__","_"),"__","_"),"__","_"),"__","_")) | AC15: =IF(OR(AB15="",AB15="_"),"",IF(LEFT(AB15,1)="_",IF(RIGHT(AB15,1)="_",MID(AB15,2,LEN(AB15)-2),RIGHT(AB15,LEN(AB15)-1)),IF(RIGHT(AB15,1)="_",LEFT(AB15,LEN(AB15)-1),AB15))) | AD15: =IF(OR(LOWER(TRIM(O15))="",LOWER(TRIM(O15))="nan",LOWER(TRIM(O15))="none",LOWER(TRIM(O15))="n/a"),"",SUBSTITUTE(SUBSTITUTE(SUBSTITUTE(SUBSTITUTE(SUBSTITUTE(SUBSTITUTE(SUBSTITUTE(SUBSTITUTE(SUBSTITUTE(SUBSTITUTE(SUBSTITUTE(SUBSTITUTE(SUBSTITUTE(SUBSTITUTE(SUBSTITUTE(SUBSTITUTE(SUBSTITUTE(SUBSTITUTE(SUBSTITUTE(SUBSTITUTE(SUBSTITUTE(SUBSTITUTE(SUBSTITUTE(SUBSTITUTE(SUBSTITUTE(SUBSTITUTE(SUBSTITUTE(SUBSTITUTE(SUBSTITUTE(SUBSTITUTE(SUBSTITUTE(SUBSTITUTE(SUBSTITUTE(SUBSTITUTE(SUBSTITUTE(SUBSTITUTE(SUBSTITUTE(SUBSTITUTE(LOWER(TRIM(O15))," ","_"),"!","_"),"#","_"),"$","_"),"%","_"),"&","_"),"'","_"),"(","_"),")","_"),"*","_"),"+","_"),",","_"),"-","_"),".","_"),"/","_"),":","_"),";","_"),"<","_"),"=","_"),">","_"),"?","_"),"@","_"),"[","_"),"\","_"),"]","_"),"^","_"),"`","_"),"{","_"),"|","_"),"}","_"),"~","_"),"–","_"),"—","_"),"’","_"),"“","_"),"”","_"),CHAR(9),"_"),CHAR(160),"_")) | AE15: =IF(AD15="","",SUBSTITUTE(SUBSTITUTE(SUBSTITUTE(SUBSTITUTE(SUBSTITUTE(SUBSTITUTE(SUBSTITUTE(SUBSTITUTE(AD15,"__","_"),"__","_"),"__","_"),"__","_"),"__","_"),"__","_"),"__","_"),"__","_")) | AF15: =IF(OR(AE15="",AE15="_"),"",IF(LEFT(AE15,1)="_",IF(RIGHT(AE15,1)="_",MID(AE15,2,LEN(AE15)-2),RIGHT(AE15,LEN(AE15)-1)),IF(RIGHT(AE15,1)="_",LEFT(AE15,LEN(AE15)-1),AE15))) | AG15: =IF(OR(LOWER(TRIM(P15))="",LOWER(TRIM(P15))="nan",LOWER(TRIM(P15))="none",LOWER(TRIM(P15))="n/a"),"",SUBSTITUTE(SUBSTITUTE(SUBSTITUTE(SUBSTITUTE(SUBSTITUTE(SUBSTITUTE(SUBSTITUTE(SUBSTITUTE(SUBSTITUTE(SUBSTITUTE(SUBSTITUTE(SUBSTITUTE(SUBSTITUTE(SUBSTITUTE(SUBSTITUTE(SUBSTITUTE(SUBSTITUTE(SUBSTITUTE(SUBSTITUTE(SUBSTITUTE(SUBSTITUTE(SUBSTITUTE(SUBSTITUTE(SUBSTITUTE(SUBSTITUTE(SUBSTITUTE(SUBSTITUTE(SUBSTITUTE(SUBSTITUTE(SUBSTITUTE(SUBSTITUTE(SUBSTITUTE(SUBSTITUTE(SUBSTITUTE(SUBSTITUTE(SUBSTITUTE(SUBSTITUTE(SUBSTITUTE(LOWER(TRIM(P15))," ","_"),"!","_"),"#","_"),"$","_"),"%","_"),"&","_"),"'","_"),"(","_"),")","_"),"*","_"),"+","_"),",","_"),"-","_"),".","_"),"/","_"),":","_"),";","_"),"<","_"),"=","_"),">","_"),"?","_"),"@","_"),"[","_"),"\","_"),"]","_"),"^","_"),"`","_"),"{","_"),"|","_"),"}","_"),"~","_"),"–","_"),"—","_"),"’","_"),"“","_"),"”","_"),CHAR(9),"_"),CHAR(160),"_")) | AH15: =IF(AG15="","",SUBSTITUTE(SUBSTITUTE(SUBSTITUTE(SUBSTITUTE(SUBSTITUTE(SUBSTITUTE(SUBSTITUTE(SUBSTITUTE(AG15,"__","_"),"__","_"),"__","_"),"__","_"),"__","_"),"__","_"),"__","_"),"__","_")) | AI15: =IF(OR(AH15="",AH15="_"),"",IF(LEFT(AH15,1)="_",IF(RIGHT(AH15,1)="_",MID(AH15,2,LEN(AH15)-2),RIGHT(AH15,LEN(AH15)-1)),IF(RIGHT(AH15,1)="_",LEFT(AH15,LEN(AH15)-1),AH15)))
L16: =IF(AC16<>"",AC16,"")&IF(AF16<>"",IF(AC16<>"","_"&AF16,AF16),"")&IF(AI16<>"",IF(AC16<>"","_"&AI16,AI16),"") | M16: =IF(TRIM(K16)<>"",TRIM(K16),L16) | N16: =IF(OR(A16="",B16="",C16="",D16="",F16="",G16="",H16="",I16=""),"Missing required field — fill in channel, market, activity_ownership, intended_model_role, model_input_measure, economic_treatment, planning_eligibility, and source.",IF(L16="","Missing required field — channel must be filled in to build an ID.",IF(COUNTIF($M$8:$M$31,M16)>1,"Duplicate activity ID — two rows currently build the same activity_id; add the next meaningful field, not a random number.",IF(AND(J16<>"",J16<>M16),"Existing activity_id differs from the built ID — review before using.","Ready")))) | AA16: =IF(OR(LOWER(TRIM(A16))="",LOWER(TRIM(A16))="nan",LOWER(TRIM(A16))="none",LOWER(TRIM(A16))="n/a"),"",SUBSTITUTE(SUBSTITUTE(SUBSTITUTE(SUBSTITUTE(SUBSTITUTE(SUBSTITUTE(SUBSTITUTE(SUBSTITUTE(SUBSTITUTE(SUBSTITUTE(SUBSTITUTE(SUBSTITUTE(SUBSTITUTE(SUBSTITUTE(SUBSTITUTE(SUBSTITUTE(SUBSTITUTE(SUBSTITUTE(SUBSTITUTE(SUBSTITUTE(SUBSTITUTE(SUBSTITUTE(SUBSTITUTE(SUBSTITUTE(SUBSTITUTE(SUBSTITUTE(SUBSTITUTE(SUBSTITUTE(SUBSTITUTE(SUBSTITUTE(SUBSTITUTE(SUBSTITUTE(SUBSTITUTE(SUBSTITUTE(SUBSTITUTE(SUBSTITUTE(SUBSTITUTE(SUBSTITUTE(LOWER(TRIM(A16))," ","_"),"!","_"),"#","_"),"$","_"),"%","_"),"&","_"),"'","_"),"(","_"),")","_"),"*","_"),"+","_"),",","_"),"-","_"),".","_"),"/","_"),":","_"),";","_"),"<","_"),"=","_"),">","_"),"?","_"),"@","_"),"[","_"),"\","_"),"]","_"),"^","_"),"`","_"),"{","_"),"|","_"),"}","_"),"~","_"),"–","_"),"—","_"),"’","_"),"“","_"),"”","_"),CHAR(9),"_"),CHAR(160),"_")) | AB16: =IF(AA16="","",SUBSTITUTE(SUBSTITUTE(SUBSTITUTE(SUBSTITUTE(SUBSTITUTE(SUBSTITUTE(SUBSTITUTE(SUBSTITUTE(AA16,"__","_"),"__","_"),"__","_"),"__","_"),"__","_"),"__","_"),"__","_"),"__","_")) | AC16: =IF(OR(AB16="",AB16="_"),"",IF(LEFT(AB16,1)="_",IF(RIGHT(AB16,1)="_",MID(AB16,2,LEN(AB16)-2),RIGHT(AB16,LEN(AB16)-1)),IF(RIGHT(AB16,1)="_",LEFT(AB16,LEN(AB16)-1),AB16))) | AD16: =IF(OR(LOWER(TRIM(O16))="",LOWER(TRIM(O16))="nan",LOWER(TRIM(O16))="none",LOWER(TRIM(O16))="n/a"),"",SUBSTITUTE(SUBSTITUTE(SUBSTITUTE(SUBSTITUTE(SUBSTITUTE(SUBSTITUTE(SUBSTITUTE(SUBSTITUTE(SUBSTITUTE(SUBSTITUTE(SUBSTITUTE(SUBSTITUTE(SUBSTITUTE(SUBSTITUTE(SUBSTITUTE(SUBSTITUTE(SUBSTITUTE(SUBSTITUTE(SUBSTITUTE(SUBSTITUTE(SUBSTITUTE(SUBSTITUTE(SUBSTITUTE(SUBSTITUTE(SUBSTITUTE(SUBSTITUTE(SUBSTITUTE(SUBSTITUTE(SUBSTITUTE(SUBSTITUTE(SUBSTITUTE(SUBSTITUTE(SUBSTITUTE(SUBSTITUTE(SUBSTITUTE(SUBSTITUTE(SUBSTITUTE(SUBSTITUTE(LOWER(TRIM(O16))," ","_"),"!","_"),"#","_"),"$","_"),"%","_"),"&","_"),"'","_"),"(","_"),")","_"),"*","_"),"+","_"),",","_"),"-","_"),".","_"),"/","_"),":","_"),";","_"),"<","_"),"=","_"),">","_"),"?","_"),"@","_"),"[","_"),"\","_"),"]","_"),"^","_"),"`","_"),"{","_"),"|","_"),"}","_"),"~","_"),"–","_"),"—","_"),"’","_"),"“","_"),"”","_"),CHAR(9),"_"),CHAR(160),"_")) | AE16: =IF(AD16="","",SUBSTITUTE(SUBSTITUTE(SUBSTITUTE(SUBSTITUTE(SUBSTITUTE(SUBSTITUTE(SUBSTITUTE(SUBSTITUTE(AD16,"__","_"),"__","_"),"__","_"),"__","_"),"__","_"),"__","_"),"__","_"),"__","_")) | AF16: =IF(OR(AE16="",AE16="_"),"",IF(LEFT(AE16,1)="_",IF(RIGHT(AE16,1)="_",MID(AE16,2,LEN(AE16)-2),RIGHT(AE16,LEN(AE16)-1)),IF(RIGHT(AE16,1)="_",LEFT(AE16,LEN(AE16)-1),AE16))) | AG16: =IF(OR(LOWER(TRIM(P16))="",LOWER(TRIM(P16))="nan",LOWER(TRIM(P16))="none",LOWER(TRIM(P16))="n/a"),"",SUBSTITUTE(SUBSTITUTE(SUBSTITUTE(SUBSTITUTE(SUBSTITUTE(SUBSTITUTE(SUBSTITUTE(SUBSTITUTE(SUBSTITUTE(SUBSTITUTE(SUBSTITUTE(SUBSTITUTE(SUBSTITUTE(SUBSTITUTE(SUBSTITUTE(SUBSTITUTE(SUBSTITUTE(SUBSTITUTE(SUBSTITUTE(SUBSTITUTE(SUBSTITUTE(SUBSTITUTE(SUBSTITUTE(SUBSTITUTE(SUBSTITUTE(SUBSTITUTE(SUBSTITUTE(SUBSTITUTE(SUBSTITUTE(SUBSTITUTE(SUBSTITUTE(SUBSTITUTE(SUBSTITUTE(SUBSTITUTE(SUBSTITUTE(SUBSTITUTE(SUBSTITUTE(SUBSTITUTE(LOWER(TRIM(P16))," ","_"),"!","_"),"#","_"),"$","_"),"%","_"),"&","_"),"'","_"),"(","_"),")","_"),"*","_"),"+","_"),",","_"),"-","_"),".","_"),"/","_"),":","_"),";","_"),"<","_"),"=","_"),">","_"),"?","_"),"@","_"),"[","_"),"\","_"),"]","_"),"^","_"),"`","_"),"{","_"),"|","_"),"}","_"),"~","_"),"–","_"),"—","_"),"’","_"),"“","_"),"”","_"),CHAR(9),"_"),CHAR(160),"_")) | AH16: =IF(AG16="","",SUBSTITUTE(SUBSTITUTE(SUBSTITUTE(SUBSTITUTE(SUBSTITUTE(SUBSTITUTE(SUBSTITUTE(SUBSTITUTE(AG16,"__","_"),"__","_"),"__","_"),"__","_"),"__","_"),"__","_"),"__","_"),"__","_")) | AI16: =IF(OR(AH16="",AH16="_"),"",IF(LEFT(AH16,1)="_",IF(RIGHT(AH16,1)="_",MID(AH16,2,LEN(AH16)-2),RIGHT(AH16,LEN(AH16)-1)),IF(RIGHT(AH16,1)="_",LEFT(AH16,LEN(AH16)-1),AH16)))
L17: =IF(AC17<>"",AC17,"")&IF(AF17<>"",IF(AC17<>"","_"&AF17,AF17),"")&IF(AI17<>"",IF(AC17<>"","_"&AI17,AI17),"") | M17: =IF(TRIM(K17)<>"",TRIM(K17),L17) | N17: =IF(OR(A17="",B17="",C17="",D17="",F17="",G17="",H17="",I17=""),"Missing required field — fill in channel, market, activity_ownership, intended_model_role, model_input_measure, economic_treatment, planning_eligibility, and source.",IF(L17="","Missing required field — channel must be filled in to build an ID.",IF(COUNTIF($M$8:$M$31,M17)>1,"Duplicate activity ID — two rows currently build the same activity_id; add the next meaningful field, not a random number.",IF(AND(J17<>"",J17<>M17),"Existing activity_id differs from the built ID — review before using.","Ready")))) | AA17: =IF(OR(LOWER(TRIM(A17))="",LOWER(TRIM(A17))="nan",LOWER(TRIM(A17))="none",LOWER(TRIM(A17))="n/a"),"",SUBSTITUTE(SUBSTITUTE(SUBSTITUTE(SUBSTITUTE(SUBSTITUTE(SUBSTITUTE(SUBSTITUTE(SUBSTITUTE(SUBSTITUTE(SUBSTITUTE(SUBSTITUTE(SUBSTITUTE(SUBSTITUTE(SUBSTITUTE(SUBSTITUTE(SUBSTITUTE(SUBSTITUTE(SUBSTITUTE(SUBSTITUTE(SUBSTITUTE(SUBSTITUTE(SUBSTITUTE(SUBSTITUTE(SUBSTITUTE(SUBSTITUTE(SUBSTITUTE(SUBSTITUTE(SUBSTITUTE(SUBSTITUTE(SUBSTITUTE(SUBSTITUTE(SUBSTITUTE(SUBSTITUTE(SUBSTITUTE(SUBSTITUTE(SUBSTITUTE(SUBSTITUTE(SUBSTITUTE(LOWER(TRIM(A17))," ","_"),"!","_"),"#","_"),"$","_"),"%","_"),"&","_"),"'","_"),"(","_"),")","_"),"*","_"),"+","_"),",","_"),"-","_"),".","_"),"/","_"),":","_"),";","_"),"<","_"),"=","_"),">","_"),"?","_"),"@","_"),"[","_"),"\","_"),"]","_"),"^","_"),"`","_"),"{","_"),"|","_"),"}","_"),"~","_"),"–","_"),"—","_"),"’","_"),"“","_"),"”","_"),CHAR(9),"_"),CHAR(160),"_")) | AB17: =IF(AA17="","",SUBSTITUTE(SUBSTITUTE(SUBSTITUTE(SUBSTITUTE(SUBSTITUTE(SUBSTITUTE(SUBSTITUTE(SUBSTITUTE(AA17,"__","_"),"__","_"),"__","_"),"__","_"),"__","_"),"__","_"),"__","_"),"__","_")) | AC17: =IF(OR(AB17="",AB17="_"),"",IF(LEFT(AB17,1)="_",IF(RIGHT(AB17,1)="_",MID(AB17,2,LEN(AB17)-2),RIGHT(AB17,LEN(AB17)-1)),IF(RIGHT(AB17,1)="_",LEFT(AB17,LEN(AB17)-1),AB17))) | AD17: =IF(OR(LOWER(TRIM(O17))="",LOWER(TRIM(O17))="nan",LOWER(TRIM(O17))="none",LOWER(TRIM(O17))="n/a"),"",SUBSTITUTE(SUBSTITUTE(SUBSTITUTE(SUBSTITUTE(SUBSTITUTE(SUBSTITUTE(SUBSTITUTE(SUBSTITUTE(SUBSTITUTE(SUBSTITUTE(SUBSTITUTE(SUBSTITUTE(SUBSTITUTE(SUBSTITUTE(SUBSTITUTE(SUBSTITUTE(SUBSTITUTE(SUBSTITUTE(SUBSTITUTE(SUBSTITUTE(SUBSTITUTE(SUBSTITUTE(SUBSTITUTE(SUBSTITUTE(SUBSTITUTE(SUBSTITUTE(SUBSTITUTE(SUBSTITUTE(SUBSTITUTE(SUBSTITUTE(SUBSTITUTE(SUBSTITUTE(SUBSTITUTE(SUBSTITUTE(SUBSTITUTE(SUBSTITUTE(SUBSTITUTE(SUBSTITUTE(LOWER(TRIM(O17))," ","_"),"!","_"),"#","_"),"$","_"),"%","_"),"&","_"),"'","_"),"(","_"),")","_"),"*","_"),"+","_"),",","_"),"-","_"),".","_"),"/","_"),":","_"),";","_"),"<","_"),"=","_"),">","_"),"?","_"),"@","_"),"[","_"),"\","_"),"]","_"),"^","_"),"`","_"),"{","_"),"|","_"),"}","_"),"~","_"),"–","_"),"—","_"),"’","_"),"“","_"),"”","_"),CHAR(9),"_"),CHAR(160),"_")) | AE17: =IF(AD17="","",SUBSTITUTE(SUBSTITUTE(SUBSTITUTE(SUBSTITUTE(SUBSTITUTE(SUBSTITUTE(SUBSTITUTE(SUBSTITUTE(AD17,"__","_"),"__","_"),"__","_"),"__","_"),"__","_"),"__","_"),"__","_"),"__","_")) | AF17: =IF(OR(AE17="",AE17="_"),"",IF(LEFT(AE17,1)="_",IF(RIGHT(AE17,1)="_",MID(AE17,2,LEN(AE17)-2),RIGHT(AE17,LEN(AE17)-1)),IF(RIGHT(AE17,1)="_",LEFT(AE17,LEN(AE17)-1),AE17))) | AG17: =IF(OR(LOWER(TRIM(P17))="",LOWER(TRIM(P17))="nan",LOWER(TRIM(P17))="none",LOWER(TRIM(P17))="n/a"),"",SUBSTITUTE(SUBSTITUTE(SUBSTITUTE(SUBSTITUTE(SUBSTITUTE(SUBSTITUTE(SUBSTITUTE(SUBSTITUTE(SUBSTITUTE(SUBSTITUTE(SUBSTITUTE(SUBSTITUTE(SUBSTITUTE(SUBSTITUTE(SUBSTITUTE(SUBSTITUTE(SUBSTITUTE(SUBSTITUTE(SUBSTITUTE(SUBSTITUTE(SUBSTITUTE(SUBSTITUTE(SUBSTITUTE(SUBSTITUTE(SUBSTITUTE(SUBSTITUTE(SUBSTITUTE(SUBSTITUTE(SUBSTITUTE(SUBSTITUTE(SUBSTITUTE(SUBSTITUTE(SUBSTITUTE(SUBSTITUTE(SUBSTITUTE(SUBSTITUTE(SUBSTITUTE(SUBSTITUTE(LOWER(TRIM(P17))," ","_"),"!","_"),"#","_"),"$","_"),"%","_"),"&","_"),"'","_"),"(","_"),")","_"),"*","_"),"+","_"),",","_"),"-","_"),".","_"),"/","_"),":","_"),";","_"),"<","_"),"=","_"),">","_"),"?","_"),"@","_"),"[","_"),"\","_"),"]","_"),"^","_"),"`","_"),"{","_"),"|","_"),"}","_"),"~","_"),"–","_"),"—","_"),"’","_"),"“","_"),"”","_"),CHAR(9),"_"),CHAR(160),"_")) | AH17: =IF(AG17="","",SUBSTITUTE(SUBSTITUTE(SUBSTITUTE(SUBSTITUTE(SUBSTITUTE(SUBSTITUTE(SUBSTITUTE(SUBSTITUTE(AG17,"__","_"),"__","_"),"__","_"),"__","_"),"__","_"),"__","_"),"__","_"),"__","_")) | AI17: =IF(OR(AH17="",AH17="_"),"",IF(LEFT(AH17,1)="_",IF(RIGHT(AH17,1)="_",MID(AH17,2,LEN(AH17)-2),RIGHT(AH17,LEN(AH17)-1)),IF(RIGHT(AH17,1)="_",LEFT(AH17,LEN(AH17)-1),AH17)))
L18: =IF(AC18<>"",AC18,"")&IF(AF18<>"",IF(AC18<>"","_"&AF18,AF18),"")&IF(AI18<>"",IF(AC18<>"","_"&AI18,AI18),"") | M18: =IF(TRIM(K18)<>"",TRIM(K18),L18) | N18: =IF(OR(A18="",B18="",C18="",D18="",F18="",G18="",H18="",I18=""),"Missing required field — fill in channel, market, activity_ownership, intended_model_role, model_input_measure, economic_treatment, planning_eligibility, and source.",IF(L18="","Missing required field — channel must be filled in to build an ID.",IF(COUNTIF($M$8:$M$31,M18)>1,"Duplicate activity ID — two rows currently build the same activity_id; add the next meaningful field, not a random number.",IF(AND(J18<>"",J18<>M18),"Existing activity_id differs from the built ID — review before using.","Ready")))) | AA18: =IF(OR(LOWER(TRIM(A18))="",LOWER(TRIM(A18))="nan",LOWER(TRIM(A18))="none",LOWER(TRIM(A18))="n/a"),"",SUBSTITUTE(SUBSTITUTE(SUBSTITUTE(SUBSTITUTE(SUBSTITUTE(SUBSTITUTE(SUBSTITUTE(SUBSTITUTE(SUBSTITUTE(SUBSTITUTE(SUBSTITUTE(SUBSTITUTE(SUBSTITUTE(SUBSTITUTE(SUBSTITUTE(SUBSTITUTE(SUBSTITUTE(SUBSTITUTE(SUBSTITUTE(SUBSTITUTE(SUBSTITUTE(SUBSTITUTE(SUBSTITUTE(SUBSTITUTE(SUBSTITUTE(SUBSTITUTE(SUBSTITUTE(SUBSTITUTE(SUBSTITUTE(SUBSTITUTE(SUBSTITUTE(SUBSTITUTE(SUBSTITUTE(SUBSTITUTE(SUBSTITUTE(SUBSTITUTE(SUBSTITUTE(SUBSTITUTE(LOWER(TRIM(A18))," ","_"),"!","_"),"#","_"),"$","_"),"%","_"),"&","_"),"'","_"),"(","_"),")","_"),"*","_"),"+","_"),",","_"),"-","_"),".","_"),"/","_"),":","_"),";","_"),"<","_"),"=","_"),">","_"),"?","_"),"@","_"),"[","_"),"\","_"),"]","_"),"^","_"),"`","_"),"{","_"),"|","_"),"}","_"),"~","_"),"–","_"),"—","_"),"’","_"),"“","_"),"”","_"),CHAR(9),"_"),CHAR(160),"_")) | AB18: =IF(AA18="","",SUBSTITUTE(SUBSTITUTE(SUBSTITUTE(SUBSTITUTE(SUBSTITUTE(SUBSTITUTE(SUBSTITUTE(SUBSTITUTE(AA18,"__","_"),"__","_"),"__","_"),"__","_"),"__","_"),"__","_"),"__","_"),"__","_")) | AC18: =IF(OR(AB18="",AB18="_"),"",IF(LEFT(AB18,1)="_",IF(RIGHT(AB18,1)="_",MID(AB18,2,LEN(AB18)-2),RIGHT(AB18,LEN(AB18)-1)),IF(RIGHT(AB18,1)="_",LEFT(AB18,LEN(AB18)-1),AB18))) | AD18: =IF(OR(LOWER(TRIM(O18))="",LOWER(TRIM(O18))="nan",LOWER(TRIM(O18))="none",LOWER(TRIM(O18))="n/a"),"",SUBSTITUTE(SUBSTITUTE(SUBSTITUTE(SUBSTITUTE(SUBSTITUTE(SUBSTITUTE(SUBSTITUTE(SUBSTITUTE(SUBSTITUTE(SUBSTITUTE(SUBSTITUTE(SUBSTITUTE(SUBSTITUTE(SUBSTITUTE(SUBSTITUTE(SUBSTITUTE(SUBSTITUTE(SUBSTITUTE(SUBSTITUTE(SUBSTITUTE(SUBSTITUTE(SUBSTITUTE(SUBSTITUTE(SUBSTITUTE(SUBSTITUTE(SUBSTITUTE(SUBSTITUTE(SUBSTITUTE(SUBSTITUTE(SUBSTITUTE(SUBSTITUTE(SUBSTITUTE(SUBSTITUTE(SUBSTITUTE(SUBSTITUTE(SUBSTITUTE(SUBSTITUTE(SUBSTITUTE(LOWER(TRIM(O18))," ","_"),"!","_"),"#","_"),"$","_"),"%","_"),"&","_"),"'","_"),"(","_"),")","_"),"*","_"),"+","_"),",","_"),"-","_"),".","_"),"/","_"),":","_"),";","_"),"<","_"),"=","_"),">","_"),"?","_"),"@","_"),"[","_"),"\","_"),"]","_"),"^","_"),"`","_"),"{","_"),"|","_"),"}","_"),"~","_"),"–","_"),"—","_"),"’","_"),"“","_"),"”","_"),CHAR(9),"_"),CHAR(160),"_")) | AE18: =IF(AD18="","",SUBSTITUTE(SUBSTITUTE(SUBSTITUTE(SUBSTITUTE(SUBSTITUTE(SUBSTITUTE(SUBSTITUTE(SUBSTITUTE(AD18,"__","_"),"__","_"),"__","_"),"__","_"),"__","_"),"__","_"),"__","_"),"__","_")) | AF18: =IF(OR(AE18="",AE18="_"),"",IF(LEFT(AE18,1)="_",IF(RIGHT(AE18,1)="_",MID(AE18,2,LEN(AE18)-2),RIGHT(AE18,LEN(AE18)-1)),IF(RIGHT(AE18,1)="_",LEFT(AE18,LEN(AE18)-1),AE18))) | AG18: =IF(OR(LOWER(TRIM(P18))="",LOWER(TRIM(P18))="nan",LOWER(TRIM(P18))="none",LOWER(TRIM(P18))="n/a"),"",SUBSTITUTE(SUBSTITUTE(SUBSTITUTE(SUBSTITUTE(SUBSTITUTE(SUBSTITUTE(SUBSTITUTE(SUBSTITUTE(SUBSTITUTE(SUBSTITUTE(SUBSTITUTE(SUBSTITUTE(SUBSTITUTE(SUBSTITUTE(SUBSTITUTE(SUBSTITUTE(SUBSTITUTE(SUBSTITUTE(SUBSTITUTE(SUBSTITUTE(SUBSTITUTE(SUBSTITUTE(SUBSTITUTE(SUBSTITUTE(SUBSTITUTE(SUBSTITUTE(SUBSTITUTE(SUBSTITUTE(SUBSTITUTE(SUBSTITUTE(SUBSTITUTE(SUBSTITUTE(SUBSTITUTE(SUBSTITUTE(SUBSTITUTE(SUBSTITUTE(SUBSTITUTE(SUBSTITUTE(LOWER(TRIM(P18))," ","_"),"!","_"),"#","_"),"$","_"),"%","_"),"&","_"),"'","_"),"(","_"),")","_"),"*","_"),"+","_"),",","_"),"-","_"),".","_"),"/","_"),":","_"),";","_"),"<","_"),"=","_"),">","_"),"?","_"),"@","_"),"[","_"),"\","_"),"]","_"),"^","_"),"`","_"),"{","_"),"|","_"),"}","_"),"~","_"),"–","_"),"—","_"),"’","_"),"“","_"),"”","_"),CHAR(9),"_"),CHAR(160),"_")) | AH18: =IF(AG18="","",SUBSTITUTE(SUBSTITUTE(SUBSTITUTE(SUBSTITUTE(SUBSTITUTE(SUBSTITUTE(SUBSTITUTE(SUBSTITUTE(AG18,"__","_"),"__","_"),"__","_"),"__","_"),"__","_"),"__","_"),"__","_"),"__","_")) | AI18: =IF(OR(AH18="",AH18="_"),"",IF(LEFT(AH18,1)="_",IF(RIGHT(AH18,1)="_",MID(AH18,2,LEN(AH18)-2),RIGHT(AH18,LEN(AH18)-1)),IF(RIGHT(AH18,1)="_",LEFT(AH18,LEN(AH18)-1),AH18)))
L19: =IF(AC19<>"",AC19,"")&IF(AF19<>"",IF(AC19<>"","_"&AF19,AF19),"")&IF(AI19<>"",IF(AC19<>"","_"&AI19,AI19),"") | M19: =IF(TRIM(K19)<>"",TRIM(K19),L19) | N19: =IF(OR(A19="",B19="",C19="",D19="",F19="",G19="",H19="",I19=""),"Missing required field — fill in channel, market, activity_ownership, intended_model_role, model_input_measure, economic_treatment, planning_eligibility, and source.",IF(L19="","Missing required field — channel must be filled in to build an ID.",IF(COUNTIF($M$8:$M$31,M19)>1,"Duplicate activity ID — two rows currently build the same activity_id; add the next meaningful field, not a random number.",IF(AND(J19<>"",J19<>M19),"Existing activity_id differs from the built ID — review before using.","Ready")))) | AA19: =IF(OR(LOWER(TRIM(A19))="",LOWER(TRIM(A19))="nan",LOWER(TRIM(A19))="none",LOWER(TRIM(A19))="n/a"),"",SUBSTITUTE(SUBSTITUTE(SUBSTITUTE(SUBSTITUTE(SUBSTITUTE(SUBSTITUTE(SUBSTITUTE(SUBSTITUTE(SUBSTITUTE(SUBSTITUTE(SUBSTITUTE(SUBSTITUTE(SUBSTITUTE(SUBSTITUTE(SUBSTITUTE(SUBSTITUTE(SUBSTITUTE(SUBSTITUTE(SUBSTITUTE(SUBSTITUTE(SUBSTITUTE(SUBSTITUTE(SUBSTITUTE(SUBSTITUTE(SUBSTITUTE(SUBSTITUTE(SUBSTITUTE(SUBSTITUTE(SUBSTITUTE(SUBSTITUTE(SUBSTITUTE(SUBSTITUTE(SUBSTITUTE(SUBSTITUTE(SUBSTITUTE(SUBSTITUTE(SUBSTITUTE(SUBSTITUTE(LOWER(TRIM(A19))," ","_"),"!","_"),"#","_"),"$","_"),"%","_"),"&","_"),"'","_"),"(","_"),")","_"),"*","_"),"+","_"),",","_"),"-","_"),".","_"),"/","_"),":","_"),";","_"),"<","_"),"=","_"),">","_"),"?","_"),"@","_"),"[","_"),"\","_"),"]","_"),"^","_"),"`","_"),"{","_"),"|","_"),"}","_"),"~","_"),"–","_"),"—","_"),"’","_"),"“","_"),"”","_"),CHAR(9),"_"),CHAR(160),"_")) | AB19: =IF(AA19="","",SUBSTITUTE(SUBSTITUTE(SUBSTITUTE(SUBSTITUTE(SUBSTITUTE(SUBSTITUTE(SUBSTITUTE(SUBSTITUTE(AA19,"__","_"),"__","_"),"__","_"),"__","_"),"__","_"),"__","_"),"__","_"),"__","_")) | AC19: =IF(OR(AB19="",AB19="_"),"",IF(LEFT(AB19,1)="_",IF(RIGHT(AB19,1)="_",MID(AB19,2,LEN(AB19)-2),RIGHT(AB19,LEN(AB19)-1)),IF(RIGHT(AB19,1)="_",LEFT(AB19,LEN(AB19)-1),AB19))) | AD19: =IF(OR(LOWER(TRIM(O19))="",LOWER(TRIM(O19))="nan",LOWER(TRIM(O19))="none",LOWER(TRIM(O19))="n/a"),"",SUBSTITUTE(SUBSTITUTE(SUBSTITUTE(SUBSTITUTE(SUBSTITUTE(SUBSTITUTE(SUBSTITUTE(SUBSTITUTE(SUBSTITUTE(SUBSTITUTE(SUBSTITUTE(SUBSTITUTE(SUBSTITUTE(SUBSTITUTE(SUBSTITUTE(SUBSTITUTE(SUBSTITUTE(SUBSTITUTE(SUBSTITUTE(SUBSTITUTE(SUBSTITUTE(SUBSTITUTE(SUBSTITUTE(SUBSTITUTE(SUBSTITUTE(SUBSTITUTE(SUBSTITUTE(SUBSTITUTE(SUBSTITUTE(SUBSTITUTE(SUBSTITUTE(SUBSTITUTE(SUBSTITUTE(SUBSTITUTE(SUBSTITUTE(SUBSTITUTE(SUBSTITUTE(SUBSTITUTE(LOWER(TRIM(O19))," ","_"),"!","_"),"#","_"),"$","_"),"%","_"),"&","_"),"'","_"),"(","_"),")","_"),"*","_"),"+","_"),",","_"),"-","_"),".","_"),"/","_"),":","_"),";","_"),"<","_"),"=","_"),">","_"),"?","_"),"@","_"),"[","_"),"\","_"),"]","_"),"^","_"),"`","_"),"{","_"),"|","_"),"}","_"),"~","_"),"–","_"),"—","_"),"’","_"),"“","_"),"”","_"),CHAR(9),"_"),CHAR(160),"_")) | AE19: =IF(AD19="","",SUBSTITUTE(SUBSTITUTE(SUBSTITUTE(SUBSTITUTE(SUBSTITUTE(SUBSTITUTE(SUBSTITUTE(SUBSTITUTE(AD19,"__","_"),"__","_"),"__","_"),"__","_"),"__","_"),"__","_"),"__","_"),"__","_")) | AF19: =IF(OR(AE19="",AE19="_"),"",IF(LEFT(AE19,1)="_",IF(RIGHT(AE19,1)="_",MID(AE19,2,LEN(AE19)-2),RIGHT(AE19,LEN(AE19)-1)),IF(RIGHT(AE19,1)="_",LEFT(AE19,LEN(AE19)-1),AE19))) | AG19: =IF(OR(LOWER(TRIM(P19))="",LOWER(TRIM(P19))="nan",LOWER(TRIM(P19))="none",LOWER(TRIM(P19))="n/a"),"",SUBSTITUTE(SUBSTITUTE(SUBSTITUTE(SUBSTITUTE(SUBSTITUTE(SUBSTITUTE(SUBSTITUTE(SUBSTITUTE(SUBSTITUTE(SUBSTITUTE(SUBSTITUTE(SUBSTITUTE(SUBSTITUTE(SUBSTITUTE(SUBSTITUTE(SUBSTITUTE(SUBSTITUTE(SUBSTITUTE(SUBSTITUTE(SUBSTITUTE(SUBSTITUTE(SUBSTITUTE(SUBSTITUTE(SUBSTITUTE(SUBSTITUTE(SUBSTITUTE(SUBSTITUTE(SUBSTITUTE(SUBSTITUTE(SUBSTITUTE(SUBSTITUTE(SUBSTITUTE(SUBSTITUTE(SUBSTITUTE(SUBSTITUTE(SUBSTITUTE(SUBSTITUTE(SUBSTITUTE(LOWER(TRIM(P19))," ","_"),"!","_"),"#","_"),"$","_"),"%","_"),"&","_"),"'","_"),"(","_"),")","_"),"*","_"),"+","_"),",","_"),"-","_"),".","_"),"/","_"),":","_"),";","_"),"<","_"),"=","_"),">","_"),"?","_"),"@","_"),"[","_"),"\","_"),"]","_"),"^","_"),"`","_"),"{","_"),"|","_"),"}","_"),"~","_"),"–","_"),"—","_"),"’","_"),"“","_"),"”","_"),CHAR(9),"_"),CHAR(160),"_")) | AH19: =IF(AG19="","",SUBSTITUTE(SUBSTITUTE(SUBSTITUTE(SUBSTITUTE(SUBSTITUTE(SUBSTITUTE(SUBSTITUTE(SUBSTITUTE(AG19,"__","_"),"__","_"),"__","_"),"__","_"),"__","_"),"__","_"),"__","_"),"__","_")) | AI19: =IF(OR(AH19="",AH19="_"),"",IF(LEFT(AH19,1)="_",IF(RIGHT(AH19,1)="_",MID(AH19,2,LEN(AH19)-2),RIGHT(AH19,LEN(AH19)-1)),IF(RIGHT(AH19,1)="_",LEFT(AH19,LEN(AH19)-1),AH19)))
