Workbook

Sheet START_HERE
A1: Outcome / KPI Dictionary Builder
A2: Formula-driven, no VBA -- builds a complete outcome_dictionary row and its outcome_id
A4: What this builder is for
A5: Use this workbook to define one row per KPI (outcome) you want the model to explain -- things like GSA, sign-ups, or Net Bill Through, split by segment.
A6: It asks only for the choices you genuinely have to make, builds a stable outcome_id for you, and produces a clean row ready to paste into the outcome_dictionary sheet of the standard Outcomes upload workbook.
A8: What you need to fill in
A9: Go to the BUILDER sheet. Fill in product, metric_key, segment, and metric for every KPI row -- these are the fields outcome_id is built from.
A10: Only fill in the amber (Fields you may need) columns if they apply: outcome grouping, eligibility overrides, or value reporting. Leave them blank otherwise -- the app already has sensible defaults.
A11: Only fill in the grey (official-approval) columns once you are ready to get this outcome approved for production reporting.
A13: What is generated automatically
A14: Generated ID -- built from product + metric_key + segment.
A15: Final ID -- the Generated ID, unless you type something in Manual override.
... A36: This builder never asks for your weekly numbers. Those go in the outcomes sheet of the same Outcomes upload workbook -- one column per outcome_id, one row per period_start x market.

Sheet BUILDER
A7: product | B7: metric_key | C7: segment | D7: metric | E7: source_column | F7: outcome_id (existing) | G7: Manual override | H7: Generated ID | I7: Final ID | J7: Row status | K7: segment_dimension | L7: outcome_group_id | M7: outcome_group_label | N7: outcome_family_key | O7: group_aggregation | P7: role | Q7: included_in_fit | R7: include_in_default_reporting | S7: include_in_official_total | T7: include_in_value | U7: include_in_optimisation | V7: value_weight | W7: value_currency | X7: definition_version | Y7: event_definition | Z7: cohort_or_attribution_basis | AA7: completeness_or_maturity_policy | AB7: exclusions | AC7: reconciliation_source | AD7: business_owner | AE7: effective_from | AF7: effective_to | AI7: _A_clean | AJ7: _A_collapsed | AK7: _A_token | AL7: _B_clean | AM7: _B_collapsed | AN7: _B_token | AO7: _C_clean | AP7: _C_collapsed | AQ7: _C_token
A8: Family History | B8: fh_gsa | C8: New | D8: GSA | H8: =IF(AK8<>"",AK8,"")&IF(AN8<>"",IF(AK8<>"","_"&AN8,AN8),"")&IF(AQ8<>"",IF(AK8<>"","_"&AQ8,AQ8),"") | I8: =IF(TRIM(G8)<>"",TRIM(G8),H8) | J8: =IF(OR(A8="",B8="",C8="",D8=""),"Missing required field — fill in product, metric_key, segment, and metric before this row can be used.",IF(H8="","Missing required field — product, metric_key, and segment must combine into an ID.",IF(COUNTIF($I$8:$I$32,I8)>1,"Duplicate outcome ID — two rows currently build the same outcome_id; add a distinguishing detail.",IF(AND(F8<>"",F8<>I8),"Existing outcome_id differs from the built ID — review before using.","Ready")))) | AI8: =IF(OR(LOWER(TRIM(A8))="",LOWER(TRIM(A8))="nan",LOWER(TRIM(A8))="none",LOWER(TRIM(A8))="n/a"),"",SUBSTITUTE(SUBSTITUTE(SUBSTITUTE(SUBSTITUTE(SUBSTITUTE(SUBSTITUTE(SUBSTITUTE(SUBSTITUTE(SUBSTITUTE(SUBSTITUTE(SUBSTITUTE(SUBSTITUTE(SUBSTITUTE(SUBSTITUTE(SUBSTITUTE(SUBSTITUTE(SUBSTITUTE(SUBSTITUTE(SUBSTITUTE(SUBSTITUTE(SUBSTITUTE(SUBSTITUTE(SUBSTITUTE(SUBSTITUTE(SUBSTITUTE(SUBSTITUTE(SUBSTITUTE(SUBSTITUTE(SUBSTITUTE(SUBSTITUTE(SUBSTITUTE(SUBSTITUTE(SUBSTITUTE(SUBSTITUTE(SUBSTITUTE(SUBSTITUTE(SUBSTITUTE(SUBSTITUTE(LOWER(TRIM(A8))," ","_"),"!","_"),"#","_"),"$","_"),"%","_"),"&","_"),"'","_"),"(","_"),")","_"),"*","_"),"+","_"),",","_"),"-","_"),".","_"),"/","_"),":","_"),";","_"),"<","_"),"=","_"),">","_"),"?","_"),"@","_"),"[","_"),"\","_"),"]","_"),"^","_"),"`","_"),"{","_"),"|","_"),"}","_"),"~","_"),"–","_"),"—","_"),"’","_"),"“","_"),"”","_"),CHAR(9),"_"),CHAR(160),"_")) | AJ8: =IF(AI8="","",SUBSTITUTE(SUBSTITUTE(SUBSTITUTE(SUBSTITUTE(SUBSTITUTE(SUBSTITUTE(SUBSTITUTE(SUBSTITUTE(AI8,"__","_"),"__","_"),"__","_"),"__","_"),"__","_"),"__","_"),"__","_"),"__","_")) | AK8: =IF(OR(AJ8="",AJ8="_"),"",IF(LEFT(AJ8,1)="_",IF(RIGHT(AJ8,1)="_",MID(AJ8,2,LEN(AJ8)-2),RIGHT(AJ8,LEN(AJ8)-1)),IF(RIGHT(AJ8,1)="_",LEFT(AJ8,LEN(AJ8)-1),AJ8))) | AL8: =IF(OR(LOWER(TRIM(B8))="",LOWER(TRIM(B8))="nan",LOWER(TRIM(B8))="none",LOWER(TRIM(B8))="n/a"),"",SUBSTITUTE(SUBSTITUTE(SUBSTITUTE(SUBSTITUTE(SUBSTITUTE(SUBSTITUTE(SUBSTITUTE(SUBSTITUTE(SUBSTITUTE(SUBSTITUTE(SUBSTITUTE(SUBSTITUTE(SUBSTITUTE(SUBSTITUTE(SUBSTITUTE(SUBSTITUTE(SUBSTITUTE(SUBSTITUTE(SUBSTITUTE(SUBSTITUTE(SUBSTITUTE(SUBSTITUTE(SUBSTITUTE(SUBSTITUTE(SUBSTITUTE(SUBSTITUTE(SUBSTITUTE(SUBSTITUTE(SUBSTITUTE(SUBSTITUTE(SUBSTITUTE(SUBSTITUTE(SUBSTITUTE(SUBSTITUTE(SUBSTITUTE(SUBSTITUTE(SUBSTITUTE(SUBSTITUTE(LOWER(TRIM(B8))," ","_"),"!","_"),"#","_"),"$","_"),"%","_"),"&","_"),"'","_"),"(","_"),")","_"),"*","_"),"+","_"),",","_"),"-","_"),".","_"),"/","_"),":","_"),";","_"),"<","_"),"=","_"),">","_"),"?","_"),"@","_"),"[","_"),"\","_"),"]","_"),"^","_"),"`","_"),"{","_"),"|","_"),"}","_"),"~","_"),"–","_"),"—","_"),"’","_"),"“","_"),"”","_"),CHAR(9),"_"),CHAR(160),"_")) | AM8: =IF(AL8="","",SUBSTITUTE(SUBSTITUTE(SUBSTITUTE(SUBSTITUTE(SUBSTITUTE(SUBSTITUTE(SUBSTITUTE(SUBSTITUTE(AL8,"__","_"),"__","_"),"__","_"),"__","_"),"__","_"),"__","_"),"__","_"),"__","_")) | AN8: =IF(OR(AM8="",AM8="_"),"",IF(LEFT(AM8,1)="_",IF(RIGHT(AM8,1)="_",MID(AM8,2,LEN(AM8)-2),RIGHT(AM8,LEN(AM8)-1)),IF(RIGHT(AM8,1)="_",LEFT(AM8,LEN(AM8)-1),AM8))) | AO8: =IF(OR(LOWER(TRIM(C8))="",LOWER(TRIM(C8))="nan",LOWER(TRIM(C8))="none",LOWER(TRIM(C8))="n/a"),"",SUBSTITUTE(SUBSTITUTE(SUBSTITUTE(SUBSTITUTE(SUBSTITUTE(SUBSTITUTE(SUBSTITUTE(SUBSTITUTE(SUBSTITUTE(SUBSTITUTE(SUBSTITUTE(SUBSTITUTE(SUBSTITUTE(SUBSTITUTE(SUBSTITUTE(SUBSTITUTE(SUBSTITUTE(SUBSTITUTE(SUBSTITUTE(SUBSTITUTE(SUBSTITUTE(SUBSTITUTE(SUBSTITUTE(SUBSTITUTE(SUBSTITUTE(SUBSTITUTE(SUBSTITUTE(SUBSTITUTE(SUBSTITUTE(SUBSTITUTE(SUBSTITUTE(SUBSTITUTE(SUBSTITUTE(SUBSTITUTE(SUBSTITUTE(SUBSTITUTE(SUBSTITUTE(SUBSTITUTE(LOWER(TRIM(C8))," ","_"),"!","_"),"#","_"),"$","_"),"%","_"),"&","_"),"'","_"),"(","_"),")","_"),"*","_"),"+","_"),",","_"),"-","_"),".","_"),"/","_"),":","_"),";","_"),"<","_"),"=","_"),">","_"),"?","_"),"@","_"),"[","_"),"\","_"),"]","_"),"^","_"),"`","_"),"{","_"),"|","_"),"}","_"),"~","_"),"–","_"),"—","_"),"’","_"),"“","_"),"”","_"),CHAR(9),"_"),CHAR(160),"_")) | AP8: =IF(AO8="","",SUBSTITUTE(SUBSTITUTE(SUBSTITUTE(SUBSTITUTE(SUBSTITUTE(SUBSTITUTE(SUBSTITUTE(SUBSTITUTE(AO8,"__","_"),"__","_"),"__","_"),"__","_"),"__","_"),"__","_"),"__","_"),"__","_")) | AQ8: =IF(OR(AP8="",AP8="_"),"",IF(LEFT(AP8,1)="_",IF(RIGHT(AP8,1)="_",MID(AP8,2,LEN(AP8)-2),RIGHT(AP8,LEN(AP8)-1)),IF(RIGHT(AP8,1)="_",LEFT(AP8,LEN(AP8)-1),AP8)))
A9: Family History | B9: fh_gsa | C9: DNA_CrossSell | D9: GSA | H9: =IF(AK9<>"",AK9,"")&IF(AN9<>"",IF(AK9<>"","_"&AN9,AN9),"")&IF(AQ9<>"",IF(AK9<>"","_"&AQ9,AQ9),"") | I9: =IF(TRIM(G9)<>"",TRIM(G9),H9) | J9: =IF(OR(A9="",B9="",C9="",D9=""),"Missing required field — fill in product, metric_key, segment, and metric before this row can be used.",IF(H9="","Missing required field — product, metric_key, and segment must combine into an ID.",IF(COUNTIF($I$8:$I$32,I9)>1,"Duplicate outcome ID — two rows currently build the same outcome_id; add a distinguishing detail.",IF(AND(F9<>"",F9<>I9),"Existing outcome_id differs from the built ID — review before using.","Ready")))) | AI9: =IF(OR(LOWER(TRIM(A9))="",LOWER(TRIM(A9))="nan",LOWER(TRIM(A9))="none",LOWER(TRIM(A9))="n/a"),"",SUBSTITUTE(SUBSTITUTE(SUBSTITUTE(SUBSTITUTE(SUBSTITUTE(SUBSTITUTE(SUBSTITUTE(SUBSTITUTE(SUBSTITUTE(SUBSTITUTE(SUBSTITUTE(SUBSTITUTE(SUBSTITUTE(SUBSTITUTE(SUBSTITUTE(SUBSTITUTE(SUBSTITUTE(SUBSTITUTE(SUBSTITUTE(SUBSTITUTE(SUBSTITUTE(SUBSTITUTE(SUBSTITUTE(SUBSTITUTE(SUBSTITUTE(SUBSTITUTE(SUBSTITUTE(SUBSTITUTE(SUBSTITUTE(SUBSTITUTE(SUBSTITUTE(SUBSTITUTE(SUBSTITUTE(SUBSTITUTE(SUBSTITUTE(SUBSTITUTE(SUBSTITUTE(SUBSTITUTE(LOWER(TRIM(A9))," ","_"),"!","_"),"#","_"),"$","_"),"%","_"),"&","_"),"'","_"),"(","_"),")","_"),"*","_"),"+","_"),",","_"),"-","_"),".","_"),"/","_"),":","_"),";","_"),"<","_"),"=","_"),">","_"),"?","_"),"@","_"),"[","_"),"\","_"),"]","_"),"^","_"),"`","_"),"{","_"),"|","_"),"}","_"),"~","_"),"–","_"),"—","_"),"’","_"),"“","_"),"”","_"),CHAR(9),"_"),CHAR(160),"_")) | AJ9: =IF(AI9="","",SUBSTITUTE(SUBSTITUTE(SUBSTITUTE(SUBSTITUTE(SUBSTITUTE(SUBSTITUTE(SUBSTITUTE(SUBSTITUTE(AI9,"__","_"),"__","_"),"__","_"),"__","_"),"__","_"),"__","_"),"__","_"),"__","_")) | AK9: =IF(OR(AJ9="",AJ9="_"),"",IF(LEFT(AJ9,1)="_",IF(RIGHT(AJ9,1)="_",MID(AJ9,2,LEN(AJ9)-2),RIGHT(AJ9,LEN(AJ9)-1)),IF(RIGHT(AJ9,1)="_",LEFT(AJ9,LEN(AJ9)-1),AJ9))) | AL9: =IF(OR(LOWER(TRIM(B9))="",LOWER(TRIM(B9))="nan",LOWER(TRIM(B9))="none",LOWER(TRIM(B9))="n/a"),"",SUBSTITUTE(SUBSTITUTE(SUBSTITUTE(SUBSTITUTE(SUBSTITUTE(SUBSTITUTE(SUBSTITUTE(SUBSTITUTE(SUBSTITUTE(SUBSTITUTE(SUBSTITUTE(SUBSTITUTE(SUBSTITUTE(SUBSTITUTE(SUBSTITUTE(SUBSTITUTE(SUBSTITUTE(SUBSTITUTE(SUBSTITUTE(SUBSTITUTE(SUBSTITUTE(SUBSTITUTE(SUBSTITUTE(SUBSTITUTE(SUBSTITUTE(SUBSTITUTE(SUBSTITUTE(SUBSTITUTE(SUBSTITUTE(SUBSTITUTE(SUBSTITUTE(SUBSTITUTE(SUBSTITUTE(SUBSTITUTE(SUBSTITUTE(SUBSTITUTE(SUBSTITUTE(SUBSTITUTE(LOWER(TRIM(B9))," ","_"),"!","_"),"#","_"),"$","_"),"%","_"),"&","_"),"'","_"),"(","_"),")","_"),"*","_"),"+","_"),",","_"),"-","_"),".","_"),"/","_"),":","_"),";","_"),"<","_"),"=","_"),">","_"),"?","_"),"@","_"),"[","_"),"\","_"),"]","_"),"^","_"),"`","_"),"{","_"),"|","_"),"}","_"),"~","_"),"–","_"),"—","_"),"’","_"),"“","_"),"”","_"),CHAR(9),"_"),CHAR(160),"_")) | AM9: =IF(AL9="","",SUBSTITUTE(SUBSTITUTE(SUBSTITUTE(SUBSTITUTE(SUBSTITUTE(SUBSTITUTE(SUBSTITUTE(SUBSTITUTE(AL9,"__","_"),"__","_"),"__","_"),"__","_"),"__","_"),"__","_"),"__","_"),"__","_")) | AN9: =IF(OR(AM9="",AM9="_"),"",IF(LEFT(AM9,1)="_",IF(RIGHT(AM9,1)="_",MID(AM9,2,LEN(AM9)-2),RIGHT(AM9,LEN(AM9)-1)),IF(RIGHT(AM9,1)="_",LEFT(AM9,LEN(AM9)-1),AM9))) | AO9: =IF(OR(LOWER(TRIM(C9))="",LOWER(TRIM(C9))="nan",LOWER(TRIM(C9))="none",LOWER(TRIM(C9))="n/a"),"",SUBSTITUTE(SUBSTITUTE(SUBSTITUTE(SUBSTITUTE(SUBSTITUTE(SUBSTITUTE(SUBSTITUTE(SUBSTITUTE(SUBSTITUTE(SUBSTITUTE(SUBSTITUTE(SUBSTITUTE(SUBSTITUTE(SUBSTITUTE(SUBSTITUTE(SUBSTITUTE(SUBSTITUTE(SUBSTITUTE(SUBSTITUTE(SUBSTITUTE(SUBSTITUTE(SUBSTITUTE(SUBSTITUTE(SUBSTITUTE(SUBSTITUTE(SUBSTITUTE(SUBSTITUTE(SUBSTITUTE(SUBSTITUTE(SUBSTITUTE(SUBSTITUTE(SUBSTITUTE(SUBSTITUTE(SUBSTITUTE(SUBSTITUTE(SUBSTITUTE(SUBSTITUTE(SUBSTITUTE(LOWER(TRIM(C9))," ","_"),"!","_"),"#","_"),"$","_"),"%","_"),"&","_"),"'","_"),"(","_"),")","_"),"*","_"),"+","_"),",","_"),"-","_"),".","_"),"/","_"),":","_"),";","_"),"<","_"),"=","_"),">","_"),"?","_"),"@","_"),"[","_"),"\","_"),"]","_"),"^","_"),"`","_"),"{","_"),"|","_"),"}","_"),"~","_"),"–","_"),"—","_"),"’","_"),"“","_"),"”","_"),CHAR(9),"_"),CHAR(160),"_")) | AP9: =IF(AO9="","",SUBSTITUTE(SUBSTITUTE(SUBSTITUTE(SUBSTITUTE(SUBSTITUTE(SUBSTITUTE(SUBSTITUTE(SUBSTITUTE(AO9,"__","_"),"__","_"),"__","_"),"__","_"),"__","_"),"__","_"),"__","_"),"__","_")) | AQ9: =IF(OR(AP9="",AP9="_"),"",IF(LEFT(AP9,1)="_",IF(RIGHT(AP9,1)="_",MID(AP9,2,LEN(AP9)-2),RIGHT(AP9,LEN(AP9)-1)),IF(RIGHT(AP9,1)="_",LEFT(AP9,LEN(AP9)-1),AP9)))
A10: Family History | B10: fh_gsa | C10: Winback | D10: GSA | H10: =IF(AK10<>"",AK10,"")&IF(AN10<>"",IF(AK10<>"","_"&AN10,AN10),"")&IF(AQ10<>"",IF(AK10<>"","_"&AQ10,AQ10),"") | I10: =IF(TRIM(G10)<>"",TRIM(G10),H10) | J10: =IF(OR(A10="",B10="",C10="",D10=""),"Missing required field — fill in product, metric_key, segment, and metric before this row can be used.",IF(H10="","Missing required field — product, metric_key, and segment must combine into an ID.",IF(COUNTIF($I$8:$I$32,I10)>1,"Duplicate outcome ID — two rows currently build the same outcome_id; add a distinguishing detail.",IF(AND(F10<>"",F10<>I10),"Existing outcome_id differs from the built ID — review before using.","Ready")))) | AI10: =IF(OR(LOWER(TRIM(A10))="",LOWER(TRIM(A10))="nan",LOWER(TRIM(A10))="none",LOWER(TRIM(A10))="n/a"),"",SUBSTITUTE(SUBSTITUTE(SUBSTITUTE(SUBSTITUTE(SUBSTITUTE(SUBSTITUTE(SUBSTITUTE(SUBSTITUTE(SUBSTITUTE(SUBSTITUTE(SUBSTITUTE(SUBSTITUTE(SUBSTITUTE(SUBSTITUTE(SUBSTITUTE(SUBSTITUTE(SUBSTITUTE(SUBSTITUTE(SUBSTITUTE(SUBSTITUTE(SUBSTITUTE(SUBSTITUTE(SUBSTITUTE(SUBSTITUTE(SUBSTITUTE(SUBSTITUTE(SUBSTITUTE(SUBSTITUTE(SUBSTITUTE(SUBSTITUTE(SUBSTITUTE(SUBSTITUTE(SUBSTITUTE(SUBSTITUTE(SUBSTITUTE(SUBSTITUTE(SUBSTITUTE(SUBSTITUTE(LOWER(TRIM(A10))," ","_"),"!","_"),"#","_"),"$","_"),"%","_"),"&","_"),"'","_"),"(","_"),")","_"),"*","_"),"+","_"),",","_"),"-","_"),".","_"),"/","_"),":","_"),";","_"),"<","_"),"=","_"),">","_"),"?","_"),"@","_"),"[","_"),"\","_"),"]","_"),"^","_"),"`","_"),"{","_"),"|","_"),"}","_"),"~","_"),"–","_"),"—","_"),"’","_"),"“","_"),"”","_"),CHAR(9),"_"),CHAR(160),"_")) | AJ10: =IF(AI10="","",SUBSTITUTE(SUBSTITUTE(SUBSTITUTE(SUBSTITUTE(SUBSTITUTE(SUBSTITUTE(SUBSTITUTE(SUBSTITUTE(AI10,"__","_"),"__","_"),"__","_"),"__","_"),"__","_"),"__","_"),"__","_"),"__","_")) | AK10: =IF(OR(AJ10="",AJ10="_"),"",IF(LEFT(AJ10,1)="_",IF(RIGHT(AJ10,1)="_",MID(AJ10,2,LEN(AJ10)-2),RIGHT(AJ10,LEN(AJ10)-1)),IF(RIGHT(AJ10,1)="_",LEFT(AJ10,LEN(AJ10)-1),AJ10))) | AL10: =IF(OR(LOWER(TRIM(B10))="",LOWER(TRIM(B10))="nan",LOWER(TRIM(B10))="none",LOWER(TRIM(B10))="n/a"),"",SUBSTITUTE(SUBSTITUTE(SUBSTITUTE(SUBSTITUTE(SUBSTITUTE(SUBSTITUTE(SUBSTITUTE(SUBSTITUTE(SUBSTITUTE(SUBSTITUTE(SUBSTITUTE(SUBSTITUTE(SUBSTITUTE(SUBSTITUTE(SUBSTITUTE(SUBSTITUTE(SUBSTITUTE(SUBSTITUTE(SUBSTITUTE(SUBSTITUTE(SUBSTITUTE(SUBSTITUTE(SUBSTITUTE(SUBSTITUTE(SUBSTITUTE(SUBSTITUTE(SUBSTITUTE(SUBSTITUTE(SUBSTITUTE(SUBSTITUTE(SUBSTITUTE(SUBSTITUTE(SUBSTITUTE(SUBSTITUTE(SUBSTITUTE(SUBSTITUTE(SUBSTITUTE(SUBSTITUTE(LOWER(TRIM(B10))," ","_"),"!","_"),"#","_"),"$","_"),"%","_"),"&","_"),"'","_"),"(","_"),")","_"),"*","_"),"+","_"),",","_"),"-","_"),".","_"),"/","_"),":","_"),";","_"),"<","_"),"=","_"),">","_"),"?","_"),"@","_"),"[","_"),"\","_"),"]","_"),"^","_"),"`","_"),"{","_"),"|","_"),"}","_"),"~","_"),"–","_"),"—","_"),"’","_"),"“","_"),"”","_"),CHAR(9),"_"),CHAR(160),"_")) | AM10: =IF(AL10="","",SUBSTITUTE(SUBSTITUTE(SUBSTITUTE(SUBSTITUTE(SUBSTITUTE(SUBSTITUTE(SUBSTITUTE(SUBSTITUTE(AL10,"__","_"),"__","_"),"__","_"),"__","_"),"__","_"),"__","_"),"__","_"),"__","_")) | AN10: =IF(OR(AM10="",AM10="_"),"",IF(LEFT(AM10,1)="_",IF(RIGHT(AM10,1)="_",MID(AM10,2,LEN(AM10)-2),RIGHT(AM10,LEN(AM10)-1)),IF(RIGHT(AM10,1)="_",LEFT(AM10,LEN(AM10)-1),AM10))) | AO10: =IF(OR(LOWER(TRIM(C10))="",LOWER(TRIM(C10))="nan",LOWER(TRIM(C10))="none",LOWER(TRIM(C10))="n/a"),"",SUBSTITUTE(SUBSTITUTE(SUBSTITUTE(SUBSTITUTE(SUBSTITUTE(SUBSTITUTE(SUBSTITUTE(SUBSTITUTE(SUBSTITUTE(SUBSTITUTE(SUBSTITUTE(SUBSTITUTE(SUBSTITUTE(SUBSTITUTE(SUBSTITUTE(SUBSTITUTE(SUBSTITUTE(SUBSTITUTE(SUBSTITUTE(SUBSTITUTE(SUBSTITUTE(SUBSTITUTE(SUBSTITUTE(SUBSTITUTE(SUBSTITUTE(SUBSTITUTE(SUBSTITUTE(SUBSTITUTE(SUBSTITUTE(SUBSTITUTE(SUBSTITUTE(SUBSTITUTE(SUBSTITUTE(SUBSTITUTE(SUBSTITUTE(SUBSTITUTE(SUBSTITUTE(SUBSTITUTE(LOWER(TRIM(C10))," ","_"),"!","_"),"#","_"),"$","_"),"%","_"),"&","_"),"'","_"),"(","_"),")","_"),"*","_"),"+","_"),",","_"),"-","_"),".","_"),"/","_"),":","_"),";","_"),"<","_"),"=","_"),">","_"),"?","_"),"@","_"),"[","_"),"\","_"),"]","_"),"^","_"),"`","_"),"{","_"),"|","_"),"}","_"),"~","_"),"–","_"),"—","_"),"’","_"),"“","_"),"”","_"),CHAR(9),"_"),CHAR(160),"_")) | AP10: =IF(AO10="","",SUBSTITUTE(SUBSTITUTE(SUBSTITUTE(SUBSTITUTE(SUBSTITUTE(SUBSTITUTE(SUBSTITUTE(SUBSTITUTE(AO10,"__","_"),"__","_"),"__","_"),"__","_"),"__","_"),"__","_"),"__","_"),"__","_")) | AQ10: =IF(OR(AP10="",AP10="_"),"",IF(LEFT(AP10,1)="_",IF(RIGHT(AP10,1)="_",MID(AP10,2,LEN(AP10)-2),RIGHT(AP10,LEN(AP10)-1)),IF(RIGHT(AP10,1)="_",LEFT(AP10,LEN(AP10)-1),AP10)))
A11: Family History | B11: fh_net_billthrough_count | C11: New | D11: Net bill-through count | H11: =IF(AK11<>"",AK11,"")&IF(AN11<>"",IF(AK11<>"","_"&AN11,AN11),"")&IF(AQ11<>"",IF(AK11<>"","_"&AQ11,AQ11),"") | I11: =IF(TRIM(G11)<>"",TRIM(G11),H11) | J11: =IF(OR(A11="",B11="",C11="",D11=""),"Missing required field — fill in product, metric_key, segment, and metric before this row can be used.",IF(H11="","Missing required field — product, metric_key, and segment must combine into an ID.",IF(COUNTIF($I$8:$I$32,I11)>1,"Duplicate outcome ID — two rows currently build the same outcome_id; add a distinguishing detail.",IF(AND(F11<>"",F11<>I11),"Existing outcome_id differs from the built ID — review before using.","Ready")))) | AI11: =IF(OR(LOWER(TRIM(A11))="",LOWER(TRIM(A11))="nan",LOWER(TRIM(A11))="none",LOWER(TRIM(A11))="n/a"),"",SUBSTITUTE(SUBSTITUTE(SUBSTITUTE(SUBSTITUTE(SUBSTITUTE(SUBSTITUTE(SUBSTITUTE(SUBSTITUTE(SUBSTITUTE(SUBSTITUTE(SUBSTITUTE(SUBSTITUTE(SUBSTITUTE(SUBSTITUTE(SUBSTITUTE(SUBSTITUTE(SUBSTITUTE(SUBSTITUTE(SUBSTITUTE(SUBSTITUTE(SUBSTITUTE(SUBSTITUTE(SUBSTITUTE(SUBSTITUTE(SUBSTITUTE(SUBSTITUTE(SUBSTITUTE(SUBSTITUTE(SUBSTITUTE(SUBSTITUTE(SUBSTITUTE(SUBSTITUTE(SUBSTITUTE(SUBSTITUTE(SUBSTITUTE(SUBSTITUTE(SUBSTITUTE(SUBSTITUTE(LOWER(TRIM(A11))," ","_"),"!","_"),"#","_"),"$","_"),"%","_"),"&","_"),"'","_"),"(","_"),")","_"),"*","_"),"+","_"),",","_"),"-","_"),".","_"),"/","_"),":","_"),";","_"),"<","_"),"=","_"),">","_"),"?","_"),"@","_"),"[","_"),"\","_"),"]","_"),"^","_"),"`","_"),"{","_"),"|","_"),"}","_"),"~","_"),"–","_"),"—","_"),"’","_"),"“","_"),"”","_"),CHAR(9),"_"),CHAR(160),"_")) | AJ11: =IF(AI11="","",SUBSTITUTE(SUBSTITUTE(SUBSTITUTE(SUBSTITUTE(SUBSTITUTE(SUBSTITUTE(SUBSTITUTE(SUBSTITUTE(AI11,"__","_"),"__","_"),"__","_"),"__","_"),"__","_"),"__","_"),"__","_"),"__","_")) | AK11: =IF(OR(AJ11="",AJ11="_"),"",IF(LEFT(AJ11,1)="_",IF(RIGHT(AJ11,1)="_",MID(AJ11,2,LEN(AJ11)-2),RIGHT(AJ11,LEN(AJ11)-1)),IF(RIGHT(AJ11,1)="_",LEFT(AJ11,LEN(AJ11)-1),AJ11))) | AL11: =IF(OR(LOWER(TRIM(B11))="",LOWER(TRIM(B11))="nan",LOWER(TRIM(B11))="none",LOWER(TRIM(B11))="n/a"),"",SUBSTITUTE(SUBSTITUTE(SUBSTITUTE(SUBSTITUTE(SUBSTITUTE(SUBSTITUTE(SUBSTITUTE(SUBSTITUTE(SUBSTITUTE(SUBSTITUTE(SUBSTITUTE(SUBSTITUTE(SUBSTITUTE(SUBSTITUTE(SUBSTITUTE(SUBSTITUTE(SUBSTITUTE(SUBSTITUTE(SUBSTITUTE(SUBSTITUTE(SUBSTITUTE(SUBSTITUTE(SUBSTITUTE(SUBSTITUTE(SUBSTITUTE(SUBSTITUTE(SUBSTITUTE(SUBSTITUTE(SUBSTITUTE(SUBSTITUTE(SUBSTITUTE(SUBSTITUTE(SUBSTITUTE(SUBSTITUTE(SUBSTITUTE(SUBSTITUTE(SUBSTITUTE(SUBSTITUTE(LOWER(TRIM(B11))," ","_"),"!","_"),"#","_"),"$","_"),"%","_"),"&","_"),"'","_"),"(","_"),")","_"),"*","_"),"+","_"),",","_"),"-","_"),".","_"),"/","_"),":","_"),";","_"),"<","_"),"=","_"),">","_"),"?","_"),"@","_"),"[","_"),"\","_"),"]","_"),"^","_"),"`","_"),"{","_"),"|","_"),"}","_"),"~","_"),"–","_"),"—","_"),"’","_"),"“","_"),"”","_"),CHAR(9),"_"),CHAR(160),"_")) | AM11: =IF(AL11="","",SUBSTITUTE(SUBSTITUTE(SUBSTITUTE(SUBSTITUTE(SUBSTITUTE(SUBSTITUTE(SUBSTITUTE(SUBSTITUTE(AL11,"__","_"),"__","_"),"__","_"),"__","_"),"__","_"),"__","_"),"__","_"),"__","_")) | AN11: =IF(OR(AM11="",AM11="_"),"",IF(LEFT(AM11,1)="_",IF(RIGHT(AM11,1)="_",MID(AM11,2,LEN(AM11)-2),RIGHT(AM11,LEN(AM11)-1)),IF(RIGHT(AM11,1)="_",LEFT(AM11,LEN(AM11)-1),AM11))) | AO11: =IF(OR(LOWER(TRIM(C11))="",LOWER(TRIM(C11))="nan",LOWER(TRIM(C11))="none",LOWER(TRIM(C11))="n/a"),"",SUBSTITUTE(SUBSTITUTE(SUBSTITUTE(SUBSTITUTE(SUBSTITUTE(SUBSTITUTE(SUBSTITUTE(SUBSTITUTE(SUBSTITUTE(SUBSTITUTE(SUBSTITUTE(SUBSTITUTE(SUBSTITUTE(SUBSTITUTE(SUBSTITUTE(SUBSTITUTE(SUBSTITUTE(SUBSTITUTE(SUBSTITUTE(SUBSTITUTE(SUBSTITUTE(SUBSTITUTE(SUBSTITUTE(SUBSTITUTE(SUBSTITUTE(SUBSTITUTE(SUBSTITUTE(SUBSTITUTE(SUBSTITUTE(SUBSTITUTE(SUBSTITUTE(SUBSTITUTE(SUBSTITUTE(SUBSTITUTE(SUBSTITUTE(SUBSTITUTE(SUBSTITUTE(SUBSTITUTE(LOWER(TRIM(C11))," ","_"),"!","_"),"#","_"),"$","_"),"%","_"),"&","_"),"'","_"),"(","_"),")","_"),"*","_"),"+","_"),",","_"),"-","_"),".","_"),"/","_"),":","_"),";","_"),"<","_"),"=","_"),">","_"),"?","_"),"@","_"),"[","_"),"\","_"),"]","_"),"^","_"),"`","_"),"{","_"),"|","_"),"}","_"),"~","_"),"–","_"),"—","_"),"’","_"),"“","_"),"”","_"),CHAR(9),"_"),CHAR(160),"_")) | AP11: =IF(AO11="","",SUBSTITUTE(SUBSTITUTE(SUBSTITUTE(SUBSTITUTE(SUBSTITUTE(SUBSTITUTE(SUBSTITUTE(SUBSTITUTE(AO11,"__","_"),"__","_"),"__","_"),"__","_"),"__","_"),"__","_"),"__","_"),"__","_")) | AQ11: =IF(OR(AP11="",AP11="_"),"",IF(LEFT(AP11,1)="_",IF(RIGHT(AP11,1)="_",MID(AP11,2,LEN(AP11)-2),RIGHT(AP11,LEN(AP11)-1)),IF(RIGHT(AP11,1)="_",LEFT(AP11,LEN(AP11)-1),AP11)))
A12: DNA | B12: dna_kit_sale | C12: New Customer | D12: Kit sale | H12: =IF(AK12<>"",AK12,"")&IF(AN12<>"",IF(AK12<>"","_"&AN12,AN12),"")&IF(AQ12<>"",IF(AK12<>"","_"&AQ12,AQ12),"") | I12: =IF(TRIM(G12)<>"",TRIM(G12),H12) | J12: =IF(OR(A12="",B12="",C12="",D12=""),"Missing required field — fill in product, metric_key, segment, and metric before this row can be used.",IF(H12="","Missing required field — product, metric_key, and segment must combine into an ID.",IF(COUNTIF($I$8:$I$32,I12)>1,"Duplicate outcome ID — two rows currently build the same outcome_id; add a distinguishing detail.",IF(AND(F12<>"",F12<>I12),"Existing outcome_id differs from the built ID — review before using.","Ready")))) | AI12: =IF(OR(LOWER(TRIM(A12))="",LOWER(TRIM(A12))="nan",LOWER(TRIM(A12))="none",LOWER(TRIM(A12))="n/a"),"",SUBSTITUTE(SUBSTITUTE(SUBSTITUTE(SUBSTITUTE(SUBSTITUTE(SUBSTITUTE(SUBSTITUTE(SUBSTITUTE(SUBSTITUTE(SUBSTITUTE(SUBSTITUTE(SUBSTITUTE(SUBSTITUTE(SUBSTITUTE(SUBSTITUTE(SUBSTITUTE(SUBSTITUTE(SUBSTITUTE(SUBSTITUTE(SUBSTITUTE(SUBSTITUTE(SUBSTITUTE(SUBSTITUTE(SUBSTITUTE(SUBSTITUTE(SUBSTITUTE(SUBSTITUTE(SUBSTITUTE(SUBSTITUTE(SUBSTITUTE(SUBSTITUTE(SUBSTITUTE(SUBSTITUTE(SUBSTITUTE(SUBSTITUTE(SUBSTITUTE(SUBSTITUTE(SUBSTITUTE(LOWER(TRIM(A12))," ","_"),"!","_"),"#","_"),"$","_"),"%","_"),"&","_"),"'","_"),"(","_"),")","_"),"*","_"),"+","_"),",","_"),"-","_"),".","_"),"/","_"),":","_"),";","_"),"<","_"),"=","_"),">","_"),"?","_"),"@","_"),"[","_"),"\","_"),"]","_"),"^","_"),"`","_"),"{","_"),"|","_"),"}","_"),"~","_"),"–","_"),"—","_"),"’","_"),"“","_"),"”","_"),CHAR(9),"_"),CHAR(160),"_")) | AJ12: =IF(AI12="","",SUBSTITUTE(SUBSTITUTE(SUBSTITUTE(SUBSTITUTE(SUBSTITUTE(SUBSTITUTE(SUBSTITUTE(SUBSTITUTE(AI12,"__","_"),"__","_"),"__","_"),"__","_"),"__","_"),"__","_"),"__","_"),"__","_")) | AK12: =IF(OR(AJ12="",AJ12="_"),"",IF(LEFT(AJ12,1)="_",IF(RIGHT(AJ12,1)="_",MID(AJ12,2,LEN(AJ12)-2),RIGHT(AJ12,LEN(AJ12)-1)),IF(RIGHT(AJ12,1)="_",LEFT(AJ12,LEN(AJ12)-1),AJ12))) | AL12: =IF(OR(LOWER(TRIM(B12))="",LOWER(TRIM(B12))="nan",LOWER(TRIM(B12))="none",LOWER(TRIM(B12))="n/a"),"",SUBSTITUTE(SUBSTITUTE(SUBSTITUTE(SUBSTITUTE(SUBSTITUTE(SUBSTITUTE(SUBSTITUTE(SUBSTITUTE(SUBSTITUTE(SUBSTITUTE(SUBSTITUTE(SUBSTITUTE(SUBSTITUTE(SUBSTITUTE(SUBSTITUTE(SUBSTITUTE(SUBSTITUTE(SUBSTITUTE(SUBSTITUTE(SUBSTITUTE(SUBSTITUTE(SUBSTITUTE(SUBSTITUTE(SUBSTITUTE(SUBSTITUTE(SUBSTITUTE(SUBSTITUTE(SUBSTITUTE(SUBSTITUTE(SUBSTITUTE(SUBSTITUTE(SUBSTITUTE(SUBSTITUTE(SUBSTITUTE(SUBSTITUTE(SUBSTITUTE(SUBSTITUTE(SUBSTITUTE(LOWER(TRIM(B12))," ","_"),"!","_"),"#","_"),"$","_"),"%","_"),"&","_"),"'","_"),"(","_"),")","_"),"*","_"),"+","_"),",","_"),"-","_"),".","_"),"/","_"),":","_"),";","_"),"<","_"),"=","_"),">","_"),"?","_"),"@","_"),"[","_"),"\","_"),"]","_"),"^","_"),"`","_"),"{","_"),"|","_"),"}","_"),"~","_"),"–","_"),"—","_"),"’","_"),"“","_"),"”","_"),CHAR(9),"_"),CHAR(160),"_")) | AM12: =IF(AL12="","",SUBSTITUTE(SUBSTITUTE(SUBSTITUTE(SUBSTITUTE(SUBSTITUTE(SUBSTITUTE(SUBSTITUTE(SUBSTITUTE(AL12,"__","_"),"__","_"),"__","_"),"__","_"),"__","_"),"__","_"),"__","_"),"__","_")) | AN12: =IF(OR(AM12="",AM12="_"),"",IF(LEFT(AM12,1)="_",IF(RIGHT(AM12,1)="_",MID(AM12,2,LEN(AM12)-2),RIGHT(AM12,LEN(AM12)-1)),IF(RIGHT(AM12,1)="_",LEFT(AM12,LEN(AM12)-1),AM12))) | AO12: =IF(OR(LOWER(TRIM(C12))="",LOWER(TRIM(C12))="nan",LOWER(TRIM(C12))="none",LOWER(TRIM(C12))="n/a"),"",SUBSTITUTE(SUBSTITUTE(SUBSTITUTE(SUBSTITUTE(SUBSTITUTE(SUBSTITUTE(SUBSTITUTE(SUBSTITUTE(SUBSTITUTE(SUBSTITUTE(SUBSTITUTE(SUBSTITUTE(SUBSTITUTE(SUBSTITUTE(SUBSTITUTE(SUBSTITUTE(SUBSTITUTE(SUBSTITUTE(SUBSTITUTE(SUBSTITUTE(SUBSTITUTE(SUBSTITUTE(SUBSTITUTE(SUBSTITUTE(SUBSTITUTE(SUBSTITUTE(SUBSTITUTE(SUBSTITUTE(SUBSTITUTE(SUBSTITUTE(SUBSTITUTE(SUBSTITUTE(SUBSTITUTE(SUBSTITUTE(SUBSTITUTE(SUBSTITUTE(SUBSTITUTE(SUBSTITUTE(LOWER(TRIM(C12))," ","_"),"!","_"),"#","_"),"$","_"),"%","_"),"&","_"),"'","_"),"(","_"),")","_"),"*","_"),"+","_"),",","_"),"-","_"),".","_"),"/","_"),":","_"),";","_"),"<","_"),"=","_"),">","_"),"?","_"),"@","_"),"[","_"),"\","_"),"]","_"),"^","_"),"`","_"),"{","_"),"|","_"),"}","_"),"~","_"),"–","_"),"—","_"),"’","_"),"“","_"),"”","_"),CHAR(9),"_"),CHAR(160),"_")) | AP12: =IF(AO12="","",SUBSTITUTE(SUBSTITUTE(SUBSTITUTE(SUBSTITUTE(SUBSTITUTE(SUBSTITUTE(SUBSTITUTE(SUBSTITUTE(AO12,"__","_"),"__","_"),"__","_"),"__","_"),"__","_"),"__","_"),"__","_"),"__","_")) | AQ12: =IF(OR(AP12="",AP12="_"),"",IF(LEFT(AP12,1)="_",IF(RIGHT(AP12,1)="_",MID(AP12,2,LEN(AP12)-2),RIGHT(AP12,LEN(AP12)-1)),IF(RIGHT(AP12,1)="_",LEFT(AP12,LEN(AP12)-1),AP12)))
H13: =IF(AK13<>"",AK13,"")&IF(AN13<>"",IF(AK13<>"","_"&AN13,AN13),"")&IF(AQ13<>"",IF(AK13<>"","_"&AQ13,AQ13),"") | I13: =IF(TRIM(G13)<>"",TRIM(G13),H13) | J13: =IF(OR(A13="",B13="",C13="",D13=""),"Missing required field — fill in product, metric_key, segment, and metric before this row can be used.",IF(H13="","Missing required field — product, metric_key, and segment must combine into an ID.",IF(COUNTIF($I$8:$I$32,I13)>1,"Duplicate outcome ID — two rows currently build the same outcome_id; add a distinguishing detail.",IF(AND(F13<>"",F13<>I13),"Existing outcome_id differs from the built ID — review before using.","Ready")))) | AI13: =IF(OR(LOWER(TRIM(A13))="",LOWER(TRIM(A13))="nan",LOWER(TRIM(A13))="none",LOWER(TRIM(A13))="n/a"),"",SUBSTITUTE(SUBSTITUTE(SUBSTITUTE(SUBSTITUTE(SUBSTITUTE(SUBSTITUTE(SUBSTITUTE(SUBSTITUTE(SUBSTITUTE(SUBSTITUTE(SUBSTITUTE(SUBSTITUTE(SUBSTITUTE(SUBSTITUTE(SUBSTITUTE(SUBSTITUTE(SUBSTITUTE(SUBSTITUTE(SUBSTITUTE(SUBSTITUTE(SUBSTITUTE(SUBSTITUTE(SUBSTITUTE(SUBSTITUTE(SUBSTITUTE(SUBSTITUTE(SUBSTITUTE(SUBSTITUTE(SUBSTITUTE(SUBSTITUTE(SUBSTITUTE(SUBSTITUTE(SUBSTITUTE(SUBSTITUTE(SUBSTITUTE(SUBSTITUTE(SUBSTITUTE(SUBSTITUTE(LOWER(TRIM(A13))," ","_"),"!","_"),"#","_"),"$","_"),"%","_"),"&","_"),"'","_"),"(","_"),")","_"),"*","_"),"+","_"),",","_"),"-","_"),".","_"),"/","_"),":","_"),";","_"),"<","_"),"=","_"),">","_"),"?","_"),"@","_"),"[","_"),"\","_"),"]","_"),"^","_"),"`","_"),"{","_"),"|","_"),"}","_"),"~","_"),"–","_"),"—","_"),"’","_"),"“","_"),"”","_"),CHAR(9),"_"),CHAR(160),"_")) | AJ13: =IF(AI13="","",SUBSTITUTE(SUBSTITUTE(SUBSTITUTE(SUBSTITUTE(SUBSTITUTE(SUBSTITUTE(SUBSTITUTE(SUBSTITUTE(AI13,"__","_"),"__","_"),"__","_"),"__","_"),"__","_"),"__","_"),"__","_"),"__","_")) | AK13: =IF(OR(AJ13="",AJ13="_"),"",IF(LEFT(AJ13,1)="_",IF(RIGHT(AJ13,1)="_",MID(AJ13,2,LEN(AJ13)-2),RIGHT(AJ13,LEN(AJ13)-1)),IF(RIGHT(AJ13,1)="_",LEFT(AJ13,LEN(AJ13)-1),AJ13))) | AL13: =IF(OR(LOWER(TRIM(B13))="",LOWER(TRIM(B13))="nan",LOWER(TRIM(B13))="none",LOWER(TRIM(B13))="n/a"),"",SUBSTITUTE(SUBSTITUTE(SUBSTITUTE(SUBSTITUTE(SUBSTITUTE(SUBSTITUTE(SUBSTITUTE(SUBSTITUTE(SUBSTITUTE(SUBSTITUTE(SUBSTITUTE(SUBSTITUTE(SUBSTITUTE(SUBSTITUTE(SUBSTITUTE(SUBSTITUTE(SUBSTITUTE(SUBSTITUTE(SUBSTITUTE(SUBSTITUTE(SUBSTITUTE(SUBSTITUTE(SUBSTITUTE(SUBSTITUTE(SUBSTITUTE(SUBSTITUTE(SUBSTITUTE(SUBSTITUTE(SUBSTITUTE(SUBSTITUTE(SUBSTITUTE(SUBSTITUTE(SUBSTITUTE(SUBSTITUTE(SUBSTITUTE(SUBSTITUTE(SUBSTITUTE(SUBSTITUTE(LOWER(TRIM(B13))," ","_"),"!","_"),"#","_"),"$","_"),"%","_"),"&","_"),"'","_"),"(","_"),")","_"),"*","_"),"+","_"),",","_"),"-","_"),".","_"),"/","_"),":","_"),";","_"),"<","_"),"=","_"),">","_"),"?","_"),"@","_"),"[","_"),"\","_"),"]","_"),"^","_"),"`","_"),"{","_"),"|","_"),"}","_"),"~","_"),"–","_"),"—","_"),"’","_"),"“","_"),"”","_"),CHAR(9),"_"),CHAR(160),"_")) | AM13: =IF(AL13="","",SUBSTITUTE(SUBSTITUTE(SUBSTITUTE(SUBSTITUTE(SUBSTITUTE(SUBSTITUTE(SUBSTITUTE(SUBSTITUTE(AL13,"__","_"),"__","_"),"__","_"),"__","_"),"__","_"),"__","_"),"__","_"),"__","_")) | AN13: =IF(OR(AM13="",AM13="_"),"",IF(LEFT(AM13,1)="_",IF(RIGHT(AM13,1)="_",MID(AM13,2,LEN(AM13)-2),RIGHT(AM13,LEN(AM13)-1)),IF(RIGHT(AM13,1)="_",LEFT(AM13,LEN(AM13)-1),AM13))) | AO13: =IF(OR(LOWER(TRIM(C13))="",LOWER(TRIM(C13))="nan",LOWER(TRIM(C13))="none",LOWER(TRIM(C13))="n/a"),"",SUBSTITUTE(SUBSTITUTE(SUBSTITUTE(SUBSTITUTE(SUBSTITUTE(SUBSTITUTE(SUBSTITUTE(SUBSTITUTE(SUBSTITUTE(SUBSTITUTE(SUBSTITUTE(SUBSTITUTE(SUBSTITUTE(SUBSTITUTE(SUBSTITUTE(SUBSTITUTE(SUBSTITUTE(SUBSTITUTE(SUBSTITUTE(SUBSTITUTE(SUBSTITUTE(SUBSTITUTE(SUBSTITUTE(SUBSTITUTE(SUBSTITUTE(SUBSTITUTE(SUBSTITUTE(SUBSTITUTE(SUBSTITUTE(SUBSTITUTE(SUBSTITUTE(SUBSTITUTE(SUBSTITUTE(SUBSTITUTE(SUBSTITUTE(SUBSTITUTE(SUBSTITUTE(SUBSTITUTE(LOWER(TRIM(C13))," ","_"),"!","_"),"#","_"),"$","_"),"%","_"),"&","_"),"'","_"),"(","_"),")","_"),"*","_"),"+","_"),",","_"),"-","_"),".","_"),"/","_"),":","_"),";","_"),"<","_"),"=","_"),">","_"),"?","_"),"@","_"),"[","_"),"\","_"),"]","_"),"^","_"),"`","_"),"{","_"),"|","_"),"}","_"),"~","_"),"–","_"),"—","_"),"’","_"),"“","_"),"”","_"),CHAR(9),"_"),CHAR(160),"_")) | AP13: =IF(AO13="","",SUBSTITUTE(SUBSTITUTE(SUBSTITUTE(SUBSTITUTE(SUBSTITUTE(SUBSTITUTE(SUBSTITUTE(SUBSTITUTE(AO13,"__","_"),"__","_"),"__","_"),"__","_"),"__","_"),"__","_"),"__","_"),"__","_")) | AQ13: =IF(OR(AP13="",AP13="_"),"",IF(LEFT(AP13,1)="_",IF(RIGHT(AP13,1)="_",MID(AP13,2,LEN(AP13)-2),RIGHT(AP13,LEN(AP13)-1)),IF(RIGHT(AP13,1)="_",LEFT(AP13,LEN(AP13)-1),AP13)))
H14: =IF(AK14<>"",AK14,"")&IF(AN14<>"",IF(AK14<>"","_"&AN14,AN14),"")&IF(AQ14<>"",IF(AK14<>"","_"&AQ14,AQ14),"") | I14: =IF(TRIM(G14)<>"",TRIM(G14),H14) | J14: =IF(OR(A14="",B14="",C14="",D14=""),"Missing required field — fill in product, metric_key, segment, and metric before this row can be used.",IF(H14="","Missing required field — product, metric_key, and segment must combine into an ID.",IF(COUNTIF($I$8:$I$32,I14)>1,"Duplicate outcome ID — two rows currently build the same outcome_id; add a distinguishing detail.",IF(AND(F14<>"",F14<>I14),"Existing outcome_id differs from the built ID — review before using.","Ready")))) | AI14: =IF(OR(LOWER(TRIM(A14))="",LOWER(TRIM(A14))="nan",LOWER(TRIM(A14))="none",LOWER(TRIM(A14))="n/a"),"",SUBSTITUTE(SUBSTITUTE(SUBSTITUTE(SUBSTITUTE(SUBSTITUTE(SUBSTITUTE(SUBSTITUTE(SUBSTITUTE(SUBSTITUTE(SUBSTITUTE(SUBSTITUTE(SUBSTITUTE(SUBSTITUTE(SUBSTITUTE(SUBSTITUTE(SUBSTITUTE(SUBSTITUTE(SUBSTITUTE(SUBSTITUTE(SUBSTITUTE(SUBSTITUTE(SUBSTITUTE(SUBSTITUTE(SUBSTITUTE(SUBSTITUTE(SUBSTITUTE(SUBSTITUTE(SUBSTITUTE(SUBSTITUTE(SUBSTITUTE(SUBSTITUTE(SUBSTITUTE(SUBSTITUTE(SUBSTITUTE(SUBSTITUTE(SUBSTITUTE(SUBSTITUTE(SUBSTITUTE(LOWER(TRIM(A14))," ","_"),"!","_"),"#","_"),"$","_"),"%","_"),"&","_"),"'","_"),"(","_"),")","_"),"*","_"),"+","_"),",","_"),"-","_"),".","_"),"/","_"),":","_"),";","_"),"<","_"),"=","_"),">","_"),"?","_"),"@","_"),"[","_"),"\","_"),"]","_"),"^","_"),"`","_"),"{","_"),"|","_"),"}","_"),"~","_"),"–","_"),"—","_"),"’","_"),"“","_"),"”","_"),CHAR(9),"_"),CHAR(160),"_")) | AJ14: =IF(AI14="","",SUBSTITUTE(SUBSTITUTE(SUBSTITUTE(SUBSTITUTE(SUBSTITUTE(SUBSTITUTE(SUBSTITUTE(SUBSTITUTE(AI14,"__","_"),"__","_"),"__","_"),"__","_"),"__","_"),"__","_"),"__","_"),"__","_")) | AK14: =IF(OR(AJ14="",AJ14="_"),"",IF(LEFT(AJ14,1)="_",IF(RIGHT(AJ14,1)="_",MID(AJ14,2,LEN(AJ14)-2),RIGHT(AJ14,LEN(AJ14)-1)),IF(RIGHT(AJ14,1)="_",LEFT(AJ14,LEN(AJ14)-1),AJ14))) | AL14: =IF(OR(LOWER(TRIM(B14))="",LOWER(TRIM(B14))="nan",LOWER(TRIM(B14))="none",LOWER(TRIM(B14))="n/a"),"",SUBSTITUTE(SUBSTITUTE(SUBSTITUTE(SUBSTITUTE(SUBSTITUTE(SUBSTITUTE(SUBSTITUTE(SUBSTITUTE(SUBSTITUTE(SUBSTITUTE(SUBSTITUTE(SUBSTITUTE(SUBSTITUTE(SUBSTITUTE(SUBSTITUTE(SUBSTITUTE(SUBSTITUTE(SUBSTITUTE(SUBSTITUTE(SUBSTITUTE(SUBSTITUTE(SUBSTITUTE(SUBSTITUTE(SUBSTITUTE(SUBSTITUTE(SUBSTITUTE(SUBSTITUTE(SUBSTITUTE(SUBSTITUTE(SUBSTITUTE(SUBSTITUTE(SUBSTITUTE(SUBSTITUTE(SUBSTITUTE(SUBSTITUTE(SUBSTITUTE(SUBSTITUTE(SUBSTITUTE(LOWER(TRIM(B14))," ","_"),"!","_"),"#","_"),"$","_"),"%","_"),"&","_"),"'","_"),"(","_"),")","_"),"*","_"),"+","_"),",","_"),"-","_"),".","_"),"/","_"),":","_"),";","_"),"<","_"),"=","_"),">","_"),"?","_"),"@","_"),"[","_"),"\","_"),"]","_"),"^","_"),"`","_"),"{","_"),"|","_"),"}","_"),"~","_"),"–","_"),"—","_"),"’","_"),"“","_"),"”","_"),CHAR(9),"_"),CHAR(160),"_")) | AM14: =IF(AL14="","",SUBSTITUTE(SUBSTITUTE(SUBSTITUTE(SUBSTITUTE(SUBSTITUTE(SUBSTITUTE(SUBSTITUTE(SUBSTITUTE(AL14,"__","_"),"__","_"),"__","_"),"__","_"),"__","_"),"__","_"),"__","_"),"__","_")) | AN14: =IF(OR(AM14="",AM14="_"),"",IF(LEFT(AM14,1)="_",IF(RIGHT(AM14,1)="_",MID(AM14,2,LEN(AM14)-2),RIGHT(AM14,LEN(AM14)-1)),IF(RIGHT(AM14,1)="_",LEFT(AM14,LEN(AM14)-1),AM14))) | AO14: =IF(OR(LOWER(TRIM(C14))="",LOWER(TRIM(C14))="nan",LOWER(TRIM(C14))="none",LOWER(TRIM(C14))="n/a"),"",SUBSTITUTE(SUBSTITUTE(SUBSTITUTE(SUBSTITUTE(SUBSTITUTE(SUBSTITUTE(SUBSTITUTE(SUBSTITUTE(SUBSTITUTE(SUBSTITUTE(SUBSTITUTE(SUBSTITUTE(SUBSTITUTE(SUBSTITUTE(SUBSTITUTE(SUBSTITUTE(SUBSTITUTE(SUBSTITUTE(SUBSTITUTE(SUBSTITUTE(SUBSTITUTE(SUBSTITUTE(SUBSTITUTE(SUBSTITUTE(SUBSTITUTE(SUBSTITUTE(SUBSTITUTE(SUBSTITUTE(SUBSTITUTE(SUBSTITUTE(SUBSTITUTE(SUBSTITUTE(SUBSTITUTE(SUBSTITUTE(SUBSTITUTE(SUBSTITUTE(SUBSTITUTE(SUBSTITUTE(LOWER(TRIM(C14))," ","_"),"!","_"),"#","_"),"$","_"),"%","_"),"&","_"),"'","_"),"(","_"),")","_"),"*","_"),"+","_"),",","_"),"-","_"),".","_"),"/","_"),":","_"),";","_"),"<","_"),"=","_"),">","_"),"?","_"),"@","_"),"[","_"),"\","_"),"]","_"),"^","_"),"`","_"),"{","_"),"|","_"),"}","_"),"~","_"),"–","_"),"—","_"),"’","_"),"“","_"),"”","_"),CHAR(9),"_"),CHAR(160),"_")) | AP14: =IF(AO14="","",SUBSTITUTE(SUBSTITUTE(SUBSTITUTE(SUBSTITUTE(SUBSTITUTE(SUBSTITUTE(SUBSTITUTE(SUBSTITUTE(AO14,"__","_"),"__","_"),"__","_"),"__","_"),"__","_"),"__","_"),"__","_"),"__","_")) | AQ14: =IF(OR(AP14="",AP14="_"),"",IF(LEFT(AP14,1)="_",IF(RIGHT(AP14,1)="_",MID(AP14,2,LEN(AP14)-2),RIGHT(AP14,LEN(AP14)-1)),IF(RIGHT(AP14,1)="_",LEFT(AP14,LEN(AP14)-1),AP14)))
H15: =IF(AK15<>"",AK15,"")&IF(AN15<>"",IF(AK15<>"","_"&AN15,AN15),"")&IF(AQ15<>"",IF(AK15<>"","_"&AQ15,AQ15),"") | I15: =IF(TRIM(G15)<>"",TRIM(G15),H15) | J15: =IF(OR(A15="",B15="",C15="",D15=""),"Missing required field — fill in product, metric_key, segment, and metric before this row can be used.",IF(H15="","Missing required field — product, metric_key, and segment must combine into an ID.",IF(COUNTIF($I$8:$I$32,I15)>1,"Duplicate outcome ID — two rows currently build the same outcome_id; add a distinguishing detail.",IF(AND(F15<>"",F15<>I15),"Existing outcome_id differs from the built ID — review before using.","Ready")))) | AI15: =IF(OR(LOWER(TRIM(A15))="",LOWER(TRIM(A15))="nan",LOWER(TRIM(A15))="none",LOWER(TRIM(A15))="n/a"),"",SUBSTITUTE(SUBSTITUTE(SUBSTITUTE(SUBSTITUTE(SUBSTITUTE(SUBSTITUTE(SUBSTITUTE(SUBSTITUTE(SUBSTITUTE(SUBSTITUTE(SUBSTITUTE(SUBSTITUTE(SUBSTITUTE(SUBSTITUTE(SUBSTITUTE(SUBSTITUTE(SUBSTITUTE(SUBSTITUTE(SUBSTITUTE(SUBSTITUTE(SUBSTITUTE(SUBSTITUTE(SUBSTITUTE(SUBSTITUTE(SUBSTITUTE(SUBSTITUTE(SUBSTITUTE(SUBSTITUTE(SUBSTITUTE(SUBSTITUTE(SUBSTITUTE(SUBSTITUTE(SUBSTITUTE(SUBSTITUTE(SUBSTITUTE(SUBSTITUTE(SUBSTITUTE(SUBSTITUTE(LOWER(TRIM(A15))," ","_"),"!","_"),"#","_"),"$","_"),"%","_"),"&","_"),"'","_"),"(","_"),")","_"),"*","_"),"+","_"),",","_"),"-","_"),".","_"),"/","_"),":","_"),";","_"),"<","_"),"=","_"),">","_"),"?","_"),"@","_"),"[","_"),"\","_"),"]","_"),"^","_"),"`","_"),"{","_"),"|","_"),"}","_"),"~","_"),"–","_"),"—","_"),"’","_"),"“","_"),"”","_"),CHAR(9),"_"),CHAR(160),"_")) | AJ15: =IF(AI15="","",SUBSTITUTE(SUBSTITUTE(SUBSTITUTE(SUBSTITUTE(SUBSTITUTE(SUBSTITUTE(SUBSTITUTE(SUBSTITUTE(AI15,"__","_"),"__","_"),"__","_"),"__","_"),"__","_"),"__","_"),"__","_"),"__","_")) | AK15: =IF(OR(AJ15="",AJ15="_"),"",IF(LEFT(AJ15,1)="_",IF(RIGHT(AJ15,1)="_",MID(AJ15,2,LEN(AJ15)-2),RIGHT(AJ15,LEN(AJ15)-1)),IF(RIGHT(AJ15,1)="_",LEFT(AJ15,LEN(AJ15)-1),AJ15))) | AL15: =IF(OR(LOWER(TRIM(B15))="",LOWER(TRIM(B15))="nan",LOWER(TRIM(B15))="none",LOWER(TRIM(B15))="n/a"),"",SUBSTITUTE(SUBSTITUTE(SUBSTITUTE(SUBSTITUTE(SUBSTITUTE(SUBSTITUTE(SUBSTITUTE(SUBSTITUTE(SUBSTITUTE(SUBSTITUTE(SUBSTITUTE(SUBSTITUTE(SUBSTITUTE(SUBSTITUTE(SUBSTITUTE(SUBSTITUTE(SUBSTITUTE(SUBSTITUTE(SUBSTITUTE(SUBSTITUTE(SUBSTITUTE(SUBSTITUTE(SUBSTITUTE(SUBSTITUTE(SUBSTITUTE(SUBSTITUTE(SUBSTITUTE(SUBSTITUTE(SUBSTITUTE(SUBSTITUTE(SUBSTITUTE(SUBSTITUTE(SUBSTITUTE(SUBSTITUTE(SUBSTITUTE(SUBSTITUTE(SUBSTITUTE(SUBSTITUTE(LOWER(TRIM(B15))," ","_"),"!","_"),"#","_"),"$","_"),"%","_"),"&","_"),"'","_"),"(","_"),")","_"),"*","_"),"+","_"),",","_"),"-","_"),".","_"),"/","_"),":","_"),";","_"),"<","_"),"=","_"),">","_"),"?","_"),"@","_"),"[","_"),"\","_"),"]","_"),"^","_"),"`","_"),"{","_"),"|","_"),"}","_"),"~","_"),"–","_"),"—","_"),"’","_"),"“","_"),"”","_"),CHAR(9),"_"),CHAR(160),"_")) | AM15: =IF(AL15="","",SUBSTITUTE(SUBSTITUTE(SUBSTITUTE(SUBSTITUTE(SUBSTITUTE(SUBSTITUTE(SUBSTITUTE(SUBSTITUTE(AL15,"__","_"),"__","_"),"__","_"),"__","_"),"__","_"),"__","_"),"__","_"),"__","_")) | AN15: =IF(OR(AM15="",AM15="_"),"",IF(LEFT(AM15,1)="_",IF(RIGHT(AM15,1)="_",MID(AM15,2,LEN(AM15)-2),RIGHT(AM15,LEN(AM15)-1)),IF(RIGHT(AM15,1)="_",LEFT(AM15,LEN(AM15)-1),AM15))) | AO15: =IF(OR(LOWER(TRIM(C15))="",LOWER(TRIM(C15))="nan",LOWER(TRIM(C15))="none",LOWER(TRIM(C15))="n/a"),"",SUBSTITUTE(SUBSTITUTE(SUBSTITUTE(SUBSTITUTE(SUBSTITUTE(SUBSTITUTE(SUBSTITUTE(SUBSTITUTE(SUBSTITUTE(SUBSTITUTE(SUBSTITUTE(SUBSTITUTE(SUBSTITUTE(SUBSTITUTE(SUBSTITUTE(SUBSTITUTE(SUBSTITUTE(SUBSTITUTE(SUBSTITUTE(SUBSTITUTE(SUBSTITUTE(SUBSTITUTE(SUBSTITUTE(SUBSTITUTE(SUBSTITUTE(SUBSTITUTE(SUBSTITUTE(SUBSTITUTE(SUBSTITUTE(SUBSTITUTE(SUBSTITUTE(SUBSTITUTE(SUBSTITUTE(SUBSTITUTE(SUBSTITUTE(SUBSTITUTE(SUBSTITUTE(SUBSTITUTE(LOWER(TRIM(C15))," ","_"),"!","_"),"#","_"),"$","_"),"%","_"),"&","_"),"'","_"),"(","_"),")","_"),"*","_"),"+","_"),",","_"),"-","_"),".","_"),"/","_"),":","_"),";","_"),"<","_"),"=","_"),">","_"),"?","_"),"@","_"),"[","_"),"\","_"),"]","_"),"^","_"),"`","_"),"{","_"),"|","_"),"}","_"),"~","_"),"–","_"),"—","_"),"’","_"),"“","_"),"”","_"),CHAR(9),"_"),CHAR(160),"_")) | AP15: =IF(AO15="","",SUBSTITUTE(SUBSTITUTE(SUBSTITUTE(SUBSTITUTE(SUBSTITUTE(SUBSTITUTE(SUBSTITUTE(SUBSTITUTE(AO15,"__","_"),"__","_"),"__","_"),"__","_"),"__","_"),"__","_"),"__","_"),"__","_")) | AQ15: =IF(OR(AP15="",AP15="_"),"",IF(LEFT(AP15,1)="_",IF(RIGHT(AP15,1)="_",MID(AP15,2,LEN(AP15)-2),RIGHT(AP15,LEN(AP15)-1)),IF(RIGHT(AP15,1)="_",LEFT(AP15,LEN(AP15)-1),AP15)))
H16: =IF(AK16<>"",AK16,"")&IF(AN16<>"",IF(AK16<>"","_"&AN16,AN16),"")&IF(AQ16<>"",IF(AK16<>"","_"&AQ16,AQ16),"") | I16: =IF(TRIM(G16)<>"",TRIM(G16),H16) | J16: =IF(OR(A16="",B16="",C16="",D16=""),"Missing required field — fill in product, metric_key, segment, and metric before this row can be used.",IF(H16="","Missing required field — product, metric_key, and segment must combine into an ID.",IF(COUNTIF($I$8:$I$32,I16)>1,"Duplicate outcome ID — two rows currently build the same outcome_id; add a distinguishing detail.",IF(AND(F16<>"",F16<>I16),"Existing outcome_id differs from the built ID — review before using.","Ready")))) | AI16: =IF(OR(LOWER(TRIM(A16))="",LOWER(TRIM(A16))="nan",LOWER(TRIM(A16))="none",LOWER(TRIM(A16))="n/a"),"",SUBSTITUTE(SUBSTITUTE(SUBSTITUTE(SUBSTITUTE(SUBSTITUTE(SUBSTITUTE(SUBSTITUTE(SUBSTITUTE(SUBSTITUTE(SUBSTITUTE(SUBSTITUTE(SUBSTITUTE(SUBSTITUTE(SUBSTITUTE(SUBSTITUTE(SUBSTITUTE(SUBSTITUTE(SUBSTITUTE(SUBSTITUTE(SUBSTITUTE(SUBSTITUTE(SUBSTITUTE(SUBSTITUTE(SUBSTITUTE(SUBSTITUTE(SUBSTITUTE(SUBSTITUTE(SUBSTITUTE(SUBSTITUTE(SUBSTITUTE(SUBSTITUTE(SUBSTITUTE(SUBSTITUTE(SUBSTITUTE(SUBSTITUTE(SUBSTITUTE(SUBSTITUTE(SUBSTITUTE(LOWER(TRIM(A16))," ","_"),"!","_"),"#","_"),"$","_"),"%","_"),"&","_"),"'","_"),"(","_"),")","_"),"*","_"),"+","_"),",","_"),"-","_"),".","_"),"/","_"),":","_"),";","_"),"<","_"),"=","_"),">","_"),"?","_"),"@","_"),"[","_"),"\","_"),"]","_"),"^","_"),"`","_"),"{","_"),"|","_"),"}","_"),"~","_"),"–","_"),"—","_"),"’","_"),"“","_"),"”","_"),CHAR(9),"_"),CHAR(160),"_")) | AJ16: =IF(AI16="","",SUBSTITUTE(SUBSTITUTE(SUBSTITUTE(SUBSTITUTE(SUBSTITUTE(SUBSTITUTE(SUBSTITUTE(SUBSTITUTE(AI16,"__","_"),"__","_"),"__","_"),"__","_"),"__","_"),"__","_"),"__","_"),"__","_")) | AK16: =IF(OR(AJ16="",AJ16="_"),"",IF(LEFT(AJ16,1)="_",IF(RIGHT(AJ16,1)="_",MID(AJ16,2,LEN(AJ16)-2),RIGHT(AJ16,LEN(AJ16)-1)),IF(RIGHT(AJ16,1)="_",LEFT(AJ16,LEN(AJ16)-1),AJ16))) | AL16: =IF(OR(LOWER(TRIM(B16))="",LOWER(TRIM(B16))="nan",LOWER(TRIM(B16))="none",LOWER(TRIM(B16))="n/a"),"",SUBSTITUTE(SUBSTITUTE(SUBSTITUTE(SUBSTITUTE(SUBSTITUTE(SUBSTITUTE(SUBSTITUTE(SUBSTITUTE(SUBSTITUTE(SUBSTITUTE(SUBSTITUTE(SUBSTITUTE(SUBSTITUTE(SUBSTITUTE(SUBSTITUTE(SUBSTITUTE(SUBSTITUTE(SUBSTITUTE(SUBSTITUTE(SUBSTITUTE(SUBSTITUTE(SUBSTITUTE(SUBSTITUTE(SUBSTITUTE(SUBSTITUTE(SUBSTITUTE(SUBSTITUTE(SUBSTITUTE(SUBSTITUTE(SUBSTITUTE(SUBSTITUTE(SUBSTITUTE(SUBSTITUTE(SUBSTITUTE(SUBSTITUTE(SUBSTITUTE(SUBSTITUTE(SUBSTITUTE(LOWER(TRIM(B16))," ","_"),"!","_"),"#","_"),"$","_"),"%","_"),"&","_"),"'","_"),"(","_"),")","_"),"*","_"),"+","_"),",","_"),"-","_"),".","_"),"/","_"),":","_"),";","_"),"<","_"),"=","_"),">","_"),"?","_"),"@","_"),"[","_"),"\","_"),"]","_"),"^","_"),"`","_"),"{","_"),"|","_"),"}","_"),"~","_"),"–","_"),"—","_"),"’","_"),"“","_"),"”","_"),CHAR(9),"_"),CHAR(160),"_")) | AM16: =IF(AL16="","",SUBSTITUTE(SUBSTITUTE(SUBSTITUTE(SUBSTITUTE(SUBSTITUTE(SUBSTITUTE(SUBSTITUTE(SUBSTITUTE(AL16,"__","_"),"__","_"),"__","_"),"__","_"),"__","_"),"__","_"),"__","_"),"__","_")) | AN16: =IF(OR(AM16="",AM16="_"),"",IF(LEFT(AM16,1)="_",IF(RIGHT(AM16,1)="_",MID(AM16,2,LEN(AM16)-2),RIGHT(AM16,LEN(AM16)-1)),IF(RIGHT(AM16,1)="_",LEFT(AM16,LEN(AM16)-1),AM16))) | AO16: =IF(OR(LOWER(TRIM(C16))="",LOWER(TRIM(C16))="nan",LOWER(TRIM(C16))="none",LOWER(TRIM(C16))="n/a"),"",SUBSTITUTE(SUBSTITUTE(SUBSTITUTE(SUBSTITUTE(SUBSTITUTE(SUBSTITUTE(SUBSTITUTE(SUBSTITUTE(SUBSTITUTE(SUBSTITUTE(SUBSTITUTE(SUBSTITUTE(SUBSTITUTE(SUBSTITUTE(SUBSTITUTE(SUBSTITUTE(SUBSTITUTE(SUBSTITUTE(SUBSTITUTE(SUBSTITUTE(SUBSTITUTE(SUBSTITUTE(SUBSTITUTE(SUBSTITUTE(SUBSTITUTE(SUBSTITUTE(SUBSTITUTE(SUBSTITUTE(SUBSTITUTE(SUBSTITUTE(SUBSTITUTE(SUBSTITUTE(SUBSTITUTE(SUBSTITUTE(SUBSTITUTE(SUBSTITUTE(SUBSTITUTE(SUBSTITUTE(LOWER(TRIM(C16))," ","_"),"!","_"),"#","_"),"$","_"),"%","_"),"&","_"),"'","_"),"(","_"),")","_"),"*","_"),"+","_"),",","_"),"-","_"),".","_"),"/","_"),":","_"),";","_"),"<","_"),"=","_"),">","_"),"?","_"),"@","_"),"[","_"),"\","_"),"]","_"),"^","_"),"`","_"),"{","_"),"|","_"),"}","_"),"~","_"),"–","_"),"—","_"),"’","_"),"“","_"),"”","_"),CHAR(9),"_"),CHAR(160),"_")) | AP16: =IF(AO16="","",SUBSTITUTE(SUBSTITUTE(SUBSTITUTE(SUBSTITUTE(SUBSTITUTE(SUBSTITUTE(SUBSTITUTE(SUBSTITUTE(AO16,"__","_"),"__","_"),"__","_"),"__","_"),"__","_"),"__","_"),"__","_"),"__","_")) | AQ16: =IF(OR(AP16="",AP16="_"),"",IF(LEFT(AP16,1)="_",IF(RIGHT(AP16,1)="_",MID(AP16,2,LEN(AP16)-2),RIGHT(AP16,LEN(AP16)-1)),IF(RIGHT(AP16,1)="_",LEFT(AP16,LEN(AP16)-1),AP16)))
H17: =IF(AK17<>"",AK17,"")&IF(AN17<>"",IF(AK17<>"","_"&AN17,AN17),"")&IF(AQ17<>"",IF(AK17<>"","_"&AQ17,AQ17),"") | I17: =IF(TRIM(G17)<>"",TRIM(G17),H17) | J17: =IF(OR(A17="",B17="",C17="",D17=""),"Missing required field — fill in product, metric_key, segment, and metric before this row can be used.",IF(H17="","Missing required field — product, metric_key, and segment must combine into an ID.",IF(COUNTIF($I$8:$I$32,I17)>1,"Duplicate outcome ID — two rows currently build the same outcome_id; add a distinguishing detail.",IF(AND(F17<>"",F17<>I17),"Existing outcome_id differs from the built ID — review before using.","Ready")))) | AI17: =IF(OR(LOWER(TRIM(A17))="",LOWER(TRIM(A17))="nan",LOWER(TRIM(A17))="none",LOWER(TRIM(A17))="n/a"),"",SUBSTITUTE(SUBSTITUTE(SUBSTITUTE(SUBSTITUTE(SUBSTITUTE(SUBSTITUTE(SUBSTITUTE(SUBSTITUTE(SUBSTITUTE(SUBSTITUTE(SUBSTITUTE(SUBSTITUTE(SUBSTITUTE(SUBSTITUTE(SUBSTITUTE(SUBSTITUTE(SUBSTITUTE(SUBSTITUTE(SUBSTITUTE(SUBSTITUTE(SUBSTITUTE(SUBSTITUTE(SUBSTITUTE(SUBSTITUTE(SUBSTITUTE(SUBSTITUTE(SUBSTITUTE(SUBSTITUTE(SUBSTITUTE(SUBSTITUTE(SUBSTITUTE(SUBSTITUTE(SUBSTITUTE(SUBSTITUTE(SUBSTITUTE(SUBSTITUTE(SUBSTITUTE(SUBSTITUTE(LOWER(TRIM(A17))," ","_"),"!","_"),"#","_"),"$","_"),"%","_"),"&","_"),"'","_"),"(","_"),")","_"),"*","_"),"+","_"),",","_"),"-","_"),".","_"),"/","_"),":","_"),";","_"),"<","_"),"=","_"),">","_"),"?","_"),"@","_"),"[","_"),"\","_"),"]","_"),"^","_"),"`","_"),"{","_"),"|","_"),"}","_"),"~","_"),"–","_"),"—","_"),"’","_"),"“","_"),"”","_"),CHAR(9),"_"),CHAR(160),"_")) | AJ17: =IF(AI17="","",SUBSTITUTE(SUBSTITUTE(SUBSTITUTE(SUBSTITUTE(SUBSTITUTE(SUBSTITUTE(SUBSTITUTE(SUBSTITUTE(AI17,"__","_"),"__","_"),"__","_"),"__","_"),"__","_"),"__","_"),"__","_"),"__","_")) | AK17: =IF(OR(AJ17="",AJ17="_"),"",IF(LEFT(AJ17,1)="_",IF(RIGHT(AJ17,1)="_",MID(AJ17,2,LEN(AJ17)-2),RIGHT(AJ17,LEN(AJ17)-1)),IF(RIGHT(AJ17,1)="_",LEFT(AJ17,LEN(AJ17)-1),AJ17))) | AL17: =IF(OR(LOWER(TRIM(B17))="",LOWER(TRIM(B17))="nan",LOWER(TRIM(B17))="none",LOWER(TRIM(B17))="n/a"),"",SUBSTITUTE(SUBSTITUTE(SUBSTITUTE(SUBSTITUTE(SUBSTITUTE(SUBSTITUTE(SUBSTITUTE(SUBSTITUTE(SUBSTITUTE(SUBSTITUTE(SUBSTITUTE(SUBSTITUTE(SUBSTITUTE(SUBSTITUTE(SUBSTITUTE(SUBSTITUTE(SUBSTITUTE(SUBSTITUTE(SUBSTITUTE(SUBSTITUTE(SUBSTITUTE(SUBSTITUTE(SUBSTITUTE(SUBSTITUTE(SUBSTITUTE(SUBSTITUTE(SUBSTITUTE(SUBSTITUTE(SUBSTITUTE(SUBSTITUTE(SUBSTITUTE(SUBSTITUTE(SUBSTITUTE(SUBSTITUTE(SUBSTITUTE(SUBSTITUTE(SUBSTITUTE(SUBSTITUTE(LOWER(TRIM(B17))," ","_"),"!","_"),"#","_"),"$","_"),"%","_"),"&","_"),"'","_"),"(","_"),")","_"),"*","_"),"+","_"),",","_"),"-","_"),".","_"),"/","_"),":","_"),";","_"),"<","_"),"=","_"),">","_"),"?","_"),"@","_"),"[","_"),"\","_"),"]","_"),"^","_"),"`","_"),"{","_"),"|","_"),"}","_"),"~","_"),"–","_"),"—","_"),"’","_"),"“","_"),"”","_"),CHAR(9),"_"),CHAR(160),"_")) | AM17: =IF(AL17="","",SUBSTITUTE(SUBSTITUTE(SUBSTITUTE(SUBSTITUTE(SUBSTITUTE(SUBSTITUTE(SUBSTITUTE(SUBSTITUTE(AL17,"__","_"),"__","_"),"__","_"),"__","_"),"__","_"),"__","_"),"__","_"),"__","_")) | AN17: =IF(OR(AM17="",AM17="_"),"",IF(LEFT(AM17,1)="_",IF(RIGHT(AM17,1)="_",MID(AM17,2,LEN(AM17)-2),RIGHT(AM17,LEN(AM17)-1)),IF(RIGHT(AM17,1)="_",LEFT(AM17,LEN(AM17)-1),AM17))) | AO17: =IF(OR(LOWER(TRIM(C17))="",LOWER(TRIM(C17))="nan",LOWER(TRIM(C17))="none",LOWER(TRIM(C17))="n/a"),"",SUBSTITUTE(SUBSTITUTE(SUBSTITUTE(SUBSTITUTE(SUBSTITUTE(SUBSTITUTE(SUBSTITUTE(SUBSTITUTE(SUBSTITUTE(SUBSTITUTE(SUBSTITUTE(SUBSTITUTE(SUBSTITUTE(SUBSTITUTE(SUBSTITUTE(SUBSTITUTE(SUBSTITUTE(SUBSTITUTE(SUBSTITUTE(SUBSTITUTE(SUBSTITUTE(SUBSTITUTE(SUBSTITUTE(SUBSTITUTE(SUBSTITUTE(SUBSTITUTE(SUBSTITUTE(SUBSTITUTE(SUBSTITUTE(SUBSTITUTE(SUBSTITUTE(SUBSTITUTE(SUBSTITUTE(SUBSTITUTE(SUBSTITUTE(SUBSTITUTE(SUBSTITUTE(SUBSTITUTE(LOWER(TRIM(C17))," ","_"),"!","_"),"#","_"),"$","_"),"%","_"),"&","_"),"'","_"),"(","_"),")","_"),"*","_"),"+","_"),",","_"),"-","_"),".","_"),"/","_"),":","_"),";","_"),"<","_"),"=","_"),">","_"),"?","_"),"@","_"),"[","_"),"\","_"),"]","_"),"^","_"),"`","_"),"{","_"),"|","_"),"}","_"),"~","_"),"–","_"),"—","_"),"’","_"),"“","_"),"”","_"),CHAR(9),"_"),CHAR(160),"_")) | AP17: =IF(AO17="","",SUBSTITUTE(SUBSTITUTE(SUBSTITUTE(SUBSTITUTE(SUBSTITUTE(SUBSTITUTE(SUBSTITUTE(SUBSTITUTE(AO17,"__","_"),"__","_"),"__","_"),"__","_"),"__","_"),"__","_"),"__","_"),"__","_")) | AQ17: =IF(OR(AP17="",AP17="_"),"",IF(LEFT(AP17,1)="_",IF(RIGHT(AP17,1)="_",MID(AP17,2,LEN(AP17)-2),RIGHT(AP17,LEN(AP17)-1)),IF(RIGHT(AP17,1)="_",LEFT(AP17,LEN(AP17)-1),AP17)))
H18: =IF(AK18<>"",AK18,"")&IF(AN18<>"",IF(AK18<>"","_"&AN18,AN18),"")&IF(AQ18<>"",IF(AK18<>"","_"&AQ18,AQ18),"") | I18: =IF(TRIM(G18)<>"",TRIM(G18),H18) | J18: =IF(OR(A18="",B18="",C18="",D18=""),"Missing required field — fill in product, metric_key, segment, and metric before this row can be used.",IF(H18="","Missing required field — product, metric_key, and segment must combine into an ID.",IF(COUNTIF($I$8:$I$32,I18)>1,"Duplicate outcome ID — two rows currently build the same outcome_id; add a distinguishing detail.",IF(AND(F18<>"",F18<>I18),"Existing outcome_id differs from the built ID — review before using.","Ready")))) | AI18: =IF(OR(LOWER(TRIM(A18))="",LOWER(TRIM(A18))="nan",LOWER(TRIM(A18))="none",LOWER(TRIM(A18))="n/a"),"",SUBSTITUTE(SUBSTITUTE(SUBSTITUTE(SUBSTITUTE(SUBSTITUTE(SUBSTITUTE(SUBSTITUTE(SUBSTITUTE(SUBSTITUTE(SUBSTITUTE(SUBSTITUTE(SUBSTITUTE(SUBSTITUTE(SUBSTITUTE(SUBSTITUTE(SUBSTITUTE(SUBSTITUTE(SUBSTITUTE(SUBSTITUTE(SUBSTITUTE(SUBSTITUTE(SUBSTITUTE(SUBSTITUTE(SUBSTITUTE(SUBSTITUTE(SUBSTITUTE(SUBSTITUTE(SUBSTITUTE(SUBSTITUTE(SUBSTITUTE(SUBSTITUTE(SUBSTITUTE(SUBSTITUTE(SUBSTITUTE(SUBSTITUTE(SUBSTITUTE(SUBSTITUTE(SUBSTITUTE(LOWER(TRIM(A18))," ","_"),"!","_"),"#","_"),"$","_"),"%","_"),"&","_"),"'","_"),"(","_"),")","_"),"*","_"),"+","_"),",","_"),"-","_"),".","_"),"/","_"),":","_"),";","_"),"<","_"),"=","_"),">","_"),"?","_"),"@","_"),"[","_"),"\","_"),"]","_"),"^","_"),"`","_"),"{","_"),"|","_"),"}","_"),"~","_"),"–","_"),"—","_"),"’","_"),"“","_"),"”","_"),CHAR(9),"_"),CHAR(160),"_")) | AJ18: =IF(AI18="","",SUBSTITUTE(SUBSTITUTE(SUBSTITUTE(SUBSTITUTE(SUBSTITUTE(SUBSTITUTE(SUBSTITUTE(SUBSTITUTE(AI18,"__","_"),"__","_"),"__","_"),"__","_"),"__","_"),"__","_"),"__","_"),"__","_")) | AK18: =IF(OR(AJ18="",AJ18="_"),"",IF(LEFT(AJ18,1)="_",IF(RIGHT(AJ18,1)="_",MID(AJ18,2,LEN(AJ18)-2),RIGHT(AJ18,LEN(AJ18)-1)),IF(RIGHT(AJ18,1)="_",LEFT(AJ18,LEN(AJ18)-1),AJ18))) | AL18: =IF(OR(LOWER(TRIM(B18))="",LOWER(TRIM(B18))="nan",LOWER(TRIM(B18))="none",LOWER(TRIM(B18))="n/a"),"",SUBSTITUTE(SUBSTITUTE(SUBSTITUTE(SUBSTITUTE(SUBSTITUTE(SUBSTITUTE(SUBSTITUTE(SUBSTITUTE(SUBSTITUTE(SUBSTITUTE(SUBSTITUTE(SUBSTITUTE(SUBSTITUTE(SUBSTITUTE(SUBSTITUTE(SUBSTITUTE(SUBSTITUTE(SUBSTITUTE(SUBSTITUTE(SUBSTITUTE(SUBSTITUTE(SUBSTITUTE(SUBSTITUTE(SUBSTITUTE(SUBSTITUTE(SUBSTITUTE(SUBSTITUTE(SUBSTITUTE(SUBSTITUTE(SUBSTITUTE(SUBSTITUTE(SUBSTITUTE(SUBSTITUTE(SUBSTITUTE(SUBSTITUTE(SUBSTITUTE(SUBSTITUTE(SUBSTITUTE(LOWER(TRIM(B18))," ","_"),"!","_"),"#","_"),"$","_"),"%","_"),"&","_"),"'","_"),"(","_"),")","_"),"*","_"),"+","_"),",","_"),"-","_"),".","_"),"/","_"),":","_"),";","_"),"<","_"),"=","_"),">","_"),"?","_"),"@","_"),"[","_"),"\","_"),"]","_"),"^","_"),"`","_"),"{","_"),"|","_"),"}","_"),"~","_"),"–","_"),"—","_"),"’","_"),"“","_"),"”","_"),CHAR(9),"_"),CHAR(160),"_")) | AM18: =IF(AL18="","",SUBSTITUTE(SUBSTITUTE(SUBSTITUTE(SUBSTITUTE(SUBSTITUTE(SUBSTITUTE(SUBSTITUTE(SUBSTITUTE(AL18,"__","_"),"__","_"),"__","_"),"__","_"),"__","_"),"__","_"),"__","_"),"__","_")) | AN18: =IF(OR(AM18="",AM18="_"),"",IF(LEFT(AM18,1)="_",IF(RIGHT(AM18,1)="_",MID(AM18,2,LEN(AM18)-2),RIGHT(AM18,LEN(AM18)-1)),IF(RIGHT(AM18,1)="_",LEFT(AM18,LEN(AM18)-1),AM18))) | AO18: =IF(OR(LOWER(TRIM(C18))="",LOWER(TRIM(C18))="nan",LOWER(TRIM(C18))="none",LOWER(TRIM(C18))="n/a"),"",SUBSTITUTE(SUBSTITUTE(SUBSTITUTE(SUBSTITUTE(SUBSTITUTE(SUBSTITUTE(SUBSTITUTE(SUBSTITUTE(SUBSTITUTE(SUBSTITUTE(SUBSTITUTE(SUBSTITUTE(SUBSTITUTE(SUBSTITUTE(SUBSTITUTE(SUBSTITUTE(SUBSTITUTE(SUBSTITUTE(SUBSTITUTE(SUBSTITUTE(SUBSTITUTE(SUBSTITUTE(SUBSTITUTE(SUBSTITUTE(SUBSTITUTE(SUBSTITUTE(SUBSTITUTE(SUBSTITUTE(SUBSTITUTE(SUBSTITUTE(SUBSTITUTE(SUBSTITUTE(SUBSTITUTE(SUBSTITUTE(SUBSTITUTE(SUBSTITUTE(SUBSTITUTE(SUBSTITUTE(LOWER(TRIM(C18))," ","_"),"!","_"),"#","_"),"$","_"),"%","_"),"&","_"),"'","_"),"(","_"),")","_"),"*","_"),"+","_"),",","_"),"-","_"),".","_"),"/","_"),":","_"),";","_"),"<","_"),"=","_"),">","_"),"?","_"),"@","_"),"[","_"),"\","_"),"]","_"),"^","_"),"`","_"),"{","_"),"|","_"),"}","_"),"~","_"),"–","_"),"—","_"),"’","_"),"“","_"),"”","_"),CHAR(9),"_"),CHAR(160),"_")) | AP18: =IF(AO18="","",SUBSTITUTE(SUBSTITUTE(SUBSTITUTE(SUBSTITUTE(SUBSTITUTE(SUBSTITUTE(SUBSTITUTE(SUBSTITUTE(AO18,"__","_"),"__","_"),"__","_"),"__","_"),"__","_"),"__","_"),"__","_"),"__","_")) | AQ18: =IF(OR(AP18="",AP18="_"),"",IF(LEFT(AP18,1)="_",IF(RIGHT(AP18,1)="_",MID(AP18,2,LEN(AP18)-2),RIGHT(AP18,LEN(AP18)-1)),IF(RIGHT(AP18,1)="_",LEFT(AP18,LEN(AP18)-1),AP18)))
H19: =IF(AK19<>"",AK19,"")&IF(AN19<>"",IF(AK19<>"","_"&AN19,AN19),"")&IF(AQ19<>"",IF(AK19<>"","_"&AQ19,AQ19),"") | I19: =IF(TRIM(G19)<>"",TRIM(G19),H19) | J19: =IF(OR(A19="",B19="",C19="",D19=""),"Missing required field — fill in product, metric_key, segment, and metric before this row can be used.",IF(H19="","Missing required field — product, metric_key, and segment must combine into an ID.",IF(COUNTIF($I$8:$I$32,I19)>1,"Duplicate outcome ID — two rows currently build the same outcome_id; add a distinguishing detail.",IF(AND(F19<>"",F19<>I19),"Existing outcome_id differs from the built ID — review before using.","Ready")))) | AI19: =IF(OR(LOWER(TRIM(A19))="",LOWER(TRIM(A19))="nan",LOWER(TRIM(A19))="none",LOWER(TRIM(A19))="n/a"),"",SUBSTITUTE(SUBSTITUTE(SUBSTITUTE(SUBSTITUTE(SUBSTITUTE(SUBSTITUTE(SUBSTITUTE(SUBSTITUTE(SUBSTITUTE(SUBSTITUTE(SUBSTITUTE(SUBSTITUTE(SUBSTITUTE(SUBSTITUTE(SUBSTITUTE(SUBSTITUTE(SUBSTITUTE(SUBSTITUTE(SUBSTITUTE(SUBSTITUTE(SUBSTITUTE(SUBSTITUTE(SUBSTITUTE(SUBSTITUTE(SUBSTITUTE(SUBSTITUTE(SUBSTITUTE(SUBSTITUTE(SUBSTITUTE(SUBSTITUTE(SUBSTITUTE(SUBSTITUTE(SUBSTITUTE(SUBSTITUTE(SUBSTITUTE(SUBSTITUTE(SUBSTITUTE(SUBSTITUTE(LOWER(TRIM(A19))," ","_"),"!","_"),"#","_"),"$","_"),"%","_"),"&","_"),"'","_"),"(","_"),")","_"),"*","_"),"+","_"),",","_"),"-","_"),".","_"),"/","_"),":","_"),";","_"),"<","_"),"=","_"),">","_"),"?","_"),"@","_"),"[","_"),"\","_"),"]","_"),"^","_"),"`","_"),"{","_"),"|","_"),"}","_"),"~","_"),"–","_"),"—","_"),"’","_"),"“","_"),"”","_"),CHAR(9),"_"),CHAR(160),"_")) | AJ19: =IF(AI19="","",SUBSTITUTE(SUBSTITUTE(SUBSTITUTE(SUBSTITUTE(SUBSTITUTE(SUBSTITUTE(SUBSTITUTE(SUBSTITUTE(AI19,"__","_"),"__","_"),"__","_"),"__","_"),"__","_"),"__","_"),"__","_"),"__","_")) | AK19: =IF(OR(AJ19="",AJ19="_"),"",IF(LEFT(AJ19,1)="_",IF(RIGHT(AJ19,1)="_",MID(AJ19,2,LEN(AJ19)-2),RIGHT(AJ19,LEN(AJ19)-1)),IF(RIGHT(AJ19,1)="_",LEFT(AJ19,LEN(AJ19)-1),AJ19))) | AL19: =IF(OR(LOWER(TRIM(B19))="",LOWER(TRIM(B19))="nan",LOWER(TRIM(B19))="none",LOWER(TRIM(B19))="n/a"),"",SUBSTITUTE(SUBSTITUTE(SUBSTITUTE(SUBSTITUTE(SUBSTITUTE(SUBSTITUTE(SUBSTITUTE(SUBSTITUTE(SUBSTITUTE(SUBSTITUTE(SUBSTITUTE(SUBSTITUTE(SUBSTITUTE(SUBSTITUTE(SUBSTITUTE(SUBSTITUTE(SUBSTITUTE(SUBSTITUTE(SUBSTITUTE(SUBSTITUTE(SUBSTITUTE(SUBSTITUTE(SUBSTITUTE(SUBSTITUTE(SUBSTITUTE(SUBSTITUTE(SUBSTITUTE(SUBSTITUTE(SUBSTITUTE(SUBSTITUTE(SUBSTITUTE(SUBSTITUTE(SUBSTITUTE(SUBSTITUTE(SUBSTITUTE(SUBSTITUTE(SUBSTITUTE(SUBSTITUTE(LOWER(TRIM(B19))," ","_"),"!","_"),"#","_"),"$","_"),"%","_"),"&","_"),"'","_"),"(","_"),")","_"),"*","_"),"+","_"),",","_"),"-","_"),".","_"),"/","_"),":","_"),";","_"),"<","_"),"=","_"),">","_"),"?","_"),"@","_"),"[","_"),"\","_"),"]","_"),"^","_"),"`","_"),"{","_"),"|","_"),"}","_"),"~","_"),"–","_"),"—","_"),"’","_"),"“","_"),"”","_"),CHAR(9),"_"),CHAR(160),"_")) | AM19: =IF(AL19="","",SUBSTITUTE(SUBSTITUTE(SUBSTITUTE(SUBSTITUTE(SUBSTITUTE(SUBSTITUTE(SUBSTITUTE(SUBSTITUTE(AL19,"__","_"),"__","_"),"__","_"),"__","_"),"__","_"),"__","_"),"__","_"),"__","_")) | AN19: =IF(OR(AM19="",AM19="_"),"",IF(LEFT(AM19,1)="_",IF(RIGHT(AM19,1)="_",MID(AM19,2,LEN(AM19)-2),RIGHT(AM19,LEN(AM19)-1)),IF(RIGHT(AM19,1)="_",LEFT(AM19,LEN(AM19)-1),AM19))) | AO19: =IF(OR(LOWER(TRIM(C19))="",LOWER(TRIM(C19))="nan",LOWER(TRIM(C19))="none",LOWER(TRIM(C19))="n/a"),"",SUBSTITUTE(SUBSTITUTE(SUBSTITUTE(SUBSTITUTE(SUBSTITUTE(SUBSTITUTE(SUBSTITUTE(SUBSTITUTE(SUBSTITUTE(SUBSTITUTE(SUBSTITUTE(SUBSTITUTE(SUBSTITUTE(SUBSTITUTE(SUBSTITUTE(SUBSTITUTE(SUBSTITUTE(SUBSTITUTE(SUBSTITUTE(SUBSTITUTE(SUBSTITUTE(SUBSTITUTE(SUBSTITUTE(SUBSTITUTE(SUBSTITUTE(SUBSTITUTE(SUBSTITUTE(SUBSTITUTE(SUBSTITUTE(SUBSTITUTE(SUBSTITUTE(SUBSTITUTE(SUBSTITUTE(SUBSTITUTE(SUBSTITUTE(SUBSTITUTE(SUBSTITUTE(SUBSTITUTE(LOWER(TRIM(C19))," ","_"),"!","_"),"#","_"),"$","_"),"%","_"),"&","_"),"'","_"),"(","_"),")","_"),"*","_"),"+","_"),",","_"),"-","_"),".","_"),"/","_"),":","_"),";","_"),"<","_"),"=","_"),">","_"),"?","_"),"@","_"),"[","_"),"\","_"),"]","_"),"^","_"),"`","_"),"{","_"),"|","_"),"}","_"),"~","_"),"–","_"),"—","_"),"’","_"),"“","_"),"”","_"),CHAR(9),"_"),CHAR(160),"_")) | AP19: =IF(AO19="","",SUBSTITUTE(SUBSTITUTE(SUBSTITUTE(SUBSTITUTE(SUBSTITUTE(SUBSTITUTE(SUBSTITUTE(SUBSTITUTE(AO19,"__","_"),"__","_"),"__","_"),"__","_"),"__","_"),"__","_"),"__","_"),"__","_")) | AQ19: =IF(OR(AP19="",AP19="_"),"",IF(LEFT(AP19,1)="_",IF(RIGHT(AP19,1)="_",MID(AP19,2,LEN(AP19)-2),RIGHT(AP19,LEN(AP19)-1)),IF(RIGHT(AP19,1)="_",LEFT(AP19,LEN(AP19)-1),AP19)))
