Workbook

Sheet START_HERE
A1: Context / External Factor Dictionary Builder
A2: Formula-driven, no VBA -- builds a complete variable_dictionary row and its variable_id
A4: What this builder is for
A5: Use this workbook to define one row per context variable -- things outside your control that might explain changes in an outcome, like CPI, seasonality, or a named event flag.
A6: It builds a stable variable_id for you from the variable's class and concept, and produces a clean row ready to paste into the variable_dictionary sheet of the standard Context and External Factors upload workbook.
A8: What you need to fill in
A9: Go to the BUILDER sheet. Fill in variable_class, concept, native_frequency, and role for every variable row.
A10: Only fill in source and scope once this variable is reviewed for wider use ("adoption") -- not needed for a first upload.
A12: What is generated automatically
A13: Generated ID -- built from variable_class and the concept name.
A14: Final ID -- the Generated ID, unless you type something in Manual override.
A15: Row status -- plain-English text telling you if the row is Ready, missing something, or a duplicate.
... A39: This builder never asks for your actual observed values. Those go in the context_data sheet of the same upload workbook, one row per period_start x market x variable_id, at whatever frequency the source actually publishes.

Sheet BUILDER
A7: variable_class | B7: concept (not an upload column) | C7: native_frequency | D7: role | E7: variable_id (existing) | F7: Manual override | G7: Generated ID | H7: Final ID | I7: Row status | J7: source | K7: scope | L7: effective_from | M7: effective_to | P7: _A_clean | Q7: _A_collapsed | R7: _A_token | S7: _B_clean | T7: _B_collapsed | U7: _B_token
A8: rate_index | B8: UK CPI | C8: monthly | D8: exogenous_forecastable_control | G8: =IF(R8<>"",R8,"")&IF(U8<>"",IF(R8<>"","_"&U8,U8),"") | H8: =IF(TRIM(F8)<>"",TRIM(F8),G8) | I8: =IF(OR(A8="",B8="",C8="",D8=""),"Missing required field — fill in variable_class, the concept name, native_frequency, and role.",IF(G8="","Missing required field — variable_class and the concept name must combine into an ID.",IF(COUNTIF($H$8:$H$32,H8)>1,"Duplicate variable ID — two rows currently build the same variable_id; distinguish the actual variable, not its source frequency.",IF(AND(E8<>"",E8<>H8),"Existing variable_id differs from the built ID — review before using.","Ready")))) | P8: =IF(OR(LOWER(TRIM(A8))="",LOWER(TRIM(A8))="nan",LOWER(TRIM(A8))="none",LOWER(TRIM(A8))="n/a"),"",SUBSTITUTE(SUBSTITUTE(SUBSTITUTE(SUBSTITUTE(SUBSTITUTE(SUBSTITUTE(SUBSTITUTE(SUBSTITUTE(SUBSTITUTE(SUBSTITUTE(SUBSTITUTE(SUBSTITUTE(SUBSTITUTE(SUBSTITUTE(SUBSTITUTE(SUBSTITUTE(SUBSTITUTE(SUBSTITUTE(SUBSTITUTE(SUBSTITUTE(SUBSTITUTE(SUBSTITUTE(SUBSTITUTE(SUBSTITUTE(SUBSTITUTE(SUBSTITUTE(SUBSTITUTE(SUBSTITUTE(SUBSTITUTE(SUBSTITUTE(SUBSTITUTE(SUBSTITUTE(SUBSTITUTE(SUBSTITUTE(SUBSTITUTE(SUBSTITUTE(SUBSTITUTE(SUBSTITUTE(LOWER(TRIM(A8))," ","_"),"!","_"),"#","_"),"$","_"),"%","_"),"&","_"),"'","_"),"(","_"),")","_"),"*","_"),"+","_"),",","_"),"-","_"),".","_"),"/","_"),":","_"),";","_"),"<","_"),"=","_"),">","_"),"?","_"),"@","_"),"[","_"),"\","_"),"]","_"),"^","_"),"`","_"),"{","_"),"|","_"),"}","_"),"~","_"),"–","_"),"—","_"),"’","_"),"“","_"),"”","_"),CHAR(9),"_"),CHAR(160),"_")) | Q8: =IF(P8="","",SUBSTITUTE(SUBSTITUTE(SUBSTITUTE(SUBSTITUTE(SUBSTITUTE(SUBSTITUTE(SUBSTITUTE(SUBSTITUTE(P8,"__","_"),"__","_"),"__","_"),"__","_"),"__","_"),"__","_"),"__","_"),"__","_")) | R8: =IF(OR(Q8="",Q8="_"),"",IF(LEFT(Q8,1)="_",IF(RIGHT(Q8,1)="_",MID(Q8,2,LEN(Q8)-2),RIGHT(Q8,LEN(Q8)-1)),IF(RIGHT(Q8,1)="_",LEFT(Q8,LEN(Q8)-1),Q8))) | S8: =IF(OR(LOWER(TRIM(B8))="",LOWER(TRIM(B8))="nan",LOWER(TRIM(B8))="none",LOWER(TRIM(B8))="n/a"),"",SUBSTITUTE(SUBSTITUTE(SUBSTITUTE(SUBSTITUTE(SUBSTITUTE(SUBSTITUTE(SUBSTITUTE(SUBSTITUTE(SUBSTITUTE(SUBSTITUTE(SUBSTITUTE(SUBSTITUTE(SUBSTITUTE(SUBSTITUTE(SUBSTITUTE(SUBSTITUTE(SUBSTITUTE(SUBSTITUTE(SUBSTITUTE(SUBSTITUTE(SUBSTITUTE(SUBSTITUTE(SUBSTITUTE(SUBSTITUTE(SUBSTITUTE(SUBSTITUTE(SUBSTITUTE(SUBSTITUTE(SUBSTITUTE(SUBSTITUTE(SUBSTITUTE(SUBSTITUTE(SUBSTITUTE(SUBSTITUTE(SUBSTITUTE(SUBSTITUTE(SUBSTITUTE(SUBSTITUTE(LOWER(TRIM(B8))," ","_"),"!","_"),"#","_"),"$","_"),"%","_"),"&","_"),"'","_"),"(","_"),")","_"),"*","_"),"+","_"),",","_"),"-","_"),".","_"),"/","_"),":","_"),";","_"),"<","_"),"=","_"),">","_"),"?","_"),"@","_"),"[","_"),"\","_"),"]","_"),"^","_"),"`","_"),"{","_"),"|","_"),"}","_"),"~","_"),"–","_"),"—","_"),"’","_"),"“","_"),"”","_"),CHAR(9),"_"),CHAR(160),"_")) | T8: =IF(S8="","",SUBSTITUTE(SUBSTITUTE(SUBSTITUTE(SUBSTITUTE(SUBSTITUTE(SUBSTITUTE(SUBSTITUTE(SUBSTITUTE(S8,"__","_"),"__","_"),"__","_"),"__","_"),"__","_"),"__","_"),"__","_"),"__","_")) | U8: =IF(OR(T8="",T8="_"),"",IF(LEFT(T8,1)="_",IF(RIGHT(T8,1)="_",MID(T8,2,LEN(T8)-2),RIGHT(T8,LEN(T8)-1)),IF(RIGHT(T8,1)="_",LEFT(T8,LEN(T8)-1),T8)))
A9: flow_count | B9: UK unemployment claims | C9: monthly | D9: exogenous_forecastable_control | G9: =IF(R9<>"",R9,"")&IF(U9<>"",IF(R9<>"","_"&U9,U9),"") | H9: =IF(TRIM(F9)<>"",TRIM(F9),G9) | I9: =IF(OR(A9="",B9="",C9="",D9=""),"Missing required field — fill in variable_class, the concept name, native_frequency, and role.",IF(G9="","Missing required field — variable_class and the concept name must combine into an ID.",IF(COUNTIF($H$8:$H$32,H9)>1,"Duplicate variable ID — two rows currently build the same variable_id; distinguish the actual variable, not its source frequency.",IF(AND(E9<>"",E9<>H9),"Existing variable_id differs from the built ID — review before using.","Ready")))) | P9: =IF(OR(LOWER(TRIM(A9))="",LOWER(TRIM(A9))="nan",LOWER(TRIM(A9))="none",LOWER(TRIM(A9))="n/a"),"",SUBSTITUTE(SUBSTITUTE(SUBSTITUTE(SUBSTITUTE(SUBSTITUTE(SUBSTITUTE(SUBSTITUTE(SUBSTITUTE(SUBSTITUTE(SUBSTITUTE(SUBSTITUTE(SUBSTITUTE(SUBSTITUTE(SUBSTITUTE(SUBSTITUTE(SUBSTITUTE(SUBSTITUTE(SUBSTITUTE(SUBSTITUTE(SUBSTITUTE(SUBSTITUTE(SUBSTITUTE(SUBSTITUTE(SUBSTITUTE(SUBSTITUTE(SUBSTITUTE(SUBSTITUTE(SUBSTITUTE(SUBSTITUTE(SUBSTITUTE(SUBSTITUTE(SUBSTITUTE(SUBSTITUTE(SUBSTITUTE(SUBSTITUTE(SUBSTITUTE(SUBSTITUTE(SUBSTITUTE(LOWER(TRIM(A9))," ","_"),"!","_"),"#","_"),"$","_"),"%","_"),"&","_"),"'","_"),"(","_"),")","_"),"*","_"),"+","_"),",","_"),"-","_"),".","_"),"/","_"),":","_"),";","_"),"<","_"),"=","_"),">","_"),"?","_"),"@","_"),"[","_"),"\","_"),"]","_"),"^","_"),"`","_"),"{","_"),"|","_"),"}","_"),"~","_"),"–","_"),"—","_"),"’","_"),"“","_"),"”","_"),CHAR(9),"_"),CHAR(160),"_")) | Q9: =IF(P9="","",SUBSTITUTE(SUBSTITUTE(SUBSTITUTE(SUBSTITUTE(SUBSTITUTE(SUBSTITUTE(SUBSTITUTE(SUBSTITUTE(P9,"__","_"),"__","_"),"__","_"),"__","_"),"__","_"),"__","_"),"__","_"),"__","_")) | R9: =IF(OR(Q9="",Q9="_"),"",IF(LEFT(Q9,1)="_",IF(RIGHT(Q9,1)="_",MID(Q9,2,LEN(Q9)-2),RIGHT(Q9,LEN(Q9)-1)),IF(RIGHT(Q9,1)="_",LEFT(Q9,LEN(Q9)-1),Q9))) | S9: =IF(OR(LOWER(TRIM(B9))="",LOWER(TRIM(B9))="nan",LOWER(TRIM(B9))="none",LOWER(TRIM(B9))="n/a"),"",SUBSTITUTE(SUBSTITUTE(SUBSTITUTE(SUBSTITUTE(SUBSTITUTE(SUBSTITUTE(SUBSTITUTE(SUBSTITUTE(SUBSTITUTE(SUBSTITUTE(SUBSTITUTE(SUBSTITUTE(SUBSTITUTE(SUBSTITUTE(SUBSTITUTE(SUBSTITUTE(SUBSTITUTE(SUBSTITUTE(SUBSTITUTE(SUBSTITUTE(SUBSTITUTE(SUBSTITUTE(SUBSTITUTE(SUBSTITUTE(SUBSTITUTE(SUBSTITUTE(SUBSTITUTE(SUBSTITUTE(SUBSTITUTE(SUBSTITUTE(SUBSTITUTE(SUBSTITUTE(SUBSTITUTE(SUBSTITUTE(SUBSTITUTE(SUBSTITUTE(SUBSTITUTE(SUBSTITUTE(LOWER(TRIM(B9))," ","_"),"!","_"),"#","_"),"$","_"),"%","_"),"&","_"),"'","_"),"(","_"),")","_"),"*","_"),"+","_"),",","_"),"-","_"),".","_"),"/","_"),":","_"),";","_"),"<","_"),"=","_"),">","_"),"?","_"),"@","_"),"[","_"),"\","_"),"]","_"),"^","_"),"`","_"),"{","_"),"|","_"),"}","_"),"~","_"),"–","_"),"—","_"),"’","_"),"“","_"),"”","_"),CHAR(9),"_"),CHAR(160),"_")) | T9: =IF(S9="","",SUBSTITUTE(SUBSTITUTE(SUBSTITUTE(SUBSTITUTE(SUBSTITUTE(SUBSTITUTE(SUBSTITUTE(SUBSTITUTE(S9,"__","_"),"__","_"),"__","_"),"__","_"),"__","_"),"__","_"),"__","_"),"__","_")) | U9: =IF(OR(T9="",T9="_"),"",IF(LEFT(T9,1)="_",IF(RIGHT(T9,1)="_",MID(T9,2,LEN(T9)-2),RIGHT(T9,LEN(T9)-1)),IF(RIGHT(T9,1)="_",LEFT(T9,LEN(T9)-1),T9)))
A10: stock_level | B10: UK active subscribers | C10: weekly | D10: exogenous_forecastable_control | G10: =IF(R10<>"",R10,"")&IF(U10<>"",IF(R10<>"","_"&U10,U10),"") | H10: =IF(TRIM(F10)<>"",TRIM(F10),G10) | I10: =IF(OR(A10="",B10="",C10="",D10=""),"Missing required field — fill in variable_class, the concept name, native_frequency, and role.",IF(G10="","Missing required field — variable_class and the concept name must combine into an ID.",IF(COUNTIF($H$8:$H$32,H10)>1,"Duplicate variable ID — two rows currently build the same variable_id; distinguish the actual variable, not its source frequency.",IF(AND(E10<>"",E10<>H10),"Existing variable_id differs from the built ID — review before using.","Ready")))) | P10: =IF(OR(LOWER(TRIM(A10))="",LOWER(TRIM(A10))="nan",LOWER(TRIM(A10))="none",LOWER(TRIM(A10))="n/a"),"",SUBSTITUTE(SUBSTITUTE(SUBSTITUTE(SUBSTITUTE(SUBSTITUTE(SUBSTITUTE(SUBSTITUTE(SUBSTITUTE(SUBSTITUTE(SUBSTITUTE(SUBSTITUTE(SUBSTITUTE(SUBSTITUTE(SUBSTITUTE(SUBSTITUTE(SUBSTITUTE(SUBSTITUTE(SUBSTITUTE(SUBSTITUTE(SUBSTITUTE(SUBSTITUTE(SUBSTITUTE(SUBSTITUTE(SUBSTITUTE(SUBSTITUTE(SUBSTITUTE(SUBSTITUTE(SUBSTITUTE(SUBSTITUTE(SUBSTITUTE(SUBSTITUTE(SUBSTITUTE(SUBSTITUTE(SUBSTITUTE(SUBSTITUTE(SUBSTITUTE(SUBSTITUTE(SUBSTITUTE(LOWER(TRIM(A10))," ","_"),"!","_"),"#","_"),"$","_"),"%","_"),"&","_"),"'","_"),"(","_"),")","_"),"*","_"),"+","_"),",","_"),"-","_"),".","_"),"/","_"),":","_"),";","_"),"<","_"),"=","_"),">","_"),"?","_"),"@","_"),"[","_"),"\","_"),"]","_"),"^","_"),"`","_"),"{","_"),"|","_"),"}","_"),"~","_"),"–","_"),"—","_"),"’","_"),"“","_"),"”","_"),CHAR(9),"_"),CHAR(160),"_")) | Q10: =IF(P10="","",SUBSTITUTE(SUBSTITUTE(SUBSTITUTE(SUBSTITUTE(SUBSTITUTE(SUBSTITUTE(SUBSTITUTE(SUBSTITUTE(P10,"__","_"),"__","_"),"__","_"),"__","_"),"__","_"),"__","_"),"__","_"),"__","_")) | R10: =IF(OR(Q10="",Q10="_"),"",IF(LEFT(Q10,1)="_",IF(RIGHT(Q10,1)="_",MID(Q10,2,LEN(Q10)-2),RIGHT(Q10,LEN(Q10)-1)),IF(RIGHT(Q10,1)="_",LEFT(Q10,LEN(Q10)-1),Q10))) | S10: =IF(OR(LOWER(TRIM(B10))="",LOWER(TRIM(B10))="nan",LOWER(TRIM(B10))="none",LOWER(TRIM(B10))="n/a"),"",SUBSTITUTE(SUBSTITUTE(SUBSTITUTE(SUBSTITUTE(SUBSTITUTE(SUBSTITUTE(SUBSTITUTE(SUBSTITUTE(SUBSTITUTE(SUBSTITUTE(SUBSTITUTE(SUBSTITUTE(SUBSTITUTE(SUBSTITUTE(SUBSTITUTE(SUBSTITUTE(SUBSTITUTE(SUBSTITUTE(SUBSTITUTE(SUBSTITUTE(SUBSTITUTE(SUBSTITUTE(SUBSTITUTE(SUBSTITUTE(SUBSTITUTE(SUBSTITUTE(SUBSTITUTE(SUBSTITUTE(SUBSTITUTE(SUBSTITUTE(SUBSTITUTE(SUBSTITUTE(SUBSTITUTE(SUBSTITUTE(SUBSTITUTE(SUBSTITUTE(SUBSTITUTE(SUBSTITUTE(LOWER(TRIM(B10))," ","_"),"!","_"),"#","_"),"$","_"),"%","_"),"&","_"),"'","_"),"(","_"),")","_"),"*","_"),"+","_"),",","_"),"-","_"),".","_"),"/","_"),":","_"),";","_"),"<","_"),"=","_"),">","_"),"?","_"),"@","_"),"[","_"),"\","_"),"]","_"),"^","_"),"`","_"),"{","_"),"|","_"),"}","_"),"~","_"),"–","_"),"—","_"),"’","_"),"“","_"),"”","_"),CHAR(9),"_"),CHAR(160),"_")) | T10: =IF(S10="","",SUBSTITUTE(SUBSTITUTE(SUBSTITUTE(SUBSTITUTE(SUBSTITUTE(SUBSTITUTE(SUBSTITUTE(SUBSTITUTE(S10,"__","_"),"__","_"),"__","_"),"__","_"),"__","_"),"__","_"),"__","_"),"__","_")) | U10: =IF(OR(T10="",T10="_"),"",IF(LEFT(T10,1)="_",IF(RIGHT(T10,1)="_",MID(T10,2,LEN(T10)-2),RIGHT(T10,LEN(T10)-1)),IF(RIGHT(T10,1)="_",LEFT(T10,LEN(T10)-1),T10)))
A11: survey_measurement | B11: Brand consideration | C11: monthly | D11: exogenous_forecastable_control | G11: =IF(R11<>"",R11,"")&IF(U11<>"",IF(R11<>"","_"&U11,U11),"") | H11: =IF(TRIM(F11)<>"",TRIM(F11),G11) | I11: =IF(OR(A11="",B11="",C11="",D11=""),"Missing required field — fill in variable_class, the concept name, native_frequency, and role.",IF(G11="","Missing required field — variable_class and the concept name must combine into an ID.",IF(COUNTIF($H$8:$H$32,H11)>1,"Duplicate variable ID — two rows currently build the same variable_id; distinguish the actual variable, not its source frequency.",IF(AND(E11<>"",E11<>H11),"Existing variable_id differs from the built ID — review before using.","Ready")))) | P11: =IF(OR(LOWER(TRIM(A11))="",LOWER(TRIM(A11))="nan",LOWER(TRIM(A11))="none",LOWER(TRIM(A11))="n/a"),"",SUBSTITUTE(SUBSTITUTE(SUBSTITUTE(SUBSTITUTE(SUBSTITUTE(SUBSTITUTE(SUBSTITUTE(SUBSTITUTE(SUBSTITUTE(SUBSTITUTE(SUBSTITUTE(SUBSTITUTE(SUBSTITUTE(SUBSTITUTE(SUBSTITUTE(SUBSTITUTE(SUBSTITUTE(SUBSTITUTE(SUBSTITUTE(SUBSTITUTE(SUBSTITUTE(SUBSTITUTE(SUBSTITUTE(SUBSTITUTE(SUBSTITUTE(SUBSTITUTE(SUBSTITUTE(SUBSTITUTE(SUBSTITUTE(SUBSTITUTE(SUBSTITUTE(SUBSTITUTE(SUBSTITUTE(SUBSTITUTE(SUBSTITUTE(SUBSTITUTE(SUBSTITUTE(SUBSTITUTE(LOWER(TRIM(A11))," ","_"),"!","_"),"#","_"),"$","_"),"%","_"),"&","_"),"'","_"),"(","_"),")","_"),"*","_"),"+","_"),",","_"),"-","_"),".","_"),"/","_"),":","_"),";","_"),"<","_"),"=","_"),">","_"),"?","_"),"@","_"),"[","_"),"\","_"),"]","_"),"^","_"),"`","_"),"{","_"),"|","_"),"}","_"),"~","_"),"–","_"),"—","_"),"’","_"),"“","_"),"”","_"),CHAR(9),"_"),CHAR(160),"_")) | Q11: =IF(P11="","",SUBSTITUTE(SUBSTITUTE(SUBSTITUTE(SUBSTITUTE(SUBSTITUTE(SUBSTITUTE(SUBSTITUTE(SUBSTITUTE(P11,"__","_"),"__","_"),"__","_"),"__","_"),"__","_"),"__","_"),"__","_"),"__","_")) | R11: =IF(OR(Q11="",Q11="_"),"",IF(LEFT(Q11,1)="_",IF(RIGHT(Q11,1)="_",MID(Q11,2,LEN(Q11)-2),RIGHT(Q11,LEN(Q11)-1)),IF(RIGHT(Q11,1)="_",LEFT(Q11,LEN(Q11)-1),Q11))) | S11: =IF(OR(LOWER(TRIM(B11))="",LOWER(TRIM(B11))="nan",LOWER(TRIM(B11))="none",LOWER(TRIM(B11))="n/a"),"",SUBSTITUTE(SUBSTITUTE(SUBSTITUTE(SUBSTITUTE(SUBSTITUTE(SUBSTITUTE(SUBSTITUTE(SUBSTITUTE(SUBSTITUTE(SUBSTITUTE(SUBSTITUTE(SUBSTITUTE(SUBSTITUTE(SUBSTITUTE(SUBSTITUTE(SUBSTITUTE(SUBSTITUTE(SUBSTITUTE(SUBSTITUTE(SUBSTITUTE(SUBSTITUTE(SUBSTITUTE(SUBSTITUTE(SUBSTITUTE(SUBSTITUTE(SUBSTITUTE(SUBSTITUTE(SUBSTITUTE(SUBSTITUTE(SUBSTITUTE(SUBSTITUTE(SUBSTITUTE(SUBSTITUTE(SUBSTITUTE(SUBSTITUTE(SUBSTITUTE(SUBSTITUTE(SUBSTITUTE(LOWER(TRIM(B11))," ","_"),"!","_"),"#","_"),"$","_"),"%","_"),"&","_"),"'","_"),"(","_"),")","_"),"*","_"),"+","_"),",","_"),"-","_"),".","_"),"/","_"),":","_"),";","_"),"<","_"),"=","_"),">","_"),"?","_"),"@","_"),"[","_"),"\","_"),"]","_"),"^","_"),"`","_"),"{","_"),"|","_"),"}","_"),"~","_"),"–","_"),"—","_"),"’","_"),"“","_"),"”","_"),CHAR(9),"_"),CHAR(160),"_")) | T11: =IF(S11="","",SUBSTITUTE(SUBSTITUTE(SUBSTITUTE(SUBSTITUTE(SUBSTITUTE(SUBSTITUTE(SUBSTITUTE(SUBSTITUTE(S11,"__","_"),"__","_"),"__","_"),"__","_"),"__","_"),"__","_"),"__","_"),"__","_")) | U11: =IF(OR(T11="",T11="_"),"",IF(LEFT(T11,1)="_",IF(RIGHT(T11,1)="_",MID(T11,2,LEN(T11)-2),RIGHT(T11,LEN(T11)-1)),IF(RIGHT(T11,1)="_",LEFT(T11,LEN(T11)-1),T11)))
A12: event_flag | B12: Black Friday | C12: weekly | D12: exogenous_forecastable_control | G12: =IF(R12<>"",R12,"")&IF(U12<>"",IF(R12<>"","_"&U12,U12),"") | H12: =IF(TRIM(F12)<>"",TRIM(F12),G12) | I12: =IF(OR(A12="",B12="",C12="",D12=""),"Missing required field — fill in variable_class, the concept name, native_frequency, and role.",IF(G12="","Missing required field — variable_class and the concept name must combine into an ID.",IF(COUNTIF($H$8:$H$32,H12)>1,"Duplicate variable ID — two rows currently build the same variable_id; distinguish the actual variable, not its source frequency.",IF(AND(E12<>"",E12<>H12),"Existing variable_id differs from the built ID — review before using.","Ready")))) | P12: =IF(OR(LOWER(TRIM(A12))="",LOWER(TRIM(A12))="nan",LOWER(TRIM(A12))="none",LOWER(TRIM(A12))="n/a"),"",SUBSTITUTE(SUBSTITUTE(SUBSTITUTE(SUBSTITUTE(SUBSTITUTE(SUBSTITUTE(SUBSTITUTE(SUBSTITUTE(SUBSTITUTE(SUBSTITUTE(SUBSTITUTE(SUBSTITUTE(SUBSTITUTE(SUBSTITUTE(SUBSTITUTE(SUBSTITUTE(SUBSTITUTE(SUBSTITUTE(SUBSTITUTE(SUBSTITUTE(SUBSTITUTE(SUBSTITUTE(SUBSTITUTE(SUBSTITUTE(SUBSTITUTE(SUBSTITUTE(SUBSTITUTE(SUBSTITUTE(SUBSTITUTE(SUBSTITUTE(SUBSTITUTE(SUBSTITUTE(SUBSTITUTE(SUBSTITUTE(SUBSTITUTE(SUBSTITUTE(SUBSTITUTE(SUBSTITUTE(LOWER(TRIM(A12))," ","_"),"!","_"),"#","_"),"$","_"),"%","_"),"&","_"),"'","_"),"(","_"),")","_"),"*","_"),"+","_"),",","_"),"-","_"),".","_"),"/","_"),":","_"),";","_"),"<","_"),"=","_"),">","_"),"?","_"),"@","_"),"[","_"),"\","_"),"]","_"),"^","_"),"`","_"),"{","_"),"|","_"),"}","_"),"~","_"),"–","_"),"—","_"),"’","_"),"“","_"),"”","_"),CHAR(9),"_"),CHAR(160),"_")) | Q12: =IF(P12="","",SUBSTITUTE(SUBSTITUTE(SUBSTITUTE(SUBSTITUTE(SUBSTITUTE(SUBSTITUTE(SUBSTITUTE(SUBSTITUTE(P12,"__","_"),"__","_"),"__","_"),"__","_"),"__","_"),"__","_"),"__","_"),"__","_")) | R12: =IF(OR(Q12="",Q12="_"),"",IF(LEFT(Q12,1)="_",IF(RIGHT(Q12,1)="_",MID(Q12,2,LEN(Q12)-2),RIGHT(Q12,LEN(Q12)-1)),IF(RIGHT(Q12,1)="_",LEFT(Q12,LEN(Q12)-1),Q12))) | S12: =IF(OR(LOWER(TRIM(B12))="",LOWER(TRIM(B12))="nan",LOWER(TRIM(B12))="none",LOWER(TRIM(B12))="n/a"),"",SUBSTITUTE(SUBSTITUTE(SUBSTITUTE(SUBSTITUTE(SUBSTITUTE(SUBSTITUTE(SUBSTITUTE(SUBSTITUTE(SUBSTITUTE(SUBSTITUTE(SUBSTITUTE(SUBSTITUTE(SUBSTITUTE(SUBSTITUTE(SUBSTITUTE(SUBSTITUTE(SUBSTITUTE(SUBSTITUTE(SUBSTITUTE(SUBSTITUTE(SUBSTITUTE(SUBSTITUTE(SUBSTITUTE(SUBSTITUTE(SUBSTITUTE(SUBSTITUTE(SUBSTITUTE(SUBSTITUTE(SUBSTITUTE(SUBSTITUTE(SUBSTITUTE(SUBSTITUTE(SUBSTITUTE(SUBSTITUTE(SUBSTITUTE(SUBSTITUTE(SUBSTITUTE(SUBSTITUTE(LOWER(TRIM(B12))," ","_"),"!","_"),"#","_"),"$","_"),"%","_"),"&","_"),"'","_"),"(","_"),")","_"),"*","_"),"+","_"),",","_"),"-","_"),".","_"),"/","_"),":","_"),";","_"),"<","_"),"=","_"),">","_"),"?","_"),"@","_"),"[","_"),"\","_"),"]","_"),"^","_"),"`","_"),"{","_"),"|","_"),"}","_"),"~","_"),"–","_"),"—","_"),"’","_"),"“","_"),"”","_"),CHAR(9),"_"),CHAR(160),"_")) | T12: =IF(S12="","",SUBSTITUTE(SUBSTITUTE(SUBSTITUTE(SUBSTITUTE(SUBSTITUTE(SUBSTITUTE(SUBSTITUTE(SUBSTITUTE(S12,"__","_"),"__","_"),"__","_"),"__","_"),"__","_"),"__","_"),"__","_"),"__","_")) | U12: =IF(OR(T12="",T12="_"),"",IF(LEFT(T12,1)="_",IF(RIGHT(T12,1)="_",MID(T12,2,LEN(T12)-2),RIGHT(T12,LEN(T12)-1)),IF(RIGHT(T12,1)="_",LEFT(T12,LEN(T12)-1),T12)))
G13: =IF(R13<>"",R13,"")&IF(U13<>"",IF(R13<>"","_"&U13,U13),"") | H13: =IF(TRIM(F13)<>"",TRIM(F13),G13) | I13: =IF(OR(A13="",B13="",C13="",D13=""),"Missing required field — fill in variable_class, the concept name, native_frequency, and role.",IF(G13="","Missing required field — variable_class and the concept name must combine into an ID.",IF(COUNTIF($H$8:$H$32,H13)>1,"Duplicate variable ID — two rows currently build the same variable_id; distinguish the actual variable, not its source frequency.",IF(AND(E13<>"",E13<>H13),"Existing variable_id differs from the built ID — review before using.","Ready")))) | P13: =IF(OR(LOWER(TRIM(A13))="",LOWER(TRIM(A13))="nan",LOWER(TRIM(A13))="none",LOWER(TRIM(A13))="n/a"),"",SUBSTITUTE(SUBSTITUTE(SUBSTITUTE(SUBSTITUTE(SUBSTITUTE(SUBSTITUTE(SUBSTITUTE(SUBSTITUTE(SUBSTITUTE(SUBSTITUTE(SUBSTITUTE(SUBSTITUTE(SUBSTITUTE(SUBSTITUTE(SUBSTITUTE(SUBSTITUTE(SUBSTITUTE(SUBSTITUTE(SUBSTITUTE(SUBSTITUTE(SUBSTITUTE(SUBSTITUTE(SUBSTITUTE(SUBSTITUTE(SUBSTITUTE(SUBSTITUTE(SUBSTITUTE(SUBSTITUTE(SUBSTITUTE(SUBSTITUTE(SUBSTITUTE(SUBSTITUTE(SUBSTITUTE(SUBSTITUTE(SUBSTITUTE(SUBSTITUTE(SUBSTITUTE(SUBSTITUTE(LOWER(TRIM(A13))," ","_"),"!","_"),"#","_"),"$","_"),"%","_"),"&","_"),"'","_"),"(","_"),")","_"),"*","_"),"+","_"),",","_"),"-","_"),".","_"),"/","_"),":","_"),";","_"),"<","_"),"=","_"),">","_"),"?","_"),"@","_"),"[","_"),"\","_"),"]","_"),"^","_"),"`","_"),"{","_"),"|","_"),"}","_"),"~","_"),"–","_"),"—","_"),"’","_"),"“","_"),"”","_"),CHAR(9),"_"),CHAR(160),"_")) | Q13: =IF(P13="","",SUBSTITUTE(SUBSTITUTE(SUBSTITUTE(SUBSTITUTE(SUBSTITUTE(SUBSTITUTE(SUBSTITUTE(SUBSTITUTE(P13,"__","_"),"__","_"),"__","_"),"__","_"),"__","_"),"__","_"),"__","_"),"__","_")) | R13: =IF(OR(Q13="",Q13="_"),"",IF(LEFT(Q13,1)="_",IF(RIGHT(Q13,1)="_",MID(Q13,2,LEN(Q13)-2),RIGHT(Q13,LEN(Q13)-1)),IF(RIGHT(Q13,1)="_",LEFT(Q13,LEN(Q13)-1),Q13))) | S13: =IF(OR(LOWER(TRIM(B13))="",LOWER(TRIM(B13))="nan",LOWER(TRIM(B13))="none",LOWER(TRIM(B13))="n/a"),"",SUBSTITUTE(SUBSTITUTE(SUBSTITUTE(SUBSTITUTE(SUBSTITUTE(SUBSTITUTE(SUBSTITUTE(SUBSTITUTE(SUBSTITUTE(SUBSTITUTE(SUBSTITUTE(SUBSTITUTE(SUBSTITUTE(SUBSTITUTE(SUBSTITUTE(SUBSTITUTE(SUBSTITUTE(SUBSTITUTE(SUBSTITUTE(SUBSTITUTE(SUBSTITUTE(SUBSTITUTE(SUBSTITUTE(SUBSTITUTE(SUBSTITUTE(SUBSTITUTE(SUBSTITUTE(SUBSTITUTE(SUBSTITUTE(SUBSTITUTE(SUBSTITUTE(SUBSTITUTE(SUBSTITUTE(SUBSTITUTE(SUBSTITUTE(SUBSTITUTE(SUBSTITUTE(SUBSTITUTE(LOWER(TRIM(B13))," ","_"),"!","_"),"#","_"),"$","_"),"%","_"),"&","_"),"'","_"),"(","_"),")","_"),"*","_"),"+","_"),",","_"),"-","_"),".","_"),"/","_"),":","_"),";","_"),"<","_"),"=","_"),">","_"),"?","_"),"@","_"),"[","_"),"\","_"),"]","_"),"^","_"),"`","_"),"{","_"),"|","_"),"}","_"),"~","_"),"–","_"),"—","_"),"’","_"),"“","_"),"”","_"),CHAR(9),"_"),CHAR(160),"_")) | T13: =IF(S13="","",SUBSTITUTE(SUBSTITUTE(SUBSTITUTE(SUBSTITUTE(SUBSTITUTE(SUBSTITUTE(SUBSTITUTE(SUBSTITUTE(S13,"__","_"),"__","_"),"__","_"),"__","_"),"__","_"),"__","_"),"__","_"),"__","_")) | U13: =IF(OR(T13="",T13="_"),"",IF(LEFT(T13,1)="_",IF(RIGHT(T13,1)="_",MID(T13,2,LEN(T13)-2),RIGHT(T13,LEN(T13)-1)),IF(RIGHT(T13,1)="_",LEFT(T13,LEN(T13)-1),T13)))
G14: =IF(R14<>"",R14,"")&IF(U14<>"",IF(R14<>"","_"&U14,U14),"") | H14: =IF(TRIM(F14)<>"",TRIM(F14),G14) | I14: =IF(OR(A14="",B14="",C14="",D14=""),"Missing required field — fill in variable_class, the concept name, native_frequency, and role.",IF(G14="","Missing required field — variable_class and the concept name must combine into an ID.",IF(COUNTIF($H$8:$H$32,H14)>1,"Duplicate variable ID — two rows currently build the same variable_id; distinguish the actual variable, not its source frequency.",IF(AND(E14<>"",E14<>H14),"Existing variable_id differs from the built ID — review before using.","Ready")))) | P14: =IF(OR(LOWER(TRIM(A14))="",LOWER(TRIM(A14))="nan",LOWER(TRIM(A14))="none",LOWER(TRIM(A14))="n/a"),"",SUBSTITUTE(SUBSTITUTE(SUBSTITUTE(SUBSTITUTE(SUBSTITUTE(SUBSTITUTE(SUBSTITUTE(SUBSTITUTE(SUBSTITUTE(SUBSTITUTE(SUBSTITUTE(SUBSTITUTE(SUBSTITUTE(SUBSTITUTE(SUBSTITUTE(SUBSTITUTE(SUBSTITUTE(SUBSTITUTE(SUBSTITUTE(SUBSTITUTE(SUBSTITUTE(SUBSTITUTE(SUBSTITUTE(SUBSTITUTE(SUBSTITUTE(SUBSTITUTE(SUBSTITUTE(SUBSTITUTE(SUBSTITUTE(SUBSTITUTE(SUBSTITUTE(SUBSTITUTE(SUBSTITUTE(SUBSTITUTE(SUBSTITUTE(SUBSTITUTE(SUBSTITUTE(SUBSTITUTE(LOWER(TRIM(A14))," ","_"),"!","_"),"#","_"),"$","_"),"%","_"),"&","_"),"'","_"),"(","_"),")","_"),"*","_"),"+","_"),",","_"),"-","_"),".","_"),"/","_"),":","_"),";","_"),"<","_"),"=","_"),">","_"),"?","_"),"@","_"),"[","_"),"\","_"),"]","_"),"^","_"),"`","_"),"{","_"),"|","_"),"}","_"),"~","_"),"–","_"),"—","_"),"’","_"),"“","_"),"”","_"),CHAR(9),"_"),CHAR(160),"_")) | Q14: =IF(P14="","",SUBSTITUTE(SUBSTITUTE(SUBSTITUTE(SUBSTITUTE(SUBSTITUTE(SUBSTITUTE(SUBSTITUTE(SUBSTITUTE(P14,"__","_"),"__","_"),"__","_"),"__","_"),"__","_"),"__","_"),"__","_"),"__","_")) | R14: =IF(OR(Q14="",Q14="_"),"",IF(LEFT(Q14,1)="_",IF(RIGHT(Q14,1)="_",MID(Q14,2,LEN(Q14)-2),RIGHT(Q14,LEN(Q14)-1)),IF(RIGHT(Q14,1)="_",LEFT(Q14,LEN(Q14)-1),Q14))) | S14: =IF(OR(LOWER(TRIM(B14))="",LOWER(TRIM(B14))="nan",LOWER(TRIM(B14))="none",LOWER(TRIM(B14))="n/a"),"",SUBSTITUTE(SUBSTITUTE(SUBSTITUTE(SUBSTITUTE(SUBSTITUTE(SUBSTITUTE(SUBSTITUTE(SUBSTITUTE(SUBSTITUTE(SUBSTITUTE(SUBSTITUTE(SUBSTITUTE(SUBSTITUTE(SUBSTITUTE(SUBSTITUTE(SUBSTITUTE(SUBSTITUTE(SUBSTITUTE(SUBSTITUTE(SUBSTITUTE(SUBSTITUTE(SUBSTITUTE(SUBSTITUTE(SUBSTITUTE(SUBSTITUTE(SUBSTITUTE(SUBSTITUTE(SUBSTITUTE(SUBSTITUTE(SUBSTITUTE(SUBSTITUTE(SUBSTITUTE(SUBSTITUTE(SUBSTITUTE(SUBSTITUTE(SUBSTITUTE(SUBSTITUTE(SUBSTITUTE(LOWER(TRIM(B14))," ","_"),"!","_"),"#","_"),"$","_"),"%","_"),"&","_"),"'","_"),"(","_"),")","_"),"*","_"),"+","_"),",","_"),"-","_"),".","_"),"/","_"),":","_"),";","_"),"<","_"),"=","_"),">","_"),"?","_"),"@","_"),"[","_"),"\","_"),"]","_"),"^","_"),"`","_"),"{","_"),"|","_"),"}","_"),"~","_"),"–","_"),"—","_"),"’","_"),"“","_"),"”","_"),CHAR(9),"_"),CHAR(160),"_")) | T14: =IF(S14="","",SUBSTITUTE(SUBSTITUTE(SUBSTITUTE(SUBSTITUTE(SUBSTITUTE(SUBSTITUTE(SUBSTITUTE(SUBSTITUTE(S14,"__","_"),"__","_"),"__","_"),"__","_"),"__","_"),"__","_"),"__","_"),"__","_")) | U14: =IF(OR(T14="",T14="_"),"",IF(LEFT(T14,1)="_",IF(RIGHT(T14,1)="_",MID(T14,2,LEN(T14)-2),RIGHT(T14,LEN(T14)-1)),IF(RIGHT(T14,1)="_",LEFT(T14,LEN(T14)-1),T14)))
G15: =IF(R15<>"",R15,"")&IF(U15<>"",IF(R15<>"","_"&U15,U15),"") | H15: =IF(TRIM(F15)<>"",TRIM(F15),G15) | I15: =IF(OR(A15="",B15="",C15="",D15=""),"Missing required field — fill in variable_class, the concept name, native_frequency, and role.",IF(G15="","Missing required field — variable_class and the concept name must combine into an ID.",IF(COUNTIF($H$8:$H$32,H15)>1,"Duplicate variable ID — two rows currently build the same variable_id; distinguish the actual variable, not its source frequency.",IF(AND(E15<>"",E15<>H15),"Existing variable_id differs from the built ID — review before using.","Ready")))) | P15: =IF(OR(LOWER(TRIM(A15))="",LOWER(TRIM(A15))="nan",LOWER(TRIM(A15))="none",LOWER(TRIM(A15))="n/a"),"",SUBSTITUTE(SUBSTITUTE(SUBSTITUTE(SUBSTITUTE(SUBSTITUTE(SUBSTITUTE(SUBSTITUTE(SUBSTITUTE(SUBSTITUTE(SUBSTITUTE(SUBSTITUTE(SUBSTITUTE(SUBSTITUTE(SUBSTITUTE(SUBSTITUTE(SUBSTITUTE(SUBSTITUTE(SUBSTITUTE(SUBSTITUTE(SUBSTITUTE(SUBSTITUTE(SUBSTITUTE(SUBSTITUTE(SUBSTITUTE(SUBSTITUTE(SUBSTITUTE(SUBSTITUTE(SUBSTITUTE(SUBSTITUTE(SUBSTITUTE(SUBSTITUTE(SUBSTITUTE(SUBSTITUTE(SUBSTITUTE(SUBSTITUTE(SUBSTITUTE(SUBSTITUTE(SUBSTITUTE(LOWER(TRIM(A15))," ","_"),"!","_"),"#","_"),"$","_"),"%","_"),"&","_"),"'","_"),"(","_"),")","_"),"*","_"),"+","_"),",","_"),"-","_"),".","_"),"/","_"),":","_"),";","_"),"<","_"),"=","_"),">","_"),"?","_"),"@","_"),"[","_"),"\","_"),"]","_"),"^","_"),"`","_"),"{","_"),"|","_"),"}","_"),"~","_"),"–","_"),"—","_"),"’","_"),"“","_"),"”","_"),CHAR(9),"_"),CHAR(160),"_")) | Q15: =IF(P15="","",SUBSTITUTE(SUBSTITUTE(SUBSTITUTE(SUBSTITUTE(SUBSTITUTE(SUBSTITUTE(SUBSTITUTE(SUBSTITUTE(P15,"__","_"),"__","_"),"__","_"),"__","_"),"__","_"),"__","_"),"__","_"),"__","_")) | R15: =IF(OR(Q15="",Q15="_"),"",IF(LEFT(Q15,1)="_",IF(RIGHT(Q15,1)="_",MID(Q15,2,LEN(Q15)-2),RIGHT(Q15,LEN(Q15)-1)),IF(RIGHT(Q15,1)="_",LEFT(Q15,LEN(Q15)-1),Q15))) | S15: =IF(OR(LOWER(TRIM(B15))="",LOWER(TRIM(B15))="nan",LOWER(TRIM(B15))="none",LOWER(TRIM(B15))="n/a"),"",SUBSTITUTE(SUBSTITUTE(SUBSTITUTE(SUBSTITUTE(SUBSTITUTE(SUBSTITUTE(SUBSTITUTE(SUBSTITUTE(SUBSTITUTE(SUBSTITUTE(SUBSTITUTE(SUBSTITUTE(SUBSTITUTE(SUBSTITUTE(SUBSTITUTE(SUBSTITUTE(SUBSTITUTE(SUBSTITUTE(SUBSTITUTE(SUBSTITUTE(SUBSTITUTE(SUBSTITUTE(SUBSTITUTE(SUBSTITUTE(SUBSTITUTE(SUBSTITUTE(SUBSTITUTE(SUBSTITUTE(SUBSTITUTE(SUBSTITUTE(SUBSTITUTE(SUBSTITUTE(SUBSTITUTE(SUBSTITUTE(SUBSTITUTE(SUBSTITUTE(SUBSTITUTE(SUBSTITUTE(LOWER(TRIM(B15))," ","_"),"!","_"),"#","_"),"$","_"),"%","_"),"&","_"),"'","_"),"(","_"),")","_"),"*","_"),"+","_"),",","_"),"-","_"),".","_"),"/","_"),":","_"),";","_"),"<","_"),"=","_"),">","_"),"?","_"),"@","_"),"[","_"),"\","_"),"]","_"),"^","_"),"`","_"),"{","_"),"|","_"),"}","_"),"~","_"),"–","_"),"—","_"),"’","_"),"“","_"),"”","_"),CHAR(9),"_"),CHAR(160),"_")) | T15: =IF(S15="","",SUBSTITUTE(SUBSTITUTE(SUBSTITUTE(SUBSTITUTE(SUBSTITUTE(SUBSTITUTE(SUBSTITUTE(SUBSTITUTE(S15,"__","_"),"__","_"),"__","_"),"__","_"),"__","_"),"__","_"),"__","_"),"__","_")) | U15: =IF(OR(T15="",T15="_"),"",IF(LEFT(T15,1)="_",IF(RIGHT(T15,1)="_",MID(T15,2,LEN(T15)-2),RIGHT(T15,LEN(T15)-1)),IF(RIGHT(T15,1)="_",LEFT(T15,LEN(T15)-1),T15)))
G16: =IF(R16<>"",R16,"")&IF(U16<>"",IF(R16<>"","_"&U16,U16),"") | H16: =IF(TRIM(F16)<>"",TRIM(F16),G16) | I16: =IF(OR(A16="",B16="",C16="",D16=""),"Missing required field — fill in variable_class, the concept name, native_frequency, and role.",IF(G16="","Missing required field — variable_class and the concept name must combine into an ID.",IF(COUNTIF($H$8:$H$32,H16)>1,"Duplicate variable ID — two rows currently build the same variable_id; distinguish the actual variable, not its source frequency.",IF(AND(E16<>"",E16<>H16),"Existing variable_id differs from the built ID — review before using.","Ready")))) | P16: =IF(OR(LOWER(TRIM(A16))="",LOWER(TRIM(A16))="nan",LOWER(TRIM(A16))="none",LOWER(TRIM(A16))="n/a"),"",SUBSTITUTE(SUBSTITUTE(SUBSTITUTE(SUBSTITUTE(SUBSTITUTE(SUBSTITUTE(SUBSTITUTE(SUBSTITUTE(SUBSTITUTE(SUBSTITUTE(SUBSTITUTE(SUBSTITUTE(SUBSTITUTE(SUBSTITUTE(SUBSTITUTE(SUBSTITUTE(SUBSTITUTE(SUBSTITUTE(SUBSTITUTE(SUBSTITUTE(SUBSTITUTE(SUBSTITUTE(SUBSTITUTE(SUBSTITUTE(SUBSTITUTE(SUBSTITUTE(SUBSTITUTE(SUBSTITUTE(SUBSTITUTE(SUBSTITUTE(SUBSTITUTE(SUBSTITUTE(SUBSTITUTE(SUBSTITUTE(SUBSTITUTE(SUBSTITUTE(SUBSTITUTE(SUBSTITUTE(LOWER(TRIM(A16))," ","_"),"!","_"),"#","_"),"$","_"),"%","_"),"&","_"),"'","_"),"(","_"),")","_"),"*","_"),"+","_"),",","_"),"-","_"),".","_"),"/","_"),":","_"),";","_"),"<","_"),"=","_"),">","_"),"?","_"),"@","_"),"[","_"),"\","_"),"]","_"),"^","_"),"`","_"),"{","_"),"|","_"),"}","_"),"~","_"),"–","_"),"—","_"),"’","_"),"“","_"),"”","_"),CHAR(9),"_"),CHAR(160),"_")) | Q16: =IF(P16="","",SUBSTITUTE(SUBSTITUTE(SUBSTITUTE(SUBSTITUTE(SUBSTITUTE(SUBSTITUTE(SUBSTITUTE(SUBSTITUTE(P16,"__","_"),"__","_"),"__","_"),"__","_"),"__","_"),"__","_"),"__","_"),"__","_")) | R16: =IF(OR(Q16="",Q16="_"),"",IF(LEFT(Q16,1)="_",IF(RIGHT(Q16,1)="_",MID(Q16,2,LEN(Q16)-2),RIGHT(Q16,LEN(Q16)-1)),IF(RIGHT(Q16,1)="_",LEFT(Q16,LEN(Q16)-1),Q16))) | S16: =IF(OR(LOWER(TRIM(B16))="",LOWER(TRIM(B16))="nan",LOWER(TRIM(B16))="none",LOWER(TRIM(B16))="n/a"),"",SUBSTITUTE(SUBSTITUTE(SUBSTITUTE(SUBSTITUTE(SUBSTITUTE(SUBSTITUTE(SUBSTITUTE(SUBSTITUTE(SUBSTITUTE(SUBSTITUTE(SUBSTITUTE(SUBSTITUTE(SUBSTITUTE(SUBSTITUTE(SUBSTITUTE(SUBSTITUTE(SUBSTITUTE(SUBSTITUTE(SUBSTITUTE(SUBSTITUTE(SUBSTITUTE(SUBSTITUTE(SUBSTITUTE(SUBSTITUTE(SUBSTITUTE(SUBSTITUTE(SUBSTITUTE(SUBSTITUTE(SUBSTITUTE(SUBSTITUTE(SUBSTITUTE(SUBSTITUTE(SUBSTITUTE(SUBSTITUTE(SUBSTITUTE(SUBSTITUTE(SUBSTITUTE(SUBSTITUTE(LOWER(TRIM(B16))," ","_"),"!","_"),"#","_"),"$","_"),"%","_"),"&","_"),"'","_"),"(","_"),")","_"),"*","_"),"+","_"),",","_"),"-","_"),".","_"),"/","_"),":","_"),";","_"),"<","_"),"=","_"),">","_"),"?","_"),"@","_"),"[","_"),"\","_"),"]","_"),"^","_"),"`","_"),"{","_"),"|","_"),"}","_"),"~","_"),"–","_"),"—","_"),"’","_"),"“","_"),"”","_"),CHAR(9),"_"),CHAR(160),"_")) | T16: =IF(S16="","",SUBSTITUTE(SUBSTITUTE(SUBSTITUTE(SUBSTITUTE(SUBSTITUTE(SUBSTITUTE(SUBSTITUTE(SUBSTITUTE(S16,"__","_"),"__","_"),"__","_"),"__","_"),"__","_"),"__","_"),"__","_"),"__","_")) | U16: =IF(OR(T16="",T16="_"),"",IF(LEFT(T16,1)="_",IF(RIGHT(T16,1)="_",MID(T16,2,LEN(T16)-2),RIGHT(T16,LEN(T16)-1)),IF(RIGHT(T16,1)="_",LEFT(T16,LEN(T16)-1),T16)))
G17: =IF(R17<>"",R17,"")&IF(U17<>"",IF(R17<>"","_"&U17,U17),"") | H17: =IF(TRIM(F17)<>"",TRIM(F17),G17) | I17: =IF(OR(A17="",B17="",C17="",D17=""),"Missing required field — fill in variable_class, the concept name, native_frequency, and role.",IF(G17="","Missing required field — variable_class and the concept name must combine into an ID.",IF(COUNTIF($H$8:$H$32,H17)>1,"Duplicate variable ID — two rows currently build the same variable_id; distinguish the actual variable, not its source frequency.",IF(AND(E17<>"",E17<>H17),"Existing variable_id differs from the built ID — review before using.","Ready")))) | P17: =IF(OR(LOWER(TRIM(A17))="",LOWER(TRIM(A17))="nan",LOWER(TRIM(A17))="none",LOWER(TRIM(A17))="n/a"),"",SUBSTITUTE(SUBSTITUTE(SUBSTITUTE(SUBSTITUTE(SUBSTITUTE(SUBSTITUTE(SUBSTITUTE(SUBSTITUTE(SUBSTITUTE(SUBSTITUTE(SUBSTITUTE(SUBSTITUTE(SUBSTITUTE(SUBSTITUTE(SUBSTITUTE(SUBSTITUTE(SUBSTITUTE(SUBSTITUTE(SUBSTITUTE(SUBSTITUTE(SUBSTITUTE(SUBSTITUTE(SUBSTITUTE(SUBSTITUTE(SUBSTITUTE(SUBSTITUTE(SUBSTITUTE(SUBSTITUTE(SUBSTITUTE(SUBSTITUTE(SUBSTITUTE(SUBSTITUTE(SUBSTITUTE(SUBSTITUTE(SUBSTITUTE(SUBSTITUTE(SUBSTITUTE(SUBSTITUTE(LOWER(TRIM(A17))," ","_"),"!","_"),"#","_"),"$","_"),"%","_"),"&","_"),"'","_"),"(","_"),")","_"),"*","_"),"+","_"),",","_"),"-","_"),".","_"),"/","_"),":","_"),";","_"),"<","_"),"=","_"),">","_"),"?","_"),"@","_"),"[","_"),"\","_"),"]","_"),"^","_"),"`","_"),"{","_"),"|","_"),"}","_"),"~","_"),"–","_"),"—","_"),"’","_"),"“","_"),"”","_"),CHAR(9),"_"),CHAR(160),"_")) | Q17: =IF(P17="","",SUBSTITUTE(SUBSTITUTE(SUBSTITUTE(SUBSTITUTE(SUBSTITUTE(SUBSTITUTE(SUBSTITUTE(SUBSTITUTE(P17,"__","_"),"__","_"),"__","_"),"__","_"),"__","_"),"__","_"),"__","_"),"__","_")) | R17: =IF(OR(Q17="",Q17="_"),"",IF(LEFT(Q17,1)="_",IF(RIGHT(Q17,1)="_",MID(Q17,2,LEN(Q17)-2),RIGHT(Q17,LEN(Q17)-1)),IF(RIGHT(Q17,1)="_",LEFT(Q17,LEN(Q17)-1),Q17))) | S17: =IF(OR(LOWER(TRIM(B17))="",LOWER(TRIM(B17))="nan",LOWER(TRIM(B17))="none",LOWER(TRIM(B17))="n/a"),"",SUBSTITUTE(SUBSTITUTE(SUBSTITUTE(SUBSTITUTE(SUBSTITUTE(SUBSTITUTE(SUBSTITUTE(SUBSTITUTE(SUBSTITUTE(SUBSTITUTE(SUBSTITUTE(SUBSTITUTE(SUBSTITUTE(SUBSTITUTE(SUBSTITUTE(SUBSTITUTE(SUBSTITUTE(SUBSTITUTE(SUBSTITUTE(SUBSTITUTE(SUBSTITUTE(SUBSTITUTE(SUBSTITUTE(SUBSTITUTE(SUBSTITUTE(SUBSTITUTE(SUBSTITUTE(SUBSTITUTE(SUBSTITUTE(SUBSTITUTE(SUBSTITUTE(SUBSTITUTE(SUBSTITUTE(SUBSTITUTE(SUBSTITUTE(SUBSTITUTE(SUBSTITUTE(SUBSTITUTE(LOWER(TRIM(B17))," ","_"),"!","_"),"#","_"),"$","_"),"%","_"),"&","_"),"'","_"),"(","_"),")","_"),"*","_"),"+","_"),",","_"),"-","_"),".","_"),"/","_"),":","_"),";","_"),"<","_"),"=","_"),">","_"),"?","_"),"@","_"),"[","_"),"\","_"),"]","_"),"^","_"),"`","_"),"{","_"),"|","_"),"}","_"),"~","_"),"–","_"),"—","_"),"’","_"),"“","_"),"”","_"),CHAR(9),"_"),CHAR(160),"_")) | T17: =IF(S17="","",SUBSTITUTE(SUBSTITUTE(SUBSTITUTE(SUBSTITUTE(SUBSTITUTE(SUBSTITUTE(SUBSTITUTE(SUBSTITUTE(S17,"__","_"),"__","_"),"__","_"),"__","_"),"__","_"),"__","_"),"__","_"),"__","_")) | U17: =IF(OR(T17="",T17="_"),"",IF(LEFT(T17,1)="_",IF(RIGHT(T17,1)="_",MID(T17,2,LEN(T17)-2),RIGHT(T17,LEN(T17)-1)),IF(RIGHT(T17,1)="_",LEFT(T17,LEN(T17)-1),T17)))
G18: =IF(R18<>"",R18,"")&IF(U18<>"",IF(R18<>"","_"&U18,U18),"") | H18: =IF(TRIM(F18)<>"",TRIM(F18),G18) | I18: =IF(OR(A18="",B18="",C18="",D18=""),"Missing required field — fill in variable_class, the concept name, native_frequency, and role.",IF(G18="","Missing required field — variable_class and the concept name must combine into an ID.",IF(COUNTIF($H$8:$H$32,H18)>1,"Duplicate variable ID — two rows currently build the same variable_id; distinguish the actual variable, not its source frequency.",IF(AND(E18<>"",E18<>H18),"Existing variable_id differs from the built ID — review before using.","Ready")))) | P18: =IF(OR(LOWER(TRIM(A18))="",LOWER(TRIM(A18))="nan",LOWER(TRIM(A18))="none",LOWER(TRIM(A18))="n/a"),"",SUBSTITUTE(SUBSTITUTE(SUBSTITUTE(SUBSTITUTE(SUBSTITUTE(SUBSTITUTE(SUBSTITUTE(SUBSTITUTE(SUBSTITUTE(SUBSTITUTE(SUBSTITUTE(SUBSTITUTE(SUBSTITUTE(SUBSTITUTE(SUBSTITUTE(SUBSTITUTE(SUBSTITUTE(SUBSTITUTE(SUBSTITUTE(SUBSTITUTE(SUBSTITUTE(SUBSTITUTE(SUBSTITUTE(SUBSTITUTE(SUBSTITUTE(SUBSTITUTE(SUBSTITUTE(SUBSTITUTE(SUBSTITUTE(SUBSTITUTE(SUBSTITUTE(SUBSTITUTE(SUBSTITUTE(SUBSTITUTE(SUBSTITUTE(SUBSTITUTE(SUBSTITUTE(SUBSTITUTE(LOWER(TRIM(A18))," ","_"),"!","_"),"#","_"),"$","_"),"%","_"),"&","_"),"'","_"),"(","_"),")","_"),"*","_"),"+","_"),",","_"),"-","_"),".","_"),"/","_"),":","_"),";","_"),"<","_"),"=","_"),">","_"),"?","_"),"@","_"),"[","_"),"\","_"),"]","_"),"^","_"),"`","_"),"{","_"),"|","_"),"}","_"),"~","_"),"–","_"),"—","_"),"’","_"),"“","_"),"”","_"),CHAR(9),"_"),CHAR(160),"_")) | Q18: =IF(P18="","",SUBSTITUTE(SUBSTITUTE(SUBSTITUTE(SUBSTITUTE(SUBSTITUTE(SUBSTITUTE(SUBSTITUTE(SUBSTITUTE(P18,"__","_"),"__","_"),"__","_"),"__","_"),"__","_"),"__","_"),"__","_"),"__","_")) | R18: =IF(OR(Q18="",Q18="_"),"",IF(LEFT(Q18,1)="_",IF(RIGHT(Q18,1)="_",MID(Q18,2,LEN(Q18)-2),RIGHT(Q18,LEN(Q18)-1)),IF(RIGHT(Q18,1)="_",LEFT(Q18,LEN(Q18)-1),Q18))) | S18: =IF(OR(LOWER(TRIM(B18))="",LOWER(TRIM(B18))="nan",LOWER(TRIM(B18))="none",LOWER(TRIM(B18))="n/a"),"",SUBSTITUTE(SUBSTITUTE(SUBSTITUTE(SUBSTITUTE(SUBSTITUTE(SUBSTITUTE(SUBSTITUTE(SUBSTITUTE(SUBSTITUTE(SUBSTITUTE(SUBSTITUTE(SUBSTITUTE(SUBSTITUTE(SUBSTITUTE(SUBSTITUTE(SUBSTITUTE(SUBSTITUTE(SUBSTITUTE(SUBSTITUTE(SUBSTITUTE(SUBSTITUTE(SUBSTITUTE(SUBSTITUTE(SUBSTITUTE(SUBSTITUTE(SUBSTITUTE(SUBSTITUTE(SUBSTITUTE(SUBSTITUTE(SUBSTITUTE(SUBSTITUTE(SUBSTITUTE(SUBSTITUTE(SUBSTITUTE(SUBSTITUTE(SUBSTITUTE(SUBSTITUTE(SUBSTITUTE(LOWER(TRIM(B18))," ","_"),"!","_"),"#","_"),"$","_"),"%","_"),"&","_"),"'","_"),"(","_"),")","_"),"*","_"),"+","_"),",","_"),"-","_"),".","_"),"/","_"),":","_"),";","_"),"<","_"),"=","_"),">","_"),"?","_"),"@","_"),"[","_"),"\","_"),"]","_"),"^","_"),"`","_"),"{","_"),"|","_"),"}","_"),"~","_"),"–","_"),"—","_"),"’","_"),"“","_"),"”","_"),CHAR(9),"_"),CHAR(160),"_")) | T18: =IF(S18="","",SUBSTITUTE(SUBSTITUTE(SUBSTITUTE(SUBSTITUTE(SUBSTITUTE(SUBSTITUTE(SUBSTITUTE(SUBSTITUTE(S18,"__","_"),"__","_"),"__","_"),"__","_"),"__","_"),"__","_"),"__","_"),"__","_")) | U18: =IF(OR(T18="",T18="_"),"",IF(LEFT(T18,1)="_",IF(RIGHT(T18,1)="_",MID(T18,2,LEN(T18)-2),RIGHT(T18,LEN(T18)-1)),IF(RIGHT(T18,1)="_",LEFT(T18,LEN(T18)-1),T18)))
G19: =IF(R19<>"",R19,"")&IF(U19<>"",IF(R19<>"","_"&U19,U19),"") | H19: =IF(TRIM(F19)<>"",TRIM(F19),G19) | I19: =IF(OR(A19="",B19="",C19="",D19=""),"Missing required field — fill in variable_class, the concept name, native_frequency, and role.",IF(G19="","Missing required field — variable_class and the concept name must combine into an ID.",IF(COUNTIF($H$8:$H$32,H19)>1,"Duplicate variable ID — two rows currently build the same variable_id; distinguish the actual variable, not its source frequency.",IF(AND(E19<>"",E19<>H19),"Existing variable_id differs from the built ID — review before using.","Ready")))) | P19: =IF(OR(LOWER(TRIM(A19))="",LOWER(TRIM(A19))="nan",LOWER(TRIM(A19))="none",LOWER(TRIM(A19))="n/a"),"",SUBSTITUTE(SUBSTITUTE(SUBSTITUTE(SUBSTITUTE(SUBSTITUTE(SUBSTITUTE(SUBSTITUTE(SUBSTITUTE(SUBSTITUTE(SUBSTITUTE(SUBSTITUTE(SUBSTITUTE(SUBSTITUTE(SUBSTITUTE(SUBSTITUTE(SUBSTITUTE(SUBSTITUTE(SUBSTITUTE(SUBSTITUTE(SUBSTITUTE(SUBSTITUTE(SUBSTITUTE(SUBSTITUTE(SUBSTITUTE(SUBSTITUTE(SUBSTITUTE(SUBSTITUTE(SUBSTITUTE(SUBSTITUTE(SUBSTITUTE(SUBSTITUTE(SUBSTITUTE(SUBSTITUTE(SUBSTITUTE(SUBSTITUTE(SUBSTITUTE(SUBSTITUTE(SUBSTITUTE(LOWER(TRIM(A19))," ","_"),"!","_"),"#","_"),"$","_"),"%","_"),"&","_"),"'","_"),"(","_"),")","_"),"*","_"),"+","_"),",","_"),"-","_"),".","_"),"/","_"),":","_"),";","_"),"<","_"),"=","_"),">","_"),"?","_"),"@","_"),"[","_"),"\","_"),"]","_"),"^","_"),"`","_"),"{","_"),"|","_"),"}","_"),"~","_"),"–","_"),"—","_"),"’","_"),"“","_"),"”","_"),CHAR(9),"_"),CHAR(160),"_")) | Q19: =IF(P19="","",SUBSTITUTE(SUBSTITUTE(SUBSTITUTE(SUBSTITUTE(SUBSTITUTE(SUBSTITUTE(SUBSTITUTE(SUBSTITUTE(P19,"__","_"),"__","_"),"__","_"),"__","_"),"__","_"),"__","_"),"__","_"),"__","_")) | R19: =IF(OR(Q19="",Q19="_"),"",IF(LEFT(Q19,1)="_",IF(RIGHT(Q19,1)="_",MID(Q19,2,LEN(Q19)-2),RIGHT(Q19,LEN(Q19)-1)),IF(RIGHT(Q19,1)="_",LEFT(Q19,LEN(Q19)-1),Q19))) | S19: =IF(OR(LOWER(TRIM(B19))="",LOWER(TRIM(B19))="nan",LOWER(TRIM(B19))="none",LOWER(TRIM(B19))="n/a"),"",SUBSTITUTE(SUBSTITUTE(SUBSTITUTE(SUBSTITUTE(SUBSTITUTE(SUBSTITUTE(SUBSTITUTE(SUBSTITUTE(SUBSTITUTE(SUBSTITUTE(SUBSTITUTE(SUBSTITUTE(SUBSTITUTE(SUBSTITUTE(SUBSTITUTE(SUBSTITUTE(SUBSTITUTE(SUBSTITUTE(SUBSTITUTE(SUBSTITUTE(SUBSTITUTE(SUBSTITUTE(SUBSTITUTE(SUBSTITUTE(SUBSTITUTE(SUBSTITUTE(SUBSTITUTE(SUBSTITUTE(SUBSTITUTE(SUBSTITUTE(SUBSTITUTE(SUBSTITUTE(SUBSTITUTE(SUBSTITUTE(SUBSTITUTE(SUBSTITUTE(SUBSTITUTE(SUBSTITUTE(LOWER(TRIM(B19))," ","_"),"!","_"),"#","_"),"$","_"),"%","_"),"&","_"),"'","_"),"(","_"),")","_"),"*","_"),"+","_"),",","_"),"-","_"),".","_"),"/","_"),":","_"),";","_"),"<","_"),"=","_"),">","_"),"?","_"),"@","_"),"[","_"),"\","_"),"]","_"),"^","_"),"`","_"),"{","_"),"|","_"),"}","_"),"~","_"),"–","_"),"—","_"),"’","_"),"“","_"),"”","_"),CHAR(9),"_"),CHAR(160),"_")) | T19: =IF(S19="","",SUBSTITUTE(SUBSTITUTE(SUBSTITUTE(SUBSTITUTE(SUBSTITUTE(SUBSTITUTE(SUBSTITUTE(SUBSTITUTE(S19,"__","_"),"__","_"),"__","_"),"__","_"),"__","_"),"__","_"),"__","_"),"__","_")) | U19: =IF(OR(T19="",T19="_"),"",IF(LEFT(T19,1)="_",IF(RIGHT(T19,1)="_",MID(T19,2,LEN(T19)-2),RIGHT(T19,LEN(T19)-1)),IF(RIGHT(T19,1)="_",LEFT(T19,LEN(T19)-1),T19)))
G20: =IF(R20<>"",R20,"")&IF(U20<>"",IF(R20<>"","_"&U20,U20),"") | H20: =IF(TRIM(F20)<>"",TRIM(F20),G20) | I20: =IF(OR(A20="",B20="",C20="",D20=""),"Missing required field — fill in variable_class, the concept name, native_frequency, and role.",IF(G20="","Missing required field — variable_class and the concept name must combine into an ID.",IF(COUNTIF($H$8:$H$32,H20)>1,"Duplicate variable ID — two rows currently build the same variable_id; distinguish the actual variable, not its source frequency.",IF(AND(E20<>"",E20<>H20),"Existing variable_id differs from the built ID — review before using.","Ready")))) | P20: =IF(OR(LOWER(TRIM(A20))="",LOWER(TRIM(A20))="nan",LOWER(TRIM(A20))="none",LOWER(TRIM(A20))="n/a"),"",SUBSTITUTE(SUBSTITUTE(SUBSTITUTE(SUBSTITUTE(SUBSTITUTE(SUBSTITUTE(SUBSTITUTE(SUBSTITUTE(SUBSTITUTE(SUBSTITUTE(SUBSTITUTE(SUBSTITUTE(SUBSTITUTE(SUBSTITUTE(SUBSTITUTE(SUBSTITUTE(SUBSTITUTE(SUBSTITUTE(SUBSTITUTE(SUBSTITUTE(SUBSTITUTE(SUBSTITUTE(SUBSTITUTE(SUBSTITUTE(SUBSTITUTE(SUBSTITUTE(SUBSTITUTE(SUBSTITUTE(SUBSTITUTE(SUBSTITUTE(SUBSTITUTE(SUBSTITUTE(SUBSTITUTE(SUBSTITUTE(SUBSTITUTE(SUBSTITUTE(SUBSTITUTE(SUBSTITUTE(LOWER(TRIM(A20))," ","_"),"!","_"),"#","_"),"$","_"),"%","_"),"&","_"),"'","_"),"(","_"),")","_"),"*","_"),"+","_"),",","_"),"-","_"),".","_"),"/","_"),":","_"),";","_"),"<","_"),"=","_"),">","_"),"?","_"),"@","_"),"[","_"),"\","_"),"]","_"),"^","_"),"`","_"),"{","_"),"|","_"),"}","_"),"~","_"),"–","_"),"—","_"),"’","_"),"“","_"),"”","_"),CHAR(9),"_"),CHAR(160),"_")) | Q20: =IF(P20="","",SUBSTITUTE(SUBSTITUTE(SUBSTITUTE(SUBSTITUTE(SUBSTITUTE(SUBSTITUTE(SUBSTITUTE(SUBSTITUTE(P20,"__","_"),"__","_"),"__","_"),"__","_"),"__","_"),"__","_"),"__","_"),"__","_")) | R20: =IF(OR(Q20="",Q20="_"),"",IF(LEFT(Q20,1)="_",IF(RIGHT(Q20,1)="_",MID(Q20,2,LEN(Q20)-2),RIGHT(Q20,LEN(Q20)-1)),IF(RIGHT(Q20,1)="_",LEFT(Q20,LEN(Q20)-1),Q20))) | S20: =IF(OR(LOWER(TRIM(B20))="",LOWER(TRIM(B20))="nan",LOWER(TRIM(B20))="none",LOWER(TRIM(B20))="n/a"),"",SUBSTITUTE(SUBSTITUTE(SUBSTITUTE(SUBSTITUTE(SUBSTITUTE(SUBSTITUTE(SUBSTITUTE(SUBSTITUTE(SUBSTITUTE(SUBSTITUTE(SUBSTITUTE(SUBSTITUTE(SUBSTITUTE(SUBSTITUTE(SUBSTITUTE(SUBSTITUTE(SUBSTITUTE(SUBSTITUTE(SUBSTITUTE(SUBSTITUTE(SUBSTITUTE(SUBSTITUTE(SUBSTITUTE(SUBSTITUTE(SUBSTITUTE(SUBSTITUTE(SUBSTITUTE(SUBSTITUTE(SUBSTITUTE(SUBSTITUTE(SUBSTITUTE(SUBSTITUTE(SUBSTITUTE(SUBSTITUTE(SUBSTITUTE(SUBSTITUTE(SUBSTITUTE(SUBSTITUTE(LOWER(TRIM(B20))," ","_"),"!","_"),"#","_"),"$","_"),"%","_"),"&","_"),"'","_"),"(","_"),")","_"),"*","_"),"+","_"),",","_"),"-","_"),".","_"),"/","_"),":","_"),";","_"),"<","_"),"=","_"),">","_"),"?","_"),"@","_"),"[","_"),"\","_"),"]","_"),"^","_"),"`","_"),"{","_"),"|","_"),"}","_"),"~","_"),"–","_"),"—","_"),"’","_"),"“","_"),"”","_"),CHAR(9),"_"),CHAR(160),"_")) | T20: =IF(S20="","",SUBSTITUTE(SUBSTITUTE(SUBSTITUTE(SUBSTITUTE(SUBSTITUTE(SUBSTITUTE(SUBSTITUTE(SUBSTITUTE(S20,"__","_"),"__","_"),"__","_"),"__","_"),"__","_"),"__","_"),"__","_"),"__","_")) | U20: =IF(OR(T20="",T20="_"),"",IF(LEFT(T20,1)="_",IF(RIGHT(T20,1)="_",MID(T20,2,LEN(T20)-2),RIGHT(T20,LEN(T20)-1)),IF(RIGHT(T20,1)="_",LEFT(T20,LEN(T20)-1),T20)))
G21: =IF(R21<>"",R21,"")&IF(U21<>"",IF(R21<>"","_"&U21,U21),"") | H21: =IF(TRIM(F21)<>"",TRIM(F21),G21) | I21: =IF(OR(A21="",B21="",C21="",D21=""),"Missing required field — fill in variable_class, the concept name, native_frequency, and role.",IF(G21="","Missing required field — variable_class and the concept name must combine into an ID.",IF(COUNTIF($H$8:$H$32,H21)>1,"Duplicate variable ID — two rows currently build the same variable_id; distinguish the actual variable, not its source frequency.",IF(AND(E21<>"",E21<>H21),"Existing variable_id differs from the built ID — review before using.","Ready")))) | P21: =IF(OR(LOWER(TRIM(A21))="",LOWER(TRIM(A21))="nan",LOWER(TRIM(A21))="none",LOWER(TRIM(A21))="n/a"),"",SUBSTITUTE(SUBSTITUTE(SUBSTITUTE(SUBSTITUTE(SUBSTITUTE(SUBSTITUTE(SUBSTITUTE(SUBSTITUTE(SUBSTITUTE(SUBSTITUTE(SUBSTITUTE(SUBSTITUTE(SUBSTITUTE(SUBSTITUTE(SUBSTITUTE(SUBSTITUTE(SUBSTITUTE(SUBSTITUTE(SUBSTITUTE(SUBSTITUTE(SUBSTITUTE(SUBSTITUTE(SUBSTITUTE(SUBSTITUTE(SUBSTITUTE(SUBSTITUTE(SUBSTITUTE(SUBSTITUTE(SUBSTITUTE(SUBSTITUTE(SUBSTITUTE(SUBSTITUTE(SUBSTITUTE(SUBSTITUTE(SUBSTITUTE(SUBSTITUTE(SUBSTITUTE(SUBSTITUTE(LOWER(TRIM(A21))," ","_"),"!","_"),"#","_"),"$","_"),"%","_"),"&","_"),"'","_"),"(","_"),")","_"),"*","_"),"+","_"),",","_"),"-","_"),".","_"),"/","_"),":","_"),";","_"),"<","_"),"=","_"),">","_"),"?","_"),"@","_"),"[","_"),"\","_"),"]","_"),"^","_"),"`","_"),"{","_"),"|","_"),"}","_"),"~","_"),"–","_"),"—","_"),"’","_"),"“","_"),"”","_"),CHAR(9),"_"),CHAR(160),"_")) | Q21: =IF(P21="","",SUBSTITUTE(SUBSTITUTE(SUBSTITUTE(SUBSTITUTE(SUBSTITUTE(SUBSTITUTE(SUBSTITUTE(SUBSTITUTE(P21,"__","_"),"__","_"),"__","_"),"__","_"),"__","_"),"__","_"),"__","_"),"__","_")) | R21: =IF(OR(Q21="",Q21="_"),"",IF(LEFT(Q21,1)="_",IF(RIGHT(Q21,1)="_",MID(Q21,2,LEN(Q21)-2),RIGHT(Q21,LEN(Q21)-1)),IF(RIGHT(Q21,1)="_",LEFT(Q21,LEN(Q21)-1),Q21))) | S21: =IF(OR(LOWER(TRIM(B21))="",LOWER(TRIM(B21))="nan",LOWER(TRIM(B21))="none",LOWER(TRIM(B21))="n/a"),"",SUBSTITUTE(SUBSTITUTE(SUBSTITUTE(SUBSTITUTE(SUBSTITUTE(SUBSTITUTE(SUBSTITUTE(SUBSTITUTE(SUBSTITUTE(SUBSTITUTE(SUBSTITUTE(SUBSTITUTE(SUBSTITUTE(SUBSTITUTE(SUBSTITUTE(SUBSTITUTE(SUBSTITUTE(SUBSTITUTE(SUBSTITUTE(SUBSTITUTE(SUBSTITUTE(SUBSTITUTE(SUBSTITUTE(SUBSTITUTE(SUBSTITUTE(SUBSTITUTE(SUBSTITUTE(SUBSTITUTE(SUBSTITUTE(SUBSTITUTE(SUBSTITUTE(SUBSTITUTE(SUBSTITUTE(SUBSTITUTE(SUBSTITUTE(SUBSTITUTE(SUBSTITUTE(SUBSTITUTE(LOWER(TRIM(B21))," ","_"),"!","_"),"#","_"),"$","_"),"%","_"),"&","_"),"'","_"),"(","_"),")","_"),"*","_"),"+","_"),",","_"),"-","_"),".","_"),"/","_"),":","_"),";","_"),"<","_"),"=","_"),">","_"),"?","_"),"@","_"),"[","_"),"\","_"),"]","_"),"^","_"),"`","_"),"{","_"),"|","_"),"}","_"),"~","_"),"–","_"),"—","_"),"’","_"),"“","_"),"”","_"),CHAR(9),"_"),CHAR(160),"_")) | T21: =IF(S21="","",SUBSTITUTE(SUBSTITUTE(SUBSTITUTE(SUBSTITUTE(SUBSTITUTE(SUBSTITUTE(SUBSTITUTE(SUBSTITUTE(S21,"__","_"),"__","_"),"__","_"),"__","_"),"__","_"),"__","_"),"__","_"),"__","_")) | U21: =IF(OR(T21="",T21="_"),"",IF(LEFT(T21,1)="_",IF(RIGHT(T21,1)="_",MID(T21,2,LEN(T21)-2),RIGHT(T21,LEN(T21)-1)),IF(RIGHT(T21,1)="_",LEFT(T21,LEN(T21)-1),T21)))
G22: =IF(R22<>"",R22,"")&IF(U22<>"",IF(R22<>"","_"&U22,U22),"") | H22: =IF(TRIM(F22)<>"",TRIM(F22),G22) | I22: =IF(OR(A22="",B22="",C22="",D22=""),"Missing required field — fill in variable_class, the concept name, native_frequency, and role.",IF(G22="","Missing required field — variable_class and the concept name must combine into an ID.",IF(COUNTIF($H$8:$H$32,H22)>1,"Duplicate variable ID — two rows currently build the same variable_id; distinguish the actual variable, not its source frequency.",IF(AND(E22<>"",E22<>H22),"Existing variable_id differs from the built ID — review before using.","Ready")))) | P22: =IF(OR(LOWER(TRIM(A22))="",LOWER(TRIM(A22))="nan",LOWER(TRIM(A22))="none",LOWER(TRIM(A22))="n/a"),"",SUBSTITUTE(SUBSTITUTE(SUBSTITUTE(SUBSTITUTE(SUBSTITUTE(SUBSTITUTE(SUBSTITUTE(SUBSTITUTE(SUBSTITUTE(SUBSTITUTE(SUBSTITUTE(SUBSTITUTE(SUBSTITUTE(SUBSTITUTE(SUBSTITUTE(SUBSTITUTE(SUBSTITUTE(SUBSTITUTE(SUBSTITUTE(SUBSTITUTE(SUBSTITUTE(SUBSTITUTE(SUBSTITUTE(SUBSTITUTE(SUBSTITUTE(SUBSTITUTE(SUBSTITUTE(SUBSTITUTE(SUBSTITUTE(SUBSTITUTE(SUBSTITUTE(SUBSTITUTE(SUBSTITUTE(SUBSTITUTE(SUBSTITUTE(SUBSTITUTE(SUBSTITUTE(SUBSTITUTE(LOWER(TRIM(A22))," ","_"),"!","_"),"#","_"),"$","_"),"%","_"),"&","_"),"'","_"),"(","_"),")","_"),"*","_"),"+","_"),",","_"),"-","_"),".","_"),"/","_"),":","_"),";","_"),"<","_"),"=","_"),">","_"),"?","_"),"@","_"),"[","_"),"\","_"),"]","_"),"^","_"),"`","_"),"{","_"),"|","_"),"}","_"),"~","_"),"–","_"),"—","_"),"’","_"),"“","_"),"”","_"),CHAR(9),"_"),CHAR(160),"_")) | Q22: =IF(P22="","",SUBSTITUTE(SUBSTITUTE(SUBSTITUTE(SUBSTITUTE(SUBSTITUTE(SUBSTITUTE(SUBSTITUTE(SUBSTITUTE(P22,"__","_"),"__","_"),"__","_"),"__","_"),"__","_"),"__","_"),"__","_"),"__","_")) | R22: =IF(OR(Q22="",Q22="_"),"",IF(LEFT(Q22,1)="_",IF(RIGHT(Q22,1)="_",MID(Q22,2,LEN(Q22)-2),RIGHT(Q22,LEN(Q22)-1)),IF(RIGHT(Q22,1)="_",LEFT(Q22,LEN(Q22)-1),Q22))) | S22: =IF(OR(LOWER(TRIM(B22))="",LOWER(TRIM(B22))="nan",LOWER(TRIM(B22))="none",LOWER(TRIM(B22))="n/a"),"",SUBSTITUTE(SUBSTITUTE(SUBSTITUTE(SUBSTITUTE(SUBSTITUTE(SUBSTITUTE(SUBSTITUTE(SUBSTITUTE(SUBSTITUTE(SUBSTITUTE(SUBSTITUTE(SUBSTITUTE(SUBSTITUTE(SUBSTITUTE(SUBSTITUTE(SUBSTITUTE(SUBSTITUTE(SUBSTITUTE(SUBSTITUTE(SUBSTITUTE(SUBSTITUTE(SUBSTITUTE(SUBSTITUTE(SUBSTITUTE(SUBSTITUTE(SUBSTITUTE(SUBSTITUTE(SUBSTITUTE(SUBSTITUTE(SUBSTITUTE(SUBSTITUTE(SUBSTITUTE(SUBSTITUTE(SUBSTITUTE(SUBSTITUTE(SUBSTITUTE(SUBSTITUTE(SUBSTITUTE(LOWER(TRIM(B22))," ","_"),"!","_"),"#","_"),"$","_"),"%","_"),"&","_"),"'","_"),"(","_"),")","_"),"*","_"),"+","_"),",","_"),"-","_"),".","_"),"/","_"),":","_"),";","_"),"<","_"),"=","_"),">","_"),"?","_"),"@","_"),"[","_"),"\","_"),"]","_"),"^","_"),"`","_"),"{","_"),"|","_"),"}","_"),"~","_"),"–","_"),"—","_"),"’","_"),"“","_"),"”","_"),CHAR(9),"_"),CHAR(160),"_")) | T22: =IF(S22="","",SUBSTITUTE(SUBSTITUTE(SUBSTITUTE(SUBSTITUTE(SUBSTITUTE(SUBSTITUTE(SUBSTITUTE(SUBSTITUTE(S22,"__","_"),"__","_"),"__","_"),"__","_"),"__","_"),"__","_"),"__","_"),"__","_")) | U22: =IF(OR(T22="",T22="_"),"",IF(LEFT(T22,1)="_",IF(RIGHT(T22,1)="_",MID(T22,2,LEN(T22)-2),RIGHT(T22,LEN(T22)-1)),IF(RIGHT(T22,1)="_",LEFT(T22,LEN(T22)-1),T22)))
G23: =IF(R23<>"",R23,"")&IF(U23<>"",IF(R23<>"","_"&U23,U23),"") | H23: =IF(TRIM(F23)<>"",TRIM(F23),G23) | I23: =IF(OR(A23="",B23="",C23="",D23=""),"Missing required field — fill in variable_class, the concept name, native_frequency, and role.",IF(G23="","Missing required field — variable_class and the concept name must combine into an ID.",IF(COUNTIF($H$8:$H$32,H23)>1,"Duplicate variable ID — two rows currently build the same variable_id; distinguish the actual variable, not its source frequency.",IF(AND(E23<>"",E23<>H23),"Existing variable_id differs from the built ID — review before using.","Ready")))) | P23: =IF(OR(LOWER(TRIM(A23))="",LOWER(TRIM(A23))="nan",LOWER(TRIM(A23))="none",LOWER(TRIM(A23))="n/a"),"",SUBSTITUTE(SUBSTITUTE(SUBSTITUTE(SUBSTITUTE(SUBSTITUTE(SUBSTITUTE(SUBSTITUTE(SUBSTITUTE(SUBSTITUTE(SUBSTITUTE(SUBSTITUTE(SUBSTITUTE(SUBSTITUTE(SUBSTITUTE(SUBSTITUTE(SUBSTITUTE(SUBSTITUTE(SUBSTITUTE(SUBSTITUTE(SUBSTITUTE(SUBSTITUTE(SUBSTITUTE(SUBSTITUTE(SUBSTITUTE(SUBSTITUTE(SUBSTITUTE(SUBSTITUTE(SUBSTITUTE(SUBSTITUTE(SUBSTITUTE(SUBSTITUTE(SUBSTITUTE(SUBSTITUTE(SUBSTITUTE(SUBSTITUTE(SUBSTITUTE(SUBSTITUTE(SUBSTITUTE(LOWER(TRIM(A23))," ","_"),"!","_"),"#","_"),"$","_"),"%","_"),"&","_"),"'","_"),"(","_"),")","_"),"*","_"),"+","_"),",","_"),"-","_"),".","_"),"/","_"),":","_"),";","_"),"<","_"),"=","_"),">","_"),"?","_"),"@","_"),"[","_"),"\","_"),"]","_"),"^","_"),"`","_"),"{","_"),"|","_"),"}","_"),"~","_"),"–","_"),"—","_"),"’","_"),"“","_"),"”","_"),CHAR(9),"_"),CHAR(160),"_")) | Q23: =IF(P23="","",SUBSTITUTE(SUBSTITUTE(SUBSTITUTE(SUBSTITUTE(SUBSTITUTE(SUBSTITUTE(SUBSTITUTE(SUBSTITUTE(P23,"__","_"),"__","_"),"__","_"),"__","_"),"__","_"),"__","_"),"__","_"),"__","_")) | R23: =IF(OR(Q23="",Q23="_"),"",IF(LEFT(Q23,1)="_",IF(RIGHT(Q23,1)="_",MID(Q23,2,LEN(Q23)-2),RIGHT(Q23,LEN(Q23)-1)),IF(RIGHT(Q23,1)="_",LEFT(Q23,LEN(Q23)-1),Q23))) | S23: =IF(OR(LOWER(TRIM(B23))="",LOWER(TRIM(B23))="nan",LOWER(TRIM(B23))="none",LOWER(TRIM(B23))="n/a"),"",SUBSTITUTE(SUBSTITUTE(SUBSTITUTE(SUBSTITUTE(SUBSTITUTE(SUBSTITUTE(SUBSTITUTE(SUBSTITUTE(SUBSTITUTE(SUBSTITUTE(SUBSTITUTE(SUBSTITUTE(SUBSTITUTE(SUBSTITUTE(SUBSTITUTE(SUBSTITUTE(SUBSTITUTE(SUBSTITUTE(SUBSTITUTE(SUBSTITUTE(SUBSTITUTE(SUBSTITUTE(SUBSTITUTE(SUBSTITUTE(SUBSTITUTE(SUBSTITUTE(SUBSTITUTE(SUBSTITUTE(SUBSTITUTE(SUBSTITUTE(SUBSTITUTE(SUBSTITUTE(SUBSTITUTE(SUBSTITUTE(SUBSTITUTE(SUBSTITUTE(SUBSTITUTE(SUBSTITUTE(LOWER(TRIM(B23))," ","_"),"!","_"),"#","_"),"$","_"),"%","_"),"&","_"),"'","_"),"(","_"),")","_"),"*","_"),"+","_"),",","_"),"-","_"),".","_"),"/","_"),":","_"),";","_"),"<","_"),"=","_"),">","_"),"?","_"),"@","_"),"[","_"),"\","_"),"]","_"),"^","_"),"`","_"),"{","_"),"|","_"),"}","_"),"~","_"),"–","_"),"—","_"),"’","_"),"“","_"),"”","_"),CHAR(9),"_"),CHAR(160),"_")) | T23: =IF(S23="","",SUBSTITUTE(SUBSTITUTE(SUBSTITUTE(SUBSTITUTE(SUBSTITUTE(SUBSTITUTE(SUBSTITUTE(SUBSTITUTE(S23,"__","_"),"__","_"),"__","_"),"__","_"),"__","_"),"__","_"),"__","_"),"__","_")) | U23: =IF(OR(T23="",T23="_"),"",IF(LEFT(T23,1)="_",IF(RIGHT(T23,1)="_",MID(T23,2,LEN(T23)-2),RIGHT(T23,LEN(T23)-1)),IF(RIGHT(T23,1)="_",LEFT(T23,LEN(T23)-1),T23)))
G24: =IF(R24<>"",R24,"")&IF(U24<>"",IF(R24<>"","_"&U24,U24),"") | H24: =IF(TRIM(F24)<>"",TRIM(F24),G24) | I24: =IF(OR(A24="",B24="",C24="",D24=""),"Missing required field — fill in variable_class, the concept name, native_frequency, and role.",IF(G24="","Missing required field — variable_class and the concept name must combine into an ID.",IF(COUNTIF($H$8:$H$32,H24)>1,"Duplicate variable ID — two rows currently build the same variable_id; distinguish the actual variable, not its source frequency.",IF(AND(E24<>"",E24<>H24),"Existing variable_id differs from the built ID — review before using.","Ready")))) | P24: =IF(OR(LOWER(TRIM(A24))="",LOWER(TRIM(A24))="nan",LOWER(TRIM(A24))="none",LOWER(TRIM(A24))="n/a"),"",SUBSTITUTE(SUBSTITUTE(SUBSTITUTE(SUBSTITUTE(SUBSTITUTE(SUBSTITUTE(SUBSTITUTE(SUBSTITUTE(SUBSTITUTE(SUBSTITUTE(SUBSTITUTE(SUBSTITUTE(SUBSTITUTE(SUBSTITUTE(SUBSTITUTE(SUBSTITUTE(SUBSTITUTE(SUBSTITUTE(SUBSTITUTE(SUBSTITUTE(SUBSTITUTE(SUBSTITUTE(SUBSTITUTE(SUBSTITUTE(SUBSTITUTE(SUBSTITUTE(SUBSTITUTE(SUBSTITUTE(SUBSTITUTE(SUBSTITUTE(SUBSTITUTE(SUBSTITUTE(SUBSTITUTE(SUBSTITUTE(SUBSTITUTE(SUBSTITUTE(SUBSTITUTE(SUBSTITUTE(LOWER(TRIM(A24))," ","_"),"!","_"),"#","_"),"$","_"),"%","_"),"&","_"),"'","_"),"(","_"),")","_"),"*","_"),"+","_"),",","_"),"-","_"),".","_"),"/","_"),":","_"),";","_"),"<","_"),"=","_"),">","_"),"?","_"),"@","_"),"[","_"),"\","_"),"]","_"),"^","_"),"`","_"),"{","_"),"|","_"),"}","_"),"~","_"),"–","_"),"—","_"),"’","_"),"“","_"),"”","_"),CHAR(9),"_"),CHAR(160),"_")) | Q24: =IF(P24="","",SUBSTITUTE(SUBSTITUTE(SUBSTITUTE(SUBSTITUTE(SUBSTITUTE(SUBSTITUTE(SUBSTITUTE(SUBSTITUTE(P24,"__","_"),"__","_"),"__","_"),"__","_"),"__","_"),"__","_"),"__","_"),"__","_")) | R24: =IF(OR(Q24="",Q24="_"),"",IF(LEFT(Q24,1)="_",IF(RIGHT(Q24,1)="_",MID(Q24,2,LEN(Q24)-2),RIGHT(Q24,LEN(Q24)-1)),IF(RIGHT(Q24,1)="_",LEFT(Q24,LEN(Q24)-1),Q24))) | S24: =IF(OR(LOWER(TRIM(B24))="",LOWER(TRIM(B24))="nan",LOWER(TRIM(B24))="none",LOWER(TRIM(B24))="n/a"),"",SUBSTITUTE(SUBSTITUTE(SUBSTITUTE(SUBSTITUTE(SUBSTITUTE(SUBSTITUTE(SUBSTITUTE(SUBSTITUTE(SUBSTITUTE(SUBSTITUTE(SUBSTITUTE(SUBSTITUTE(SUBSTITUTE(SUBSTITUTE(SUBSTITUTE(SUBSTITUTE(SUBSTITUTE(SUBSTITUTE(SUBSTITUTE(SUBSTITUTE(SUBSTITUTE(SUBSTITUTE(SUBSTITUTE(SUBSTITUTE(SUBSTITUTE(SUBSTITUTE(SUBSTITUTE(SUBSTITUTE(SUBSTITUTE(SUBSTITUTE(SUBSTITUTE(SUBSTITUTE(SUBSTITUTE(SUBSTITUTE(SUBSTITUTE(SUBSTITUTE(SUBSTITUTE(SUBSTITUTE(LOWER(TRIM(B24))," ","_"),"!","_"),"#","_"),"$","_"),"%","_"),"&","_"),"'","_"),"(","_"),")","_"),"*","_"),"+","_"),",","_"),"-","_"),".","_"),"/","_"),":","_"),";","_"),"<","_"),"=","_"),">","_"),"?","_"),"@","_"),"[","_"),"\","_"),"]","_"),"^","_"),"`","_"),"{","_"),"|","_"),"}","_"),"~","_"),"–","_"),"—","_"),"’","_"),"“","_"),"”","_"),CHAR(9),"_"),CHAR(160),"_")) | T24: =IF(S24="","",SUBSTITUTE(SUBSTITUTE(SUBSTITUTE(SUBSTITUTE(SUBSTITUTE(SUBSTITUTE(SUBSTITUTE(SUBSTITUTE(S24,"__","_"),"__","_"),"__","_"),"__","_"),"__","_"),"__","_"),"__","_"),"__","_")) | U24: =IF(OR(T24="",T24="_"),"",IF(LEFT(T24,1)="_",IF(RIGHT(T24,1)="_",MID(T24,2,LEN(T24)-2),RIGHT(T24,LEN(T24)-1)),IF(RIGHT(T24,1)="_",LEFT(T24,LEN(T24)-1),T24)))
... G32: =IF(R32<>"",R32,"")&IF(U32<>"",IF(R32<>"","_"&U32,U32),"") | H32: =IF(TRIM(F32)<>"",TRIM(F32),G32) | I32: =IF(OR(A32="",B32="",C32="",D32=""),"Missing required field — fill in variable_class, the concept name, native_frequency, and role.",IF(G32="","Missing required field — variable_class and the concept name must combine into an ID.",IF(COUNTIF($H$8:$H$32,H32)>1,"Duplicate variable ID — two rows currently build the same variable_id; distinguish the actual variable, not its source frequency.",IF(AND(E32<>"",E32<>H32),"Existing variable_id differs from the built ID — review before using.","Ready")))) | P32: =IF(OR(LOWER(TRIM(A32))="",LOWER(TRIM(A32))="nan",LOWER(TRIM(A32))="none",LOWER(TRIM(A32))="n/a"),"",SUBSTITUTE(SUBSTITUTE(SUBSTITUTE(SUBSTITUTE(SUBSTITUTE(SUBSTITUTE(SUBSTITUTE(SUBSTITUTE(SUBSTITUTE(SUBSTITUTE(SUBSTITUTE(SUBSTITUTE(SUBSTITUTE(SUBSTITUTE(SUBSTITUTE(SUBSTITUTE(SUBSTITUTE(SUBSTITUTE(SUBSTITUTE(SUBSTITUTE(SUBSTITUTE(SUBSTITUTE(SUBSTITUTE(SUBSTITUTE(SUBSTITUTE(SUBSTITUTE(SUBSTITUTE(SUBSTITUTE(SUBSTITUTE(SUBSTITUTE(SUBSTITUTE(SUBSTITUTE(SUBSTITUTE(SUBSTITUTE(SUBSTITUTE(SUBSTITUTE(SUBSTITUTE(SUBSTITUTE(LOWER(TRIM(A32))," ","_"),"!","_"),"#","_"),"$","_"),"%","_"),"&","_"),"'","_"),"(","_"),")","_"),"*","_"),"+","_"),",","_"),"-","_"),".","_"),"/","_"),":","_"),";","_"),"<","_"),"=","_"),">","_"),"?","_"),"@","_"),"[","_"),"\","_"),"]","_"),"^","_"),"`","_"),"{","_"),"|","_"),"}","_"),"~","_"),"–","_"),"—","_"),"’","_"),"“","_"),"”","_"),CHAR(9),"_"),CHAR(160),"_")) | Q32: =IF(P32="","",SUBSTITUTE(SUBSTITUTE(SUBSTITUTE(SUBSTITUTE(SUBSTITUTE(SUBSTITUTE(SUBSTITUTE(SUBSTITUTE(P32,"__","_"),"__","_"),"__","_"),"__","_"),"__","_"),"__","_"),"__","_"),"__","_")) | R32: =IF(OR(Q32="",Q32="_"),"",IF(LEFT(Q32,1)="_",IF(RIGHT(Q32,1)="_",MID(Q32,2,LEN(Q32)-2),RIGHT(Q32,LEN(Q32)-1)),IF(RIGHT(Q32,1)="_",LEFT(Q32,LEN(Q32)-1),Q32))) | S32: =IF(OR(LOWER(TRIM(B32))="",LOWER(TRIM(B32))="nan",LOWER(TRIM(B32))="none",LOWER(TRIM(B32))="n/a"),"",SUBSTITUTE(SUBSTITUTE(SUBSTITUTE(SUBSTITUTE(SUBSTITUTE(SUBSTITUTE(SUBSTITUTE(SUBSTITUTE(SUBSTITUTE(SUBSTITUTE(SUBSTITUTE(SUBSTITUTE(SUBSTITUTE(SUBSTITUTE(SUBSTITUTE(SUBSTITUTE(SUBSTITUTE(SUBSTITUTE(SUBSTITUTE(SUBSTITUTE(SUBSTITUTE(SUBSTITUTE(SUBSTITUTE(SUBSTITUTE(SUBSTITUTE(SUBSTITUTE(SUBSTITUTE(SUBSTITUTE(SUBSTITUTE(SUBSTITUTE(SUBSTITUTE(SUBSTITUTE(SUBSTITUTE(SUBSTITUTE(SUBSTITUTE(SUBSTITUTE(SUBSTITUTE(SUBSTITUTE(LOWER(TRIM(B32))," ","_"),"!","_"),"#","_"),"$","_"),"%","_"),"&","_"),"'","_"),"(","_"),")","_"),"*","_"),"+","_"),",","_"),"-","_"),".","_"),"/","_"),":","_"),";","_"),"<","_"),"=","_"),">","_"),"?","_"),"@","_"),"[","_"),"\","_"),"]","_"),"^","_"),"`","_"),"{","_"),"|","_"),"}","_"),"~","_"),"–","_"),"—","_"),"’","_"),"“","_"),"”","_"),CHAR(9),"_"),CHAR(160),"_")) | T32: =IF(S32="","",SUBSTITUTE(SUBSTITUTE(SUBSTITUTE(SUBSTITUTE(SUBSTITUTE(SUBSTITUTE(SUBSTITUTE(SUBSTITUTE(S32,"__","_"),"__","_"),"__","_"),"__","_"),"__","_"),"__","_"),"__","_"),"__","_")) | U32: =IF(OR(T32="",T32="_"),"",IF(LEFT(T32,1)="_",IF(RIGHT(T32,1)="_",MID(T32,2,LEN(T32)-2),RIGHT(T32,LEN(T32)-1)),IF(RIGHT(T32,1)="_",LEFT(T32,LEN(T32)-1),T32)))

Sheet DICTIONARY_OUTPUT
A1: variable_id | B1: variable_class | C1: native_frequency | D1: role | E1: source | F1: scope | G1: effective_from | H1: effective_to | I1: unit
A2: ='BUILDER'!H8 | B2: ='BUILDER'!A8 | C2: ='BUILDER'!C8 | D2: ='BUILDER'!D8 | E2: ='BUILDER'!J8 | F2: ='BUILDER'!K8 | G2: ='BUILDER'!L8 | H2: ='BUILDER'!M8
A3: ='BUILDER'!H9 | B3: ='BUILDER'!A9 | C3: ='BUILDER'!C9 | D3: ='BUILDER'!D9 | E3: ='BUILDER'!J9 | F3: ='BUILDER'!K9 | G3: ='BUILDER'!L9 | H3: ='BUILDER'!M9
A4: ='BUILDER'!H10 | B4: ='BUILDER'!A10 | C4: ='BUILDER'!C10 | D4: ='BUILDER'!D10 | E4: ='BUILDER'!J10 | F4: ='BUILDER'!K10 | G4: ='BUILDER'!L10 | H4: ='BUILDER'!M10
A5: ='BUILDER'!H11 | B5: ='BUILDER'!A11 | C5: ='BUILDER'!C11 | D5: ='BUILDER'!D11 | E5: ='BUILDER'!J11 | F5: ='BUILDER'!K11 | G5: ='BUILDER'!L11 | H5: ='BUILDER'!M11
A6: ='BUILDER'!H12 | B6: ='BUILDER'!A12 | C6: ='BUILDER'!C12 | D6: ='BUILDER'!D12 | E6: ='BUILDER'!J12 | F6: ='BUILDER'!K12 | G6: ='BUILDER'!L12 | H6: ='BUILDER'!M12
A7: ='BUILDER'!H13 | B7: ='BUILDER'!A13 | C7: ='BUILDER'!C13 | D7: ='BUILDER'!D13 | E7: ='BUILDER'!J13 | F7: ='BUILDER'!K13 | G7: ='BUILDER'!L13 | H7: ='BUILDER'!M13
A8: ='BUILDER'!H14 | B8: ='BUILDER'!A14 | C8: ='BUILDER'!C14 | D8: ='BUILDER'!D14 | E8: ='BUILDER'!J14 | F8: ='BUILDER'!K14 | G8: ='BUILDER'!L14 | H8: ='BUILDER'!M14
A9: ='BUILDER'!H15 | B9: ='BUILDER'!A15 | C9: ='BUILDER'!C15 | D9: ='BUILDER'!D15 | E9: ='BUILDER'!J15 | F9: ='BUILDER'!K15 | G9: ='BUILDER'!L15 | H9: ='BUILDER'!M15
A10: ='BUILDER'!H16 | B10: ='BUILDER'!A16 | C10: ='BUILDER'!C16 | D10: ='BUILDER'!D16 | E10: ='BUILDER'!J16 | F10: ='BUILDER'!K16 | G10: ='BUILDER'!L16 | H10: ='BUILDER'!M16
